Workbook

Sheet личный дневной (печатная форма)
A1: ООО Инженерная инфраструктура | D1: ФОРМА РЕКОМЕНДУЕМАЯ К ЗАПОЛНЕНИЮ ЗА ОДИН ДЕНЬ
A3: Дата заполнения:
A4: Подразделение: | B4: ИТС / Отдел главного энергетика | D4: можно распечатать с наименованием, можно очистить поля
A5: Должность: | B5: Дежурный инженер | D5: можно распечатать с наименованием, можно очистить поля
A6: ФИО сотрудника:
A7: Табельный номер:
A9: Всего рабочих часов в смену: | C9: Подпись сотрудника
A10: Айсберг и ТА
A11: МЛАХ и ТА
A12: Сириус Арена
A13: Спортивный Парк
A14: Спец Объект
A15: КТ
A16: СБТ
A17: ЦЕ
A18: Капмус ОЦ
A19: Корпус Спорт ОЦ
A20: Корпус Школа ОЦ
A21: Международная, 10 (Лицей)
... A42: Подпись руководителя подразделения
C43: (ФИО)

Sheet личный месяц (печатная форма)
B1: ООО Инженерная инфраструктура | AJ1: ФОРМА К ЗАПОЛНЕНИЮ ЗА МЕСЯЦ - ОБЯЗАТЕЛЬНАЯ !!!
B3: Дата заполнения:
B4: Подразделение: | C4: ИТС / Отдел главного энергетика | AH4: указать месяц
B5: Должность: | C5: Дежурный инженер
B6: ФИО сотрудника:
B7: Табельный номер:
C9: 1 | D9: 2 | E9: 3 | F9: 4 | G9: 5 | H9: 6 | I9: 7 | J9: 8 | K9: 9 | L9: 10 | M9: 11 | N9: 12 | O9: 13 | P9: 14 | Q9: 15 | R9: 16 | S9: 17 | T9: 18 | U9: 19 | V9: 20 | W9: 21 | X9: 22 | Y9: 23 | Z9: 24 | AA9: 25 | AB9: 26 | AC9: 27 | AD9: 28 | AE9: 29 | AF9: 30 | AG9: 31 | AH9: всего за месяц:
B10: Айсберг и ТА
B11: МЛАХ и ТА
B12: Сириус Арена
B13: Спортивный Парк
B14: Спец Объект
B15: КТ
B16: СБТ
B17: ЦЕ
B18: Капмус ОЦ
B19: Корпус Спорт ОЦ
B20: Корпус Школа ОЦ
B21: Международная, 10 (Лицей)
... B41: Всего:
B43: Подпись руководителя подразделения | U43: Подпись сотрудника | AK43: ПОДПИСИ ОБЯЗАТЕЛЬНЫ
K44: (ФИО) | AH44: (ФИО)

Sheet сотрудники
A1: ООО Инженерная инфраструктура
A2: № п.п. | B2: Табельный номер | C2: ФИО сотрудника | D2: Должность (выбрать из списка) | E2: Подразделение (выбрать из списка) | F2: ДАННЫЕ СОТРУДНИКОВ ЗАПОЛНЯТЬ НА ЭТОМ ЛИСТЕ (В ЛИСТАХ ПО ДНЯМ ТОЛЬКО ВЫБИРАТЬ ИЗ ВЫПАДАЮЩЕГО СПИСКА ТАБЕЛЬНЫЙ НОМЕР)
A4: 1 | B4: 255 | C4: Хабаров Д.Б. | D4: Руководитель группы | E4: Производственно-технический отдел
A5: 2 | B5: 166 | C5: Агеев В.А. | D5: Ведущий инженер | E5: ИТС / Отдел главного энергетика
A6: 3 | B6: 167 | C6: Линев А.В. | D6: Ведущий инженер
A7: 4 | B7: 163 | C7: Меньщиков А.В. | D7: Ведущий инженер
A8: 5
A9: 6
A10: 7
A11: 8
A12: 9 | C12: =сотрудники!E4 -> Производственно-технический отдел
A13: 10
A14: 11
A15: 12
A16: 13
A17: 14
A18: 15
A19: 16
A20: 17
A21: 18
A22: 19
A23: 20
A24: 21
... A217: 700

Sheet Подразделения
A4: Дежурная служба
A5: ИТС / Отдел главного энергетика
A6: ИТС / Отдел главного технолога
A7: ИТС / Отдел по эксплуатации инфраструкткрных объектов
A8: ИТС / Отдел по обслуживанию объектов
A9: ИТС / Отдел по подготовке льда и трансформации арен
A10: ИТС / Отдел по подготовке льда и спортивных сооружений
A11: Дежурная служба
A12: Служба эксплуатации Кампус / Отдел по эксплуатации
A13: Служба эксплуатации Кампус / Диспетчерская группа
A14: Служба эксплуатации ПНиИ / Отдел по эксплуатации
A15: Служба эксплуатации ПНиИ / Диспетчерская группа
... A26: Ремонтная служба, Группа по эксплуатации лифтового оборудования и грузоподъемных механизмов

Sheet Должности
A1: Дежурный инженер-технолог
A2: Дежурный инженер
A3: Ведущий инженер
A4: Ведущий инженер по эксплуатации
A5: Ведущий инженер по водоснабжению и канализации
A6: Ведущий инженер по лифтовому оборудованию и грузоподъемным механизмам
A7: Главный инженер-сметчик
A8: Ведущий инженер по обслуживанию и ремонту технологического оборудования
A9: Ведущий специлист по закупкам
A10: Ведущий инженер по технической документации
A11: Ведущий инженер по эксплуатации
A12: Ведущий инженер по эксплуатации бассейнов
... A95: Ведущий специлист по материально-техническому обепечению

Sheet Август
A1: ООО Инженерная инфраструктура | E1: месяц: | F1: июль
A4: № п.п. | B4: Табельный номер (автозаполнение) | C4: ФИО сотрудника (автозаполнение) | D4: Должность (автозаполнение) | E4: Подразделение (автозаполнение) | F4: Всего отработано часов в смену | G4: часы работы на объектах
G5: Айсберг и ТА | H5: МЛАХ и ТА | I5: Сириус Арена | J5: Спортивный Парк | K5: Спец Объект | L5: КТ | M5: СБТ | N5: ЦС | O5: Академия Единоборств (ЦПС) | P5: Академия Единоборств (УСТК1) | Q5: Академия Единоборств (УСТК2) | R5: Капмус ОЦ | S5: Корпус Спорт ОЦ | T5: Корпус Школа ОЦ | U5: Международная, 10 (Лицей) | V5: ПЛ Школа | W5: ПЛ ДДУ | X5: ПЛ Бассейн | Y5: ПНиИ | Z5: Админ. здания ОП | AA5: Планетарий | AB5: Концертный | AC5: Квартиры Худякова | AD5: Квартиры Эстонская | AE5: Олимп. Парк | AF5: РЖД | AG5: Парусная | AH5: Дельта | AI5: Омега | AJ5: Гамма | AK5: Сигма А | AL5: Сигма Б,В,Г | AM5: Хостел S | AN5: Русские сезоны
A6: 1 | B6: =сотрудники!B5 -> 166 | C6: =IF(B6<>0,(VLOOKUP($B6,сотрудники!$B$4:$D$217,2,0)),0) -> Агеев В.А. | D6: =IF(C6<>0,(VLOOKUP($B6,сотрудники!$B$4:$D$217,3,0)),0) -> Ведущий инженер | E6: =IF(D6<>0,(VLOOKUP($B6,сотрудники!$B$4:$E$217,4,0)),0) -> ИТС / Отдел главного энергетика | F6: =SUM(G6:AZ6) -> 104 | N6: 104
A7: 2 | B7: =сотрудники!B6 -> 167 | C7: =IF(B7<>0,(VLOOKUP($B7,сотрудники!$B$4:$D$217,2,0)),0) -> Линев А.В. | D7: =IF(C7<>0,(VLOOKUP($B7,сотрудники!$B$4:$D$217,3,0)),0) -> Ведущий инженер | E7: =IF(D7<>0,(VLOOKUP($B7,сотрудники!$B$4:$E$217,4,0)),0) -> 0 | F7: =SUM(G7:AZ7) -> 104 | N7: 104
A8: 3 | B8: =сотрудники!B7 -> 163 | C8: =IF(B8<>0,(VLOOKUP($B8,сотрудники!$B$4:$D$217,2,0)),0) -> Меньщиков А.В. | D8: =IF(C8<>0,(VLOOKUP($B8,сотрудники!$B$4:$D$217,3,0)),0) -> Ведущий инженер | E8: =IF(D8<>0,(VLOOKUP($B8,сотрудники!$B$4:$E$217,4,0)),0) -> 0 | F8: =SUM(G8:AZ8) -> 104 | N8: 104
A9: 4 | B9: =сотрудники!B8 -> 0 | C9: =IF(B9<>0,(VLOOKUP($B9,сотрудники!$B$4:$D$217,2,0)),0) -> 0 | D9: =IF(C9<>0,(VLOOKUP($B9,сотрудники!$B$4:$D$217,3,0)),0) -> 0 | E9: =IF(D9<>0,(VLOOKUP($B9,сотрудники!$B$4:$E$217,4,0)),0) -> 0 | F9: =SUM(G9:AZ9) -> 104 | N9: 104
A10: 5 | B10: =сотрудники!B9 -> 0 | C10: =IF(B10<>0,(VLOOKUP($B10,сотрудники!$B$4:$D$217,2,0)),0) -> 0 | D10: =IF(C10<>0,(VLOOKUP($B10,сотрудники!$B$4:$D$217,3,0)),0) -> 0 | E10: =IF(D10<>0,(VLOOKUP($B10,сотрудники!$B$4:$E$217,4,0)),0) -> 0 | F10: =SUM(G10:AZ10) -> 88 | N10: 88
A11: 6 | B11: =сотрудники!B10 -> 0 | C11: =IF(B11<>0,(VLOOKUP($B11,сотрудники!$B$4:$D$217,2,0)),0) -> 0 | D11: =IF(C11<>0,(VLOOKUP($B11,сотрудники!$B$4:$D$217,3,0)),0) -> 0 | E11: =IF(D11<>0,(VLOOKUP($B11,сотрудники!$B$4:$E$217,4,0)),0) -> 0 | F11: =SUM(G11:AZ11) -> 24 | N11: 24
A12: 7 | B12: =сотрудники!B11 -> 0 | C12: =IF(B12<>0,(VLOOKUP($B12,сотрудники!$B$4:$D$217,2,0)),0) -> 0 | D12: =IF(C12<>0,(VLOOKUP($B12,сотрудники!$B$4:$D$217,3,0)),0) -> 0 | E12: =IF(D12<>0,(VLOOKUP($B12,сотрудники!$B$4:$E$217,4,0)),0) -> 0 | F12: =SUM(G12:AZ12) -> 104 | N12: 104
A13: 8 | B13: =сотрудники!B12 -> 0 | C13: =IF(B13<>0,(VLOOKUP($B13,сотрудники!$B$4:$D$217,2,0)),0) -> 0 | D13: =IF(C13<>0,(VLOOKUP($B13,сотрудники!$B$4:$D$217,3,0)),0) -> 0 | E13: =IF(D13<>0,(VLOOKUP($B13,сотрудники!$B$4:$E$217,4,0)),0) -> 0 | F13: =SUM(G13:AZ13) -> 104 | N13: 104
A14: 9 | B14: =сотрудники!B15 -> 0 | C14: =IF(B14<>0,(VLOOKUP($B14,сотрудники!$B$4:$D$217,2,0)),0) -> 0 | D14: =IF(C14<>0,(VLOOKUP($B14,сотрудники!$B$4:$D$217,3,0)),0) -> 0 | E14: =IF(D14<>0,(VLOOKUP($B14,сотрудники!$B$4:$E$217,4,0)),0) -> 0 | F14: =SUM(G14:AZ14) -> 104 | N14: 104
A15: 10 | B15: =сотрудники!B19 -> 0 | C15: =IF(B15<>0,(VLOOKUP($B15,сотрудники!$B$4:$D$217,2,0)),0) -> 0 | D15: =IF(C15<>0,(VLOOKUP($B15,сотрудники!$B$4:$D$217,3,0)),0) -> 0 | E15: =IF(D15<>0,(VLOOKUP($B15,сотрудники!$B$4:$E$217,4,0)),0) -> 0 | F15: =SUM(G15:AZ15) -> 104 | N15: 104
A16: 11 | B16: =сотрудники!B20 -> 0 | C16: =IF(B16<>0,(VLOOKUP($B16,сотрудники!$B$4:$D$217,2,0)),0) -> 0 | D16: =IF(C16<>0,(VLOOKUP($B16,сотрудники!$B$4:$D$217,3,0)),0) -> 0 | E16: =IF(D16<>0,(VLOOKUP($B16,сотрудники!$B$4:$E$217,4,0)),0) -> 0 | F16: =SUM(G16:AZ16) -> 32 | N16: 32
A17: 12 | B17: =сотрудники!B21 -> 0 | C17: =IF(B17<>0,(VLOOKUP($B17,сотрудники!$B$4:$D$217,2,0)),0) -> 0 | D17: =IF(C17<>0,(VLOOKUP($B17,сотрудники!$B$4:$D$217,3,0)),0) -> 0 | E17: =IF(D17<>0,(VLOOKUP($B17,сотрудники!$B$4:$E$217,4,0)),0) -> 0 | F17: =SUM(G17:AZ17) -> 104 | N17: 104
A18: 13 | B18: =сотрудники!B24 -> 0 | C18: =IF(B18<>0,(VLOOKUP($B18,сотрудники!$B$4:$D$217,2,0)),0) -> 0 | D18: =IF(C18<>0,(VLOOKUP($B18,сотрудники!$B$4:$D$217,3,0)),0) -> 0 | E18: =IF(D18<>0,(VLOOKUP($B18,сотрудники!$B$4:$E$217,4,0)),0) -> 0 | F18: =SUM(G18:AZ18) -> 24 | N18: 24
A19: 14 | B19: =сотрудники!B25 -> 0 | C19: =IF(B19<>0,(VLOOKUP($B19,сотрудники!$B$4:$D$217,2,0)),0) -> 0 | D19: =IF(C19<>0,(VLOOKUP($B19,сотрудники!$B$4:$D$217,3,0)),0) -> 0 | E19: =IF(D19<>0,(VLOOKUP($B19,сотрудники!$B$4:$E$217,4,0)),0) -> 0 | F19: =SUM(G19:AZ19) -> 80 | N19: 80
A20: 15 | B20: =сотрудники!B29 -> 0 | C20: =IF(B20<>0,(VLOOKUP($B20,сотрудники!$B$4:$D$217,2,0)),0) -> 0 | D20: =IF(C20<>0,(VLOOKUP($B20,сотрудники!$B$4:$D$217,3,0)),0) -> 0 | E20: =IF(D20<>0,(VLOOKUP($B20,сотрудники!$B$4:$E$217,4,0)),0) -> 0 | F20: =SUM(G20:AZ20) -> 64 | N20: 64
A21: 17 | B21: =сотрудники!B32 -> 0 | C21: =IF(B21<>0,(VLOOKUP($B21,сотрудники!$B$4:$D$217,2,0)),0) -> 0 | D21: =IF(C21<>0,(VLOOKUP($B21,сотрудники!$B$4:$D$217,3,0)),0) -> 0 | E21: =IF(D21<>0,(VLOOKUP($B21,сотрудники!$B$4:$E$217,4,0)),0) -> 0 | F21: =SUM(G21:AZ21) -> 80 | N21: 80
A22: 18 | B22: =сотрудники!B33 -> 0 | C22: =IF(B22<>0,(VLOOKUP($B22,сотрудники!$B$4:$D$217,2,0)),0) -> 0 | D22: =IF(C22<>0,(VLOOKUP($B22,сотрудники!$B$4:$D$217,3,0)),0) -> 0 | E22: =IF(D22<>0,(VLOOKUP($B22,сотрудники!$B$4:$E$217,4,0)),0) -> 0 | F22: =SUM(G22:AZ22) -> 80 | N22: 80
A23: 19 | B23: =сотрудники!B34 -> 0 | C23: =IF(B23<>0,(VLOOKUP($B23,сотрудники!$B$4:$D$217,2,0)),0) -> 0 | D23: =IF(C23<>0,(VLOOKUP($B23,сотрудники!$B$4:$D$217,3,0)),0) -> 0 | E23: =IF(D23<>0,(VLOOKUP($B23,сотрудники!$B$4:$E$217,4,0)),0) -> 0 | F23: =SUM(G23:AZ23) -> 80 | N23: 80
A24: 30 | B24: =сотрудники!B35 -> 0 | C24: =IF(B24<>0,(VLOOKUP($B24,сотрудники!$B$4:$D$217,2,0)),0) -> 0 | D24: =IF(C24<>0,(VLOOKUP($B24,сотрудники!$B$4:$D$217,3,0)),0) -> 0 | E24: =IF(D24<>0,(VLOOKUP($B24,сотрудники!$B$4:$E$217,4,0)),0) -> 0 | F24: =SUM(G24:AZ24) -> 24 | N24: 24
A25: 31 | B25: =сотрудники!B36 -> 0 | C25: =IF(B25<>0,(VLOOKUP($B25,сотрудники!$B$4:$D$217,2,0)),0) -> 0 | D25: =IF(C25<>0,(VLOOKUP($B25,сотрудники!$B$4:$D$217,3,0)),0) -> 0 | E25: =IF(D25<>0,(VLOOKUP($B25,сотрудники!$B$4:$E$217,4,0)),0) -> 0 | F25: =SUM(G25:AZ25) -> 24 | N25: 24
A26: 32 | B26: =сотрудники!B37 -> 0 | C26: =IF(B26<>0,(VLOOKUP($B26,сотрудники!$B$4:$D$217,2,0)),0) -> 0 | D26: =IF(C26<>0,(VLOOKUP($B26,сотрудники!$B$4:$D$217,3,0)),0) -> 0 | E26: =IF(D26<>0,(VLOOKUP($B26,сотрудники!$B$4:$E$217,4,0)),0) -> 0 | F26: =SUM(G26:AZ26) -> 24 | N26: 24
A27: 33 | B27: =сотрудники!B38 -> 0 | C27: =IF(B27<>0,(VLOOKUP($B27,сотрудники!$B$4:$D$217,2,0)),0) -> 0 | D27: =IF(C27<>0,(VLOOKUP($B27,сотрудники!$B$4:$D$217,3,0)),0) -> 0 | E27: =IF(D27<>0,(VLOOKUP($B27,сотрудники!$B$4:$E$217,4,0)),0) -> 0 | F27: =SUM(G27:AZ27) -> 24 | N27: 24
A28: 34 | B28: =сотрудники!B39 -> 0 | C28: =IF(B28<>0,(VLOOKUP($B28,сотрудники!$B$4:$D$217,2,0)),0) -> 0 | D28: =IF(C28<>0,(VLOOKUP($B28,сотрудники!$B$4:$D$217,3,0)),0) -> 0 | E28: =IF(D28<>0,(VLOOKUP($B28,сотрудники!$B$4:$E$217,4,0)),0) -> 0 | F28: =SUM(G28:AZ28) -> 64 | N28: 64
A29: 35 | B29: =сотрудники!B40 -> 0 | C29: =IF(B29<>0,(VLOOKUP($B29,сотрудники!$B$4:$D$217,2,0)),0) -> 0 | D29: =IF(C29<>0,(VLOOKUP($B29,сотрудники!$B$4:$D$217,3,0)),0) -> 0 | E29: =IF(D29<>0,(VLOOKUP($B29,сотрудники!$B$4:$E$217,4,0)),0) -> 0 | F29: =SUM(G29:AZ29) -> 104 | N29: 104
A30: 36 | B30: =сотрудники!B114 -> 0 | C30: =IF(B30<>0,(VLOOKUP($B30,сотрудники!$B$4:$D$217,2,0)),0) -> 0 | D30: =IF(C30<>0,(VLOOKUP($B30,сотрудники!$B$4:$D$217,3,0)),0) -> 0 | E30: =IF(D30<>0,(VLOOKUP($B30,сотрудники!$B$4:$E$217,4,0)),0) -> 0 | F30: =SUM(G30:AZ30) -> 0
A31: 37 | B31: =сотрудники!B115 -> 0 | C31: =IF(B31<>0,(VLOOKUP($B31,сотрудники!$B$4:$D$217,2,0)),0) -> 0 | D31: =IF(C31<>0,(VLOOKUP($B31,сотрудники!$B$4:$D$217,3,0)),0) -> 0 | E31: =IF(D31<>0,(VLOOKUP($B31,сотрудники!$B$4:$E$217,4,0)),0) -> 0 | F31: =SUM(G31:AZ31) -> 0
A32: 38 | B32: =сотрудники!B116 -> 0 | C32: =IF(B32<>0,(VLOOKUP($B32,сотрудники!$B$4:$D$217,2,0)),0) -> 0 | D32: =IF(C32<>0,(VLOOKUP($B32,сотрудники!$B$4:$D$217,3,0)),0) -> 0 | E32: =IF(D32<>0,(VLOOKUP($B32,сотрудники!$B$4:$E$217,4,0)),0) -> 0 | F32: =SUM(G32:AZ32) -> 0
A33: 39 | B33: =сотрудники!B117 -> 0 | C33: =IF(B33<>0,(VLOOKUP($B33,сотрудники!$B$4:$D$217,2,0)),0) -> 0 | D33: =IF(C33<>0,(VLOOKUP($B33,сотрудники!$B$4:$D$217,3,0)),0) -> 0 | E33: =IF(D33<>0,(VLOOKUP($B33,сотрудники!$B$4:$E$217,4,0)),0) -> 0 | F33: =SUM(G33:AZ33) -> 0
A34: 40 | B34: =сотрудники!B118 -> 0 | C34: =IF(B34<>0,(VLOOKUP($B34,сотрудники!$B$4:$D$217,2,0)),0) -> 0 | D34: =IF(C34<>0,(VLOOKUP($B34,сотрудники!$B$4:$D$217,3,0)),0) -> 0 | E34: =IF(D34<>0,(VLOOKUP($B34,сотрудники!$B$4:$E$217,4,0)),0) -> 0 | F34: =SUM(G34:AZ34) -> 0
A35: 602 | B35: =сотрудники!B119 -> 0 | C35: =IF(B35<>0,(VLOOKUP($B35,сотрудники!$B$4:$D$217,2,0)),0) -> 0 | D35: =IF(C35<>0,(VLOOKUP($B35,сотрудники!$B$4:$D$217,3,0)),0) -> 0 | E35: =IF(D35<>0,(VLOOKUP($B35,сотрудники!$B$4:$E$217,4,0)),0) -> 0 | F35: =SUM(G35:AZ35) -> 0
A36: 603 | B36: =сотрудники!B120 -> 0 | C36: =IF(B36<>0,(VLOOKUP($B36,сотрудники!$B$4:$D$217,2,0)),0) -> 0 | D36: =IF(C36<>0,(VLOOKUP($B36,сотрудники!$B$4:$D$217,3,0)),0) -> 0 | E36: =IF(D36<>0,(VLOOKUP($B36,сотрудники!$B$4:$E$217,4,0)),0) -> 0 | F36: =SUM(G36:AZ36) -> 0
A37: 604 | B37: =сотрудники!B121 -> 0 | C37: =IF(B37<>0,(VLOOKUP($B37,сотрудники!$B$4:$D$217,2,0)),0) -> 0 | D37: =IF(C37<>0,(VLOOKUP($B37,сотрудники!$B$4:$D$217,3,0)),0) -> 0 | E37: =IF(D37<>0,(VLOOKUP($B37,сотрудники!$B$4:$E$217,4,0)),0) -> 0 | F37: =SUM(G37:AZ37) -> 0
A38: 605 | B38: =сотрудники!B122 -> 0 | C38: =IF(B38<>0,(VLOOKUP($B38,сотрудники!$B$4:$D$217,2,0)),0) -> 0 | D38: =IF(C38<>0,(VLOOKUP($B38,сотрудники!$B$4:$D$217,3,0)),0) -> 0 | E38: =IF(D38<>0,(VLOOKUP($B38,сотрудники!$B$4:$E$217,4,0)),0) -> 0 | F38: =SUM(G38:AZ38) -> 0
A39: 606 | B39: =сотрудники!B123 -> 0 | C39: =IF(B39<>0,(VLOOKUP($B39,сотрудники!$B$4:$D$217,2,0)),0) -> 0 | D39: =IF(C39<>0,(VLOOKUP($B39,сотрудники!$B$4:$D$217,3,0)),0) -> 0 | E39: =IF(D39<>0,(VLOOKUP($B39,сотрудники!$B$4:$E$217,4,0)),0) -> 0 | F39: =SUM(G39:AZ39) -> 0
A40: 607 | B40: =сотрудники!B124 -> 0 | C40: =IF(B40<>0,(VLOOKUP($B40,сотрудники!$B$4:$D$217,2,0)),0) -> 0 | D40: =IF(C40<>0,(VLOOKUP($B40,сотрудники!$B$4:$D$217,3,0)),0) -> 0 | E40: =IF(D40<>0,(VLOOKUP($B40,сотрудники!$B$4:$E$217,4,0)),0) -> 0 | F40: =SUM(G40:AZ40) -> 0
A41: 608 | B41: =сотрудники!B125 -> 0 | C41: =IF(B41<>0,(VLOOKUP($B41,сотрудники!$B$4:$D$217,2,0)),0) -> 0 | D41: =IF(C41<>0,(VLOOKUP($B41,сотрудники!$B$4:$D$217,3,0)),0) -> 0 | E41: =IF(D41<>0,(VLOOKUP($B41,сотрудники!$B$4:$E$217,4,0)),0) -> 0 | F41: =SUM(G41:AZ41) -> 0
... A133: 700 | B133: =сотрудники!B217 -> 0 | C133: =IF(B133<>0,(VLOOKUP($B133,сотрудники!$B$4:$D$217,2,0)),0) -> 0 | D133: =IF(C133<>0,(VLOOKUP($B133,сотрудники!$B$4:$D$217,3,0)),0) -> 0 | E133: =IF(D133<>0,(VLOOKUP($B133,сотрудники!$B$4:$E$217,4,0)),0) -> 0 | F133: =SUM(G133:AZ133) -> 0

Sheet месяц
A3: январь
A4: февраль
A5: март
A6: апрель
A7: май
A8: июнь
A9: июль
A10: август
A11: сентябрь
A12: октябрь
A13: ноябрь
A14: декабрь

Sheet Август 2024
A1: ООО Инженерная инфраструктура | E1: месяц: | F1: август
A4: № п.п. | B4: Табельный номер (автозаполнение) | C4: ФИО сотрудника (автозаполнение) | D4: Должность (автозаполнение) | E4: Подразделение (автозаполнение) | F4: Всего отработано часов в смену | H4: Спортивные объекты | L4: Спец.обекты | N4: Горный кластер | P4: Центр-альная служба | Q4: Образовательные объекты | Y4: Административные здания | AA4: Прочее | AG4: Гостиничные объекты | AR4: Коммерческие договоры
H5: ЛД Айсберг и ТА | I5: ЛД Шайба и ТА | J5: Сириус Арена | K5: Спортивный Парк | L5: Спорткомплекс_Инжирная_300/23 (50%) | M5: Спорткомплекс_Кур.пр._312/23 (50%) | N5: КТ | O5: СБТ | Q5: Кампус ОЦ "Сириус" | R5: Корпус Спорт | S5: Корпус Школа | T5: Лицей Международная, 10 | U5: ПЛ Школа Воскресенская, 18 | V5: ДДУ Воскресенская, 16 | W5: Бассейн_Воскресенская, 18 | X5: Унивеситет "Сириус" (ПНИИ "Сириус") | Y5: Международная, 4 (10%) | Z5: Международная, 2 (90%) | AA5: Планетарий "Сириус" | AB5: Концертный комплекс | AC5: Квартирный фонд Худякова | AD5: Квартирный фонд Эстонская | AE5: Территория Олимпийского Парк | AF5: Технико-внедренческая зона (РЖД) | AG5: Гостиница "Альфа Сириус" | AH5: Комплекс апартаментов, Парусная д.10,12 | AI5: Гостиница "Дельта Сириус" | AJ5: Гостиница "Омега Сириус" | AK5: Гостиница "Гамма Сириус" | AL5: Гостиница "Сигма Сириус" (квартал А) | AM5: Сигма Сириус (квартал Б) (90 %) | AN5: Сигма Сириус (квартал Г) (10 %) | AO5: Хостел «S Hostel» | AP5: Триумфальный проезд 3, Пульсар | AQ5: НИЦ Автодром | AR5: 04/24-3007/01 КЦ_Университет «Сириус» (ПНиИ «Сириус») | AS5: 315/02 УК_Апарт-отель_«Альфа Сириус» | AT5: 03/07-1/5 КЦ Масленица_Территория Олимпийского парка
A6: 1 | B6: 255 | C6: =IF(B6<>0,(VLOOKUP($B6,сотрудники!$B$4:$D$217,2,0)),0) -> Хабаров Д.Б. | D6: =IF(C6<>0,(VLOOKUP($B6,сотрудники!$B$4:$D$217,3,0)),0) -> Руководитель группы | E6: =IF(D6<>0,(VLOOKUP($B6,сотрудники!$B$4:$E$217,4,0)),0) -> Производственно-технический отдел | F6: =SUM(H6:AT6) -> 176 | H6: 10 | I6: 10 | J6: 10 | Q6: 10 | R6: 6 | S6: 6 | T6: 6 | U6: 6 | V6: 6 | X6: 42 | Y6: 2 | Z6: 10 | AI6: 24 | AJ6: 12 | AP6: 16
F7: =SUM(H7:AT7) -> 1 | G7: Итого % | H7: =SUM(H6)/SUM($H$6:$AT$6) -> 0.056818182 | I7: =SUM(I6)/SUM($H$6:$AT$6) -> 0.056818182 | J7: =SUM(J6)/SUM($H$6:$AT$6) -> 0.056818182 | K7: =SUM(K6)/SUM($H$6:$AT$6) -> 0 | L7: =SUM(L6)/SUM($H$6:$AT$6) -> 0 | M7: =SUM(M6)/SUM($H$6:$AT$6) -> 0 | N7: =SUM(N6)/SUM($H$6:$AT$6) -> 0 | O7: =SUM(O6)/SUM($H$6:$AT$6) -> 0 | ... AT7: =SUM(AT6)/SUM($H$6:$AT$6) -> 0
A8: 2 | B8: 166 | C8: =IF(B8<>0,(VLOOKUP($B8,сотрудники!$B$4:$D$217,2,0)),0) -> Агеев В.А. | D8: =IF(C8<>0,(VLOOKUP($B8,сотрудники!$B$4:$D$217,3,0)),0) -> Ведущий инженер | E8: =IF(D8<>0,(VLOOKUP($B8,сотрудники!$B$4:$E$217,4,0)),0) -> ИТС / Отдел главного энергетика | F8: =SUM(H8:AT8) -> 176 | H8: 12 | I8: 12 | J8: 12 | AK8: 44 | AL8: 46 | AM8: 40 | AN8: 10
F9: =SUM(H9:AT9) -> 1 | G9: Итого % | H9: =SUM(H8)/SUM($H$8:$AT$8) -> 0.068181818 | I9: =SUM(I8)/SUM($H$8:$AT$8) -> 0.068181818 | J9: =SUM(J8)/SUM($H$8:$AT$8) -> 0.068181818 | K9: =SUM(K8)/SUM($H$8:$AT$8) -> 0 | L9: =SUM(L8)/SUM($H$8:$AT$8) -> 0 | M9: =SUM(M8)/SUM($H$8:$AT$8) -> 0 | N9: =SUM(N8)/SUM($H$8:$AT$8) -> 0 | O9: =SUM(O8)/SUM($H$8:$AT$8) -> 0 | ... AT9: =SUM(AT8)/SUM($H$8:$AT$8) -> 0
A10: 3 | B10: 167 | C10: =IF(B10<>0,(VLOOKUP($B10,сотрудники!$B$4:$D$217,2,0)),0) -> Линев А.В. | D10: =IF(C10<>0,(VLOOKUP($B10,сотрудники!$B$4:$D$217,3,0)),0) -> Ведущий инженер | E10: =IF(D10<>0,(VLOOKUP($B10,сотрудники!$B$4:$E$217,4,0)),0) -> 0 | F10: =SUM(H10:AT10) -> 128 | H10: 20 | I10: 18 | Q10: 10 | T10: 6 | AG10: 50 | AH10: 16 | AJ10: 4 | AQ10: 4
F11: =SUM(H11:AT11) -> 1 | G11: Итого % | H11: =SUM(H10)/SUM($H$10:$AT$10) -> 0.15625 | I11: =SUM(I10)/SUM($H$10:$AT$10) -> 0.140625 | J11: =SUM(J10)/SUM($H$10:$AT$10) -> 0 | K11: =SUM(K10)/SUM($H$10:$AT$10) -> 0 | L11: =SUM(L10)/SUM($H$10:$AT$10) -> 0 | M11: =SUM(M10)/SUM($H$10:$AT$10) -> 0 | N11: =SUM(N10)/SUM($H$10:$AT$10) -> 0 | O11: =SUM(O10)/SUM($H$10:$AT$10) -> 0 | ... AT11: =SUM(AT10)/SUM($H$10:$AT$10) -> 0
A12: 4 | B12: 163 | C12: =IF(B12<>0,(VLOOKUP($B12,сотрудники!$B$4:$D$217,2,0)),0) -> Меньщиков А.В. | D12: =IF(C12<>0,(VLOOKUP($B12,сотрудники!$B$4:$D$217,3,0)),0) -> Ведущий инженер | E12: =IF(D12<>0,(VLOOKUP($B12,сотрудники!$B$4:$E$217,4,0)),0) -> 0 | F12: =SUM(H12:AT12) -> 176 | H12: 56 | N12: 20 | Q12: 14 | U12: 12 | V12: 12 | X12: 10 | AL12: 12 | AQ12: 40
F13: =SUM(H13:AT13) -> 1 | G13: Итого % | H13: =SUM(H12)/SUM($H$12:$AT$12) -> 0.31818182 | I13: =SUM(I12)/SUM($H$12:$AT$12) -> 0 | J13: =SUM(J12)/SUM($H$12:$AT$12) -> 0 | K13: =SUM(K12)/SUM($H$12:$AT$12) -> 0 | L13: =SUM(L12)/SUM($H$12:$AT$12) -> 0 | M13: =SUM(M12)/SUM($H$12:$AT$12) -> 0 | N13: =SUM(N12)/SUM($H$12:$AT$12) -> 0.11363636 | O13: =SUM(O12)/SUM($H$12:$AT$12) -> 0 | ... AT13: =SUM(AT12)/SUM($H$12:$AT$12) -> 0

Sheet Сентябрь
A1: ООО Инженерная инфраструктура | E1: месяц: | F1: сентябрь
A4: № п.п. | B4: Табельный номер (автозаполнение) | C4: ФИО сотрудника (автозаполнение) | D4: Должность (автозаполнение) | E4: Подразделение (автозаполнение) | F4: Всего отработано часов в смену | G4: часы работы на объектах
G5: Айсберг и ТА | H5: МЛАХ и ТА | I5: Сириус Арена | J5: Спортивный Парк | K5: Спец Объект | L5: КТ | M5: СБТ | N5: ЦС | O5: Академия Единоборств (ЦПС) | P5: Академия Единоборств (УСТК1) | Q5: Академия Единоборств (УСТК2) | R5: Капмус ОЦ | S5: Корпус Спорт ОЦ | T5: Корпус Школа ОЦ | U5: Международная, 10 (Лицей) | V5: ПЛ Школа | W5: ПЛ ДДУ | X5: ПЛ Бассейн | Y5: ПНиИ | Z5: Админ. здания ОП | AA5: Планетарий | AB5: Концертный | AC5: Квартиры Худякова | AD5: Квартиры Эстонская | AE5: Олимп. Парк | AF5: РЖД | AG5: Парусная | AH5: Дельта | AI5: Омега | AJ5: Гамма | AK5: Сигма А | AL5: Сигма Б,В,Г | AM5: Хостел S | AN5: Русские сезоны
A6: 1 | B6: 90 | C6: =IF(B6<>0,(VLOOKUP($B6,сотрудники!$B$4:$D$217,2,0)),0) -> #N/A | D6: =IF(C6<>0,(VLOOKUP($B6,сотрудники!$B$4:$D$217,3,0)),0) -> #N/A | E6: =IF(D6<>0,(VLOOKUP($B6,сотрудники!$B$4:$E$217,4,0)),0) -> #N/A | F6: =SUM(G6:AZ6) -> 143 | AH6: 143
A7: 2 | B7: 147 | C7: =IF(B7<>0,(VLOOKUP($B7,сотрудники!$B$4:$D$217,2,0)),0) -> #N/A | D7: =IF(C7<>0,(VLOOKUP($B7,сотрудники!$B$4:$D$217,3,0)),0) -> #N/A | E7: =IF(D7<>0,(VLOOKUP($B7,сотрудники!$B$4:$E$217,4,0)),0) -> #N/A | F7: =SUM(G7:AZ7) -> 121 | AJ7: 121
A8: 3 | B8: 150 | C8: =IF(B8<>0,(VLOOKUP($B8,сотрудники!$B$4:$D$217,2,0)),0) -> #N/A | D8: =IF(C8<>0,(VLOOKUP($B8,сотрудники!$B$4:$D$217,3,0)),0) -> #N/A | E8: =IF(D8<>0,(VLOOKUP($B8,сотрудники!$B$4:$E$217,4,0)),0) -> #N/A | F8: =SUM(G8:AZ8) -> 88 | AJ8: 88
A9: 4 | B9: 96 | C9: =IF(B9<>0,(VLOOKUP($B9,сотрудники!$B$4:$D$217,2,0)),0) -> #N/A | D9: =IF(C9<>0,(VLOOKUP($B9,сотрудники!$B$4:$D$217,3,0)),0) -> #N/A | E9: =IF(D9<>0,(VLOOKUP($B9,сотрудники!$B$4:$E$217,4,0)),0) -> #N/A | F9: =SUM(G9:AZ9) -> 132 | O9: 132
A10: 5 | B10: 177 | C10: =IF(B10<>0,(VLOOKUP($B10,сотрудники!$B$4:$D$217,2,0)),0) -> #N/A | D10: =IF(C10<>0,(VLOOKUP($B10,сотрудники!$B$4:$D$217,3,0)),0) -> #N/A | E10: =IF(D10<>0,(VLOOKUP($B10,сотрудники!$B$4:$E$217,4,0)),0) -> #N/A | F10: =SUM(G10:AZ10) -> 64 | AJ10: 64
A11: 6 | B11: 77 | C11: =IF(B11<>0,(VLOOKUP($B11,сотрудники!$B$4:$D$217,2,0)),0) -> #N/A | D11: =IF(C11<>0,(VLOOKUP($B11,сотрудники!$B$4:$D$217,3,0)),0) -> #N/A | E11: =IF(D11<>0,(VLOOKUP($B11,сотрудники!$B$4:$E$217,4,0)),0) -> #N/A | F11: =SUM(G11:AZ11) -> 120 | AK11: 40 | AL11: 80
A12: 7 | B12: 171 | C12: =IF(B12<>0,(VLOOKUP($B12,сотрудники!$B$4:$D$217,2,0)),0) -> #N/A | D12: =IF(C12<>0,(VLOOKUP($B12,сотрудники!$B$4:$D$217,3,0)),0) -> #N/A | E12: =IF(D12<>0,(VLOOKUP($B12,сотрудники!$B$4:$E$217,4,0)),0) -> #N/A | F12: =SUM(G12:AZ12) -> 99 | Y12: 99
A13: 8 | B13: 97 | C13: =IF(B13<>0,(VLOOKUP($B13,сотрудники!$B$4:$D$217,2,0)),0) -> #N/A | D13: =IF(C13<>0,(VLOOKUP($B13,сотрудники!$B$4:$D$217,3,0)),0) -> #N/A | E13: =IF(D13<>0,(VLOOKUP($B13,сотрудники!$B$4:$E$217,4,0)),0) -> #N/A | F13: =SUM(G13:AZ13) -> 132 | I13: 132
A14: 9 | B14: 92 | C14: =IF(B14<>0,(VLOOKUP($B14,сотрудники!$B$4:$D$217,2,0)),0) -> #N/A | D14: =IF(C14<>0,(VLOOKUP($B14,сотрудники!$B$4:$D$217,3,0)),0) -> #N/A | E14: =IF(D14<>0,(VLOOKUP($B14,сотрудники!$B$4:$E$217,4,0)),0) -> #N/A | F14: =SUM(G14:AZ14) -> 48 | H14: 24 | J14: 24
A15: 10 | B15: 145 | C15: =IF(B15<>0,(VLOOKUP($B15,сотрудники!$B$4:$D$217,2,0)),0) -> #N/A | D15: =IF(C15<>0,(VLOOKUP($B15,сотрудники!$B$4:$D$217,3,0)),0) -> #N/A | E15: =IF(D15<>0,(VLOOKUP($B15,сотрудники!$B$4:$E$217,4,0)),0) -> #N/A | F15: =SUM(G15:AZ15) -> 112 | AK15: 38 | AL15: 74
A16: 11 | B16: 100 | C16: =IF(B16<>0,(VLOOKUP($B16,сотрудники!$B$4:$D$217,2,0)),0) -> #N/A | D16: =IF(C16<>0,(VLOOKUP($B16,сотрудники!$B$4:$D$217,3,0)),0) -> #N/A | E16: =IF(D16<>0,(VLOOKUP($B16,сотрудники!$B$4:$E$217,4,0)),0) -> #N/A | F16: =SUM(G16:AZ16) -> 132 | U16: 33 | V16: 33 | W16: 33 | X16: 33
A17: 12 | B17: 257 | C17: =IF(B17<>0,(VLOOKUP($B17,сотрудники!$B$4:$D$217,2,0)),0) -> #N/A | D17: =IF(C17<>0,(VLOOKUP($B17,сотрудники!$B$4:$D$217,3,0)),0) -> #N/A | E17: =IF(D17<>0,(VLOOKUP($B17,сотрудники!$B$4:$E$217,4,0)),0) -> #N/A | F17: =SUM(G17:AZ17) -> 88 | Y17: 88
A18: 13 | B18: 173 | C18: =IF(B18<>0,(VLOOKUP($B18,сотрудники!$B$4:$D$217,2,0)),0) -> #N/A | D18: =IF(C18<>0,(VLOOKUP($B18,сотрудники!$B$4:$D$217,3,0)),0) -> #N/A | E18: =IF(D18<>0,(VLOOKUP($B18,сотрудники!$B$4:$E$217,4,0)),0) -> #N/A | F18: =SUM(G18:AZ18) -> 99 | H18: 99
A19: 14 | B19: 174 | C19: =IF(B19<>0,(VLOOKUP($B19,сотрудники!$B$4:$D$217,2,0)),0) -> #N/A | D19: =IF(C19<>0,(VLOOKUP($B19,сотрудники!$B$4:$D$217,3,0)),0) -> #N/A | E19: =IF(D19<>0,(VLOOKUP($B19,сотрудники!$B$4:$E$217,4,0)),0) -> #N/A | F19: =SUM(G19:AZ19) -> 88 | U19: 22 | V19: 22 | W19: 22 | X19: 22
A20: 15 | B20: 98 | C20: =IF(B20<>0,(VLOOKUP($B20,сотрудники!$B$4:$D$217,2,0)),0) -> #N/A | D20: =IF(C20<>0,(VLOOKUP($B20,сотрудники!$B$4:$D$217,3,0)),0) -> #N/A | E20: =IF(D20<>0,(VLOOKUP($B20,сотрудники!$B$4:$E$217,4,0)),0) -> #N/A | F20: =SUM(G20:AZ20) -> 132 | R20: 44 | S20: 44 | T20: 44
A21: 16 | B21: 206 | C21: =IF(B21<>0,(VLOOKUP($B21,сотрудники!$B$4:$D$217,2,0)),0) -> #N/A | D21: =IF(C21<>0,(VLOOKUP($B21,сотрудники!$B$4:$D$217,3,0)),0) -> #N/A | E21: =IF(D21<>0,(VLOOKUP($B21,сотрудники!$B$4:$E$217,4,0)),0) -> #N/A | F21: =SUM(G21:AZ21) -> 88 | Y21: 88
A22: 17 | B22: 121 | C22: =IF(B22<>0,(VLOOKUP($B22,сотрудники!$B$4:$D$217,2,0)),0) -> #N/A | D22: =IF(C22<>0,(VLOOKUP($B22,сотрудники!$B$4:$D$217,3,0)),0) -> #N/A | E22: =IF(D22<>0,(VLOOKUP($B22,сотрудники!$B$4:$E$217,4,0)),0) -> #N/A | F22: =SUM(G22:AZ22) -> 121 | AH22: 121
A23: 18 | B23: 94 | C23: =IF(B23<>0,(VLOOKUP($B23,сотрудники!$B$4:$D$217,2,0)),0) -> #N/A | D23: =IF(C23<>0,(VLOOKUP($B23,сотрудники!$B$4:$D$217,3,0)),0) -> #N/A | E23: =IF(D23<>0,(VLOOKUP($B23,сотрудники!$B$4:$E$217,4,0)),0) -> #N/A | F23: =SUM(G23:AZ23) -> 143 | H23: 143
A24: 19 | B24: 99 | C24: =IF(B24<>0,(VLOOKUP($B24,сотрудники!$B$4:$D$217,2,0)),0) -> #N/A | D24: =IF(C24<>0,(VLOOKUP($B24,сотрудники!$B$4:$D$217,3,0)),0) -> #N/A | E24: =IF(D24<>0,(VLOOKUP($B24,сотрудники!$B$4:$E$217,4,0)),0) -> #N/A | F24: =SUM(G24:AZ24) -> 73 | R24: 25 | S24: 24 | T24: 24
A25: 20 | B25: 91 | C25: =IF(B25<>0,(VLOOKUP($B25,сотрудники!$B$4:$D$217,2,0)),0) -> #N/A | D25: =IF(C25<>0,(VLOOKUP($B25,сотрудники!$B$4:$D$217,3,0)),0) -> #N/A | E25: =IF(D25<>0,(VLOOKUP($B25,сотрудники!$B$4:$E$217,4,0)),0) -> #N/A | F25: =SUM(G25:AZ25) -> 121 | G25: 121
A26: 21 | B26: 86 | C26: =IF(B26<>0,(VLOOKUP($B26,сотрудники!$B$4:$D$217,2,0)),0) -> #N/A | D26: =IF(C26<>0,(VLOOKUP($B26,сотрудники!$B$4:$D$217,3,0)),0) -> #N/A | E26: =IF(D26<>0,(VLOOKUP($B26,сотрудники!$B$4:$E$217,4,0)),0) -> #N/A | F26: =SUM(G26:AZ26) -> 141 | AK26: 47 | AL26: 94
A27: 22 | B27: 181 | C27: =IF(B27<>0,(VLOOKUP($B27,сотрудники!$B$4:$D$217,2,0)),0) -> #N/A | D27: =IF(C27<>0,(VLOOKUP($B27,сотрудники!$B$4:$D$217,3,0)),0) -> #N/A | E27: =IF(D27<>0,(VLOOKUP($B27,сотрудники!$B$4:$E$217,4,0)),0) -> #N/A | F27: =SUM(G27:AZ27) -> 88 | I27: 44 | O27: 44
A28: 23 | B28: 93 | C28: =IF(B28<>0,(VLOOKUP($B28,сотрудники!$B$4:$D$217,2,0)),0) -> #N/A | D28: =IF(C28<>0,(VLOOKUP($B28,сотрудники!$B$4:$D$217,3,0)),0) -> #N/A | E28: =IF(D28<>0,(VLOOKUP($B28,сотрудники!$B$4:$E$217,4,0)),0) -> #N/A | F28: =SUM(G28:AZ28) -> 121 | O28: 121
A29: 24 | B29: 124 | C29: =IF(B29<>0,(VLOOKUP($B29,сотрудники!$B$4:$D$217,2,0)),0) -> #N/A | D29: =IF(C29<>0,(VLOOKUP($B29,сотрудники!$B$4:$D$217,3,0)),0) -> #N/A | E29: =IF(D29<>0,(VLOOKUP($B29,сотрудники!$B$4:$E$217,4,0)),0) -> #N/A | F29: =SUM(G29:AZ29) -> 112 | U29: 28 | V29: 28 | W29: 28 | X29: 28
A30: 25 | B30: 170 | C30: =IF(B30<>0,(VLOOKUP($B30,сотрудники!$B$4:$D$217,2,0)),0) -> #N/A | D30: =IF(C30<>0,(VLOOKUP($B30,сотрудники!$B$4:$D$217,3,0)),0) -> #N/A | E30: =IF(D30<>0,(VLOOKUP($B30,сотрудники!$B$4:$E$217,4,0)),0) -> #N/A | F30: =SUM(G30:AZ30) -> 99 | I30: 99
A31: 26 | B31: 208 | C31: =IF(B31<>0,(VLOOKUP($B31,сотрудники!$B$4:$D$217,2,0)),0) -> #N/A | D31: =IF(C31<>0,(VLOOKUP($B31,сотрудники!$B$4:$D$217,3,0)),0) -> #N/A | E31: =IF(D31<>0,(VLOOKUP($B31,сотрудники!$B$4:$E$217,4,0)),0) -> #N/A | F31: =SUM(G31:AZ31) -> 66 | Y31: 66
A32: 27 | B32: 267 | C32: =IF(B32<>0,(VLOOKUP($B32,сотрудники!$B$4:$D$217,2,0)),0) -> #N/A | D32: =IF(C32<>0,(VLOOKUP($B32,сотрудники!$B$4:$D$217,3,0)),0) -> #N/A | E32: =IF(D32<>0,(VLOOKUP($B32,сотрудники!$B$4:$E$217,4,0)),0) -> #N/A | F32: =SUM(G32:AZ32) -> 66 | Y32: 66
A33: 28 | B33: 95 | C33: =IF(B33<>0,(VLOOKUP($B33,сотрудники!$B$4:$D$217,2,0)),0) -> #N/A | D33: =IF(C33<>0,(VLOOKUP($B33,сотрудники!$B$4:$D$217,3,0)),0) -> #N/A | E33: =IF(D33<>0,(VLOOKUP($B33,сотрудники!$B$4:$E$217,4,0)),0) -> #N/A | F33: =SUM(G33:AZ33) -> 132 | G33: 132

Sheet Октябрь
A1: ООО Инженерная инфраструктура | E1: месяц: | F1: октябрь
A4: № п.п. | B4: Табельный номер (автозаполнение) | C4: ФИО сотрудника (автозаполнение) | D4: Должность (автозаполнение) | E4: Подразделение (автозаполнение) | F4: Всего отработано часов в смену | G4: часы работы на объектах
G5: Айсберг и ТА | H5: МЛАХ и ТА | I5: Сириус Арена | J5: Спортивный Парк | K5: Спец Объект | L5: КТ | M5: СБТ | N5: ЦС | O5: Академия Единоборств (ЦПС) | P5: Академия Единоборств (УСТК1) | Q5: Академия Единоборств (УСТК2) | R5: Капмус ОЦ | S5: Корпус Спорт ОЦ | T5: Корпус Школа ОЦ | U5: Международная, 10 (Лицей) | V5: ПЛ Школа | W5: ПЛ ДДУ | X5: ПЛ Бассейн | Y5: ПНиИ | Z5: Админ. здания ОП | AA5: Планетарий | AB5: Концертный | AC5: Квартиры Худякова | AD5: Квартиры Эстонская | AE5: Олимп. Парк | AF5: РЖД | AG5: Парусная | AH5: Дельта | AI5: Омега | AJ5: Гамма | AK5: Сигма А | AL5: Сигма Б,В,Г | AM5: Хостел S | AN5: Русские сезоны
A6: 1 | B6: 90 | C6: =IF(B6<>0,(VLOOKUP($B6,сотрудники!$B$4:$D$217,2,0)),0) -> #N/A | D6: =IF(C6<>0,(VLOOKUP($B6,сотрудники!$B$4:$D$217,3,0)),0) -> #N/A | E6: =IF(D6<>0,(VLOOKUP($B6,сотрудники!$B$4:$E$217,4,0)),0) -> #N/A | F6: =SUM(G6:AZ6) -> 165 | AH6: 165
A7: 2 | B7: 147 | C7: =IF(B7<>0,(VLOOKUP($B7,сотрудники!$B$4:$D$217,2,0)),0) -> #N/A | D7: =IF(C7<>0,(VLOOKUP($B7,сотрудники!$B$4:$D$217,3,0)),0) -> #N/A | E7: =IF(D7<>0,(VLOOKUP($B7,сотрудники!$B$4:$E$217,4,0)),0) -> #N/A | F7: =SUM(G7:AZ7) -> 154 | AJ7: 154
A8: 3 | B8: 150 | C8: =IF(B8<>0,(VLOOKUP($B8,сотрудники!$B$4:$D$217,2,0)),0) -> #N/A | D8: =IF(C8<>0,(VLOOKUP($B8,сотрудники!$B$4:$D$217,3,0)),0) -> #N/A | E8: =IF(D8<>0,(VLOOKUP($B8,сотрудники!$B$4:$E$217,4,0)),0) -> #N/A | F8: =SUM(G8:AZ8) -> 176 | AJ8: 176
A9: 4 | B9: 96 | C9: =IF(B9<>0,(VLOOKUP($B9,сотрудники!$B$4:$D$217,2,0)),0) -> #N/A | D9: =IF(C9<>0,(VLOOKUP($B9,сотрудники!$B$4:$D$217,3,0)),0) -> #N/A | E9: =IF(D9<>0,(VLOOKUP($B9,сотрудники!$B$4:$E$217,4,0)),0) -> #N/A | F9: =SUM(G9:AZ9) -> 165 | O9: 165
A10: 5 | B10: 177 | C10: =IF(B10<>0,(VLOOKUP($B10,сотрудники!$B$4:$D$217,2,0)),0) -> #N/A | D10: =IF(C10<>0,(VLOOKUP($B10,сотрудники!$B$4:$D$217,3,0)),0) -> #N/A | E10: =IF(D10<>0,(VLOOKUP($B10,сотрудники!$B$4:$E$217,4,0)),0) -> #N/A | F10: =SUM(G10:AZ10) -> 165 | AJ10: 165
A11: 6 | B11: 77 | C11: =IF(B11<>0,(VLOOKUP($B11,сотрудники!$B$4:$D$217,2,0)),0) -> #N/A | D11: =IF(C11<>0,(VLOOKUP($B11,сотрудники!$B$4:$D$217,3,0)),0) -> #N/A | E11: =IF(D11<>0,(VLOOKUP($B11,сотрудники!$B$4:$E$217,4,0)),0) -> #N/A | F11: =SUM(G11:AZ11) -> 200 | AK11: 80 | AL11: 120
A12: 7 | B12: 171 | C12: =IF(B12<>0,(VLOOKUP($B12,сотрудники!$B$4:$D$217,2,0)),0) -> #N/A | D12: =IF(C12<>0,(VLOOKUP($B12,сотрудники!$B$4:$D$217,3,0)),0) -> #N/A | E12: =IF(D12<>0,(VLOOKUP($B12,сотрудники!$B$4:$E$217,4,0)),0) -> #N/A | F12: =SUM(G12:AZ12) -> 176 | Y12: 176
A13: 8 | B13: 97 | C13: =IF(B13<>0,(VLOOKUP($B13,сотрудники!$B$4:$D$217,2,0)),0) -> #N/A | D13: =IF(C13<>0,(VLOOKUP($B13,сотрудники!$B$4:$D$217,3,0)),0) -> #N/A | E13: =IF(D13<>0,(VLOOKUP($B13,сотрудники!$B$4:$E$217,4,0)),0) -> #N/A | F13: =SUM(G13:AZ13) -> 132 | I13: 132
A14: 9 | B14: 92 | C14: =IF(B14<>0,(VLOOKUP($B14,сотрудники!$B$4:$D$217,2,0)),0) -> #N/A | D14: =IF(C14<>0,(VLOOKUP($B14,сотрудники!$B$4:$D$217,3,0)),0) -> #N/A | E14: =IF(D14<>0,(VLOOKUP($B14,сотрудники!$B$4:$E$217,4,0)),0) -> #N/A | F14: =SUM(G14:AZ14) -> 176 | H14: 88 | J14: 88
A15: 10 | B15: 145 | C15: =IF(B15<>0,(VLOOKUP($B15,сотрудники!$B$4:$D$217,2,0)),0) -> #N/A | D15: =IF(C15<>0,(VLOOKUP($B15,сотрудники!$B$4:$D$217,3,0)),0) -> #N/A | E15: =IF(D15<>0,(VLOOKUP($B15,сотрудники!$B$4:$E$217,4,0)),0) -> #N/A | F15: =SUM(G15:AZ15) -> 176 | AK15: 56 | AL15: 120
A16: 11 | B16: 100 | C16: =IF(B16<>0,(VLOOKUP($B16,сотрудники!$B$4:$D$217,2,0)),0) -> #N/A | D16: =IF(C16<>0,(VLOOKUP($B16,сотрудники!$B$4:$D$217,3,0)),0) -> #N/A | E16: =IF(D16<>0,(VLOOKUP($B16,сотрудники!$B$4:$E$217,4,0)),0) -> #N/A | F16: =SUM(G16:AZ16) -> 165 | U16: 41 | V16: 41 | W16: 41 | X16: 42
A17: 12 | B17: 257 | C17: =IF(B17<>0,(VLOOKUP($B17,сотрудники!$B$4:$D$217,2,0)),0) -> #N/A | D17: =IF(C17<>0,(VLOOKUP($B17,сотрудники!$B$4:$D$217,3,0)),0) -> #N/A | E17: =IF(D17<>0,(VLOOKUP($B17,сотрудники!$B$4:$E$217,4,0)),0) -> #N/A | F17: =SUM(G17:AZ17) -> 176 | Y17: 176
A18: 13 | B18: 173 | C18: =IF(B18<>0,(VLOOKUP($B18,сотрудники!$B$4:$D$217,2,0)),0) -> #N/A | D18: =IF(C18<>0,(VLOOKUP($B18,сотрудники!$B$4:$D$217,3,0)),0) -> #N/A | E18: =IF(D18<>0,(VLOOKUP($B18,сотрудники!$B$4:$E$217,4,0)),0) -> #N/A | F18: =SUM(G18:AZ18) -> 176 | H18: 176
A19: 14 | B19: 174 | C19: =IF(B19<>0,(VLOOKUP($B19,сотрудники!$B$4:$D$217,2,0)),0) -> #N/A | D19: =IF(C19<>0,(VLOOKUP($B19,сотрудники!$B$4:$D$217,3,0)),0) -> #N/A | E19: =IF(D19<>0,(VLOOKUP($B19,сотрудники!$B$4:$E$217,4,0)),0) -> #N/A | F19: =SUM(G19:AZ19) -> 88 | U19: 22 | V19: 22 | W19: 22 | X19: 22
A20: 15 | B20: 98 | C20: =IF(B20<>0,(VLOOKUP($B20,сотрудники!$B$4:$D$217,2,0)),0) -> #N/A | D20: =IF(C20<>0,(VLOOKUP($B20,сотрудники!$B$4:$D$217,3,0)),0) -> #N/A | E20: =IF(D20<>0,(VLOOKUP($B20,сотрудники!$B$4:$E$217,4,0)),0) -> #N/A | F20: =SUM(G20:AZ20) -> 121 | R20: 41 | S20: 41 | T20: 39
A21: 16 | B21: 206 | C21: =IF(B21<>0,(VLOOKUP($B21,сотрудники!$B$4:$D$217,2,0)),0) -> #N/A | D21: =IF(C21<>0,(VLOOKUP($B21,сотрудники!$B$4:$D$217,3,0)),0) -> #N/A | E21: =IF(D21<>0,(VLOOKUP($B21,сотрудники!$B$4:$E$217,4,0)),0) -> #N/A | F21: =SUM(G21:AZ21) -> 168 | Y21: 168
A22: 17 | B22: 121 | C22: =IF(B22<>0,(VLOOKUP($B22,сотрудники!$B$4:$D$217,2,0)),0) -> #N/A | D22: =IF(C22<>0,(VLOOKUP($B22,сотрудники!$B$4:$D$217,3,0)),0) -> #N/A | E22: =IF(D22<>0,(VLOOKUP($B22,сотрудники!$B$4:$E$217,4,0)),0) -> #N/A | F22: =SUM(G22:AZ22) -> 176 | AH22: 176
A23: 18 | B23: 94 | C23: =IF(B23<>0,(VLOOKUP($B23,сотрудники!$B$4:$D$217,2,0)),0) -> #N/A | D23: =IF(C23<>0,(VLOOKUP($B23,сотрудники!$B$4:$D$217,3,0)),0) -> #N/A | E23: =IF(D23<>0,(VLOOKUP($B23,сотрудники!$B$4:$E$217,4,0)),0) -> #N/A | F23: =SUM(G23:AZ23) -> 165 | H23: 165
A24: 19 | B24: 99 | C24: =IF(B24<>0,(VLOOKUP($B24,сотрудники!$B$4:$D$217,2,0)),0) -> #N/A | D24: =IF(C24<>0,(VLOOKUP($B24,сотрудники!$B$4:$D$217,3,0)),0) -> #N/A | E24: =IF(D24<>0,(VLOOKUP($B24,сотрудники!$B$4:$E$217,4,0)),0) -> #N/A | F24: =SUM(G24:AZ24) -> 176 | R24: 58 | S24: 58 | T24: 60
A25: 20 | B25: 91 | C25: =IF(B25<>0,(VLOOKUP($B25,сотрудники!$B$4:$D$217,2,0)),0) -> #N/A | D25: =IF(C25<>0,(VLOOKUP($B25,сотрудники!$B$4:$D$217,3,0)),0) -> #N/A | E25: =IF(D25<>0,(VLOOKUP($B25,сотрудники!$B$4:$E$217,4,0)),0) -> #N/A | F25: =SUM(G25:AZ25) -> 176 | G25: 176
A26: 21 | B26: 86 | C26: =IF(B26<>0,(VLOOKUP($B26,сотрудники!$B$4:$D$217,2,0)),0) -> #N/A | D26: =IF(C26<>0,(VLOOKUP($B26,сотрудники!$B$4:$D$217,3,0)),0) -> #N/A | E26: =IF(D26<>0,(VLOOKUP($B26,сотрудники!$B$4:$E$217,4,0)),0) -> #N/A | F26: =SUM(G26:AZ26) -> 120 | AK26: 40 | AL26: 80
A27: 22 | B27: 181 | C27: =IF(B27<>0,(VLOOKUP($B27,сотрудники!$B$4:$D$217,2,0)),0) -> #N/A | D27: =IF(C27<>0,(VLOOKUP($B27,сотрудники!$B$4:$D$217,3,0)),0) -> #N/A | E27: =IF(D27<>0,(VLOOKUP($B27,сотрудники!$B$4:$E$217,4,0)),0) -> #N/A | F27: =SUM(G27:AZ27) -> 176 | I27: 88 | O27: 88
A28: 23 | B28: 93 | C28: =IF(B28<>0,(VLOOKUP($B28,сотрудники!$B$4:$D$217,2,0)),0) -> #N/A | D28: =IF(C28<>0,(VLOOKUP($B28,сотрудники!$B$4:$D$217,3,0)),0) -> #N/A | E28: =IF(D28<>0,(VLOOKUP($B28,сотрудники!$B$4:$E$217,4,0)),0) -> #N/A | F28: =SUM(G28:AZ28) -> 176 | O28: 176
A29: 24 | B29: 124 | C29: =IF(B29<>0,(VLOOKUP($B29,сотрудники!$B$4:$D$217,2,0)),0) -> #N/A | D29: =IF(C29<>0,(VLOOKUP($B29,сотрудники!$B$4:$D$217,3,0)),0) -> #N/A | E29: =IF(D29<>0,(VLOOKUP($B29,сотрудники!$B$4:$E$217,4,0)),0) -> #N/A | F29: =SUM(G29:AZ29) -> 176 | U29: 44 | V29: 44 | W29: 44 | X29: 44
A30: 25 | B30: 170 | C30: =IF(B30<>0,(VLOOKUP($B30,сотрудники!$B$4:$D$217,2,0)),0) -> #N/A | D30: =IF(C30<>0,(VLOOKUP($B30,сотрудники!$B$4:$D$217,3,0)),0) -> #N/A | E30: =IF(D30<>0,(VLOOKUP($B30,сотрудники!$B$4:$E$217,4,0)),0) -> #N/A | F30: =SUM(G30:AZ30) -> 132 | I30: 132
A31: 26 | B31: 208 | C31: =IF(B31<>0,(VLOOKUP($B31,сотрудники!$B$4:$D$217,2,0)),0) -> #N/A | D31: =IF(C31<>0,(VLOOKUP($B31,сотрудники!$B$4:$D$217,3,0)),0) -> #N/A | E31: =IF(D31<>0,(VLOOKUP($B31,сотрудники!$B$4:$E$217,4,0)),0) -> #N/A | F31: =SUM(G31:AZ31) -> 176 | Y31: 176
A32: 27 | B32: 267 | C32: =IF(B32<>0,(VLOOKUP($B32,сотрудники!$B$4:$D$217,2,0)),0) -> #N/A | D32: =IF(C32<>0,(VLOOKUP($B32,сотрудники!$B$4:$D$217,3,0)),0) -> #N/A | E32: =IF(D32<>0,(VLOOKUP($B32,сотрудники!$B$4:$E$217,4,0)),0) -> #N/A | F32: =SUM(G32:AZ32) -> 162 | Y32: 162
A33: 28 | B33: 95 | C33: =IF(B33<>0,(VLOOKUP($B33,сотрудники!$B$4:$D$217,2,0)),0) -> #N/A | D33: =IF(C33<>0,(VLOOKUP($B33,сотрудники!$B$4:$D$217,3,0)),0) -> #N/A | E33: =IF(D33<>0,(VLOOKUP($B33,сотрудники!$B$4:$E$217,4,0)),0) -> #N/A | F33: =SUM(G33:AZ33) -> 165 | G33: 165
A34: 29 | B34: 317 | C34: =IF(B34<>0,(VLOOKUP($B34,сотрудники!$B$4:$D$217,2,0)),0) -> #N/A | D34: =IF(C34<>0,(VLOOKUP($B34,сотрудники!$B$4:$D$217,3,0)),0) -> #N/A | E34: =IF(D34<>0,(VLOOKUP($B34,сотрудники!$B$4:$E$217,4,0)),0) -> #N/A | F34: =SUM(G34:AZ34) -> 110 | Y34: 110

Sheet Ноябрь
A1: ООО Инженерная инфраструктура | E1: месяц: | F1: ноябрь
A4: № п.п. | B4: Табельный номер (автозаполнение) | C4: ФИО сотрудника (автозаполнение) | D4: Должность (автозаполнение) | E4: Подразделение (автозаполнение) | F4: Всего отработано часов в смену | H4: часы работы на объектах
H5: Айсберг и ТА | I5: МЛАХ и ТА | J5: Сириус Арена | K5: Спортивный Парк | L5: Спец Объект | M5: КТ | N5: СБТ | O5: ЦС | P5: Академия Единоборств (ЦПС) | Q5: Академия Единоборств (УСТК1) | R5: Академия Единоборств (УСТК2) | S5: Капмус ОЦ | T5: Корпус Спорт ОЦ | U5: Корпус Школа ОЦ | V5: Международная, 10 (Лицей) | W5: ПЛ Школа | X5: ПЛ ДДУ | Y5: ПЛ Бассейн | Z5: ПНиИ | AA5: Админ. здания ОП | AB5: Планетарий | AC5: Концертный | AD5: Квартиры Худякова | AE5: Квартиры Эстонская | AF5: Олимп. Парк | AG5: РЖД | AH5: Парусная | AI5: Дельта | AJ5: Омега | AK5: Гамма | AL5: Сигма А | AM5: Сигма Б,В,Г | AN5: Хостел S | AO5: Русские сезоны
A6: 1 | B6: 90 | C6: =IF(B6<>0,(VLOOKUP($B6,сотрудники!$B$4:$D$217,2,0)),0) -> #N/A | D6: =IF(C6<>0,(VLOOKUP($B6,сотрудники!$B$4:$D$217,3,0)),0) -> #N/A | E6: =IF(D6<>0,(VLOOKUP($B6,сотрудники!$B$4:$E$217,4,0)),0) -> #N/A | F6: =SUM(H6:BA6) -> 88 | AI6: 88
A8: 2 | B8: 147 | C8: =IF(B8<>0,(VLOOKUP($B8,сотрудники!$B$4:$D$217,2,0)),0) -> #N/A | D8: =IF(C8<>0,(VLOOKUP($B8,сотрудники!$B$4:$D$217,3,0)),0) -> #N/A | E8: =IF(D8<>0,(VLOOKUP($B8,сотрудники!$B$4:$E$217,4,0)),0) -> #N/A | F8: =SUM(H8:BA8) -> 165 | AK8: 165
A10: 3 | B10: 150 | C10: =IF(B10<>0,(VLOOKUP($B10,сотрудники!$B$4:$D$217,2,0)),0) -> #N/A | D10: =IF(C10<>0,(VLOOKUP($B10,сотрудники!$B$4:$D$217,3,0)),0) -> #N/A | E10: =IF(D10<>0,(VLOOKUP($B10,сотрудники!$B$4:$E$217,4,0)),0) -> #N/A | F10: =SUM(H10:BA10) -> 95 | AK10: 95
A12: 4 | B12: 96 | C12: =IF(B12<>0,(VLOOKUP($B12,сотрудники!$B$4:$D$217,2,0)),0) -> #N/A | D12: =IF(C12<>0,(VLOOKUP($B12,сотрудники!$B$4:$D$217,3,0)),0) -> #N/A | E12: =IF(D12<>0,(VLOOKUP($B12,сотрудники!$B$4:$E$217,4,0)),0) -> #N/A | F12: =SUM(H12:BA12) -> 165 | P12: 165
A14: 5 | B14: 177 | C14: =IF(B14<>0,(VLOOKUP($B14,сотрудники!$B$4:$D$217,2,0)),0) -> #N/A | D14: =IF(C14<>0,(VLOOKUP($B14,сотрудники!$B$4:$D$217,3,0)),0) -> #N/A | E14: =IF(D14<>0,(VLOOKUP($B14,сотрудники!$B$4:$E$217,4,0)),0) -> #N/A | F14: =SUM(H14:BA14) -> 165 | AK14: 165
A16: 6 | B16: 77 | C16: =IF(B16<>0,(VLOOKUP($B16,сотрудники!$B$4:$D$217,2,0)),0) -> #N/A | D16: =IF(C16<>0,(VLOOKUP($B16,сотрудники!$B$4:$D$217,3,0)),0) -> #N/A | E16: =IF(D16<>0,(VLOOKUP($B16,сотрудники!$B$4:$E$217,4,0)),0) -> #N/A | F16: =SUM(H16:BA16) -> 154 | AL16: 44 | AM16: 110
G17: Итого % | H17: =SUM(H16)/SUM($H$16:$AO$16) -> 0 | I17: =SUM(I16)/SUM($H$16:$AO$16) -> 0 | J17: =SUM(J16)/SUM($H$16:$AO$16) -> 0 | K17: =SUM(K16)/SUM($H$16:$AO$16) -> 0 | L17: =SUM(L16)/SUM($H$16:$AO$16) -> 0 | M17: =SUM(M16)/SUM($H$16:$AO$16) -> 0 | N17: =SUM(N16)/SUM($H$16:$AO$16) -> 0 | O17: =SUM(O16)/SUM($H$16:$AO$16) -> 0 | ... AO17: =SUM(AO16)/SUM($H$16:$AO$16) -> 0
A18: 7 | B18: 171 | C18: =IF(B18<>0,(VLOOKUP($B18,сотрудники!$B$4:$D$217,2,0)),0) -> #N/A | D18: =IF(C18<>0,(VLOOKUP($B18,сотрудники!$B$4:$D$217,3,0)),0) -> #N/A | E18: =IF(D18<>0,(VLOOKUP($B18,сотрудники!$B$4:$E$217,4,0)),0) -> #N/A | F18: =SUM(H18:BA18) -> 165 | Z18: 165
A20: 8 | B20: 97 | C20: =IF(B20<>0,(VLOOKUP($B20,сотрудники!$B$4:$D$217,2,0)),0) -> #N/A | D20: =IF(C20<>0,(VLOOKUP($B20,сотрудники!$B$4:$D$217,3,0)),0) -> #N/A | E20: =IF(D20<>0,(VLOOKUP($B20,сотрудники!$B$4:$E$217,4,0)),0) -> #N/A | F20: =SUM(H20:BA20) -> 132 | J20: 132
A22: 9 | B22: 92 | C22: =IF(B22<>0,(VLOOKUP($B22,сотрудники!$B$4:$D$217,2,0)),0) -> #N/A | D22: =IF(C22<>0,(VLOOKUP($B22,сотрудники!$B$4:$D$217,3,0)),0) -> #N/A | E22: =IF(D22<>0,(VLOOKUP($B22,сотрудники!$B$4:$E$217,4,0)),0) -> #N/A | F22: =SUM(H22:BA22) -> 167 | I22: 80 | K22: 87
G23: Итого % | H23: =SUM(H22)/SUM($H$22:$AO$22) -> 0 | I23: =SUM(I22)/SUM($H$22:$AO$22) -> 0.47904192 | J23: =SUM(J22)/SUM($H$22:$AO$22) -> 0 | K23: =SUM(K22)/SUM($H$22:$AO$22) -> 0.52095808 | L23: =SUM(L22)/SUM($H$22:$AO$22) -> 0 | M23: =SUM(M22)/SUM($H$22:$AO$22) -> 0 | N23: =SUM(N22)/SUM($H$22:$AO$22) -> 0 | O23: =SUM(O22)/SUM($H$22:$AO$22) -> 0 | ... AO23: =SUM(AO22)/SUM($H$22:$AO$22) -> 0
A24: 10 | B24: 145 | C24: =IF(B24<>0,(VLOOKUP($B24,сотрудники!$B$4:$D$217,2,0)),0) -> #N/A | D24: =IF(C24<>0,(VLOOKUP($B24,сотрудники!$B$4:$D$217,3,0)),0) -> #N/A | E24: =IF(D24<>0,(VLOOKUP($B24,сотрудники!$B$4:$E$217,4,0)),0) -> #N/A | F24: =SUM(H24:BA24) -> 167 | AL24: 67 | AM24: 100
G25: Итого % | H25: =SUM(H24)/SUM($H$24:$AO$24) -> 0 | I25: =SUM(I24)/SUM($H$24:$AO$24) -> 0 | J25: =SUM(J24)/SUM($H$24:$AO$24) -> 0 | K25: =SUM(K24)/SUM($H$24:$AO$24) -> 0 | L25: =SUM(L24)/SUM($H$24:$AO$24) -> 0 | M25: =SUM(M24)/SUM($H$24:$AO$24) -> 0 | N25: =SUM(N24)/SUM($H$24:$AO$24) -> 0 | O25: =SUM(O24)/SUM($H$24:$AO$24) -> 0 | ... AO25: =SUM(AO24)/SUM($H$24:$AO$24) -> 0
A26: 11 | B26: 100 | C26: =IF(B26<>0,(VLOOKUP($B26,сотрудники!$B$4:$D$217,2,0)),0) -> #N/A | D26: =IF(C26<>0,(VLOOKUP($B26,сотрудники!$B$4:$D$217,3,0)),0) -> #N/A | E26: =IF(D26<>0,(VLOOKUP($B26,сотрудники!$B$4:$E$217,4,0)),0) -> #N/A | F26: =SUM(H26:BA26) -> 165 | V26: 41 | W26: 41 | X26: 41 | Y26: 42
G27: Итого % | H27: =SUM(H26)/SUM($H$26:$AO$26) -> 0 | I27: =SUM(I26)/SUM($H$26:$AO$26) -> 0 | J27: =SUM(J26)/SUM($H$26:$AO$26) -> 0 | K27: =SUM(K26)/SUM($H$26:$AO$26) -> 0 | L27: =SUM(L26)/SUM($H$26:$AO$26) -> 0 | M27: =SUM(M26)/SUM($H$26:$AO$26) -> 0 | N27: =SUM(N26)/SUM($H$26:$AO$26) -> 0 | O27: =SUM(O26)/SUM($H$26:$AO$26) -> 0 | ... AO27: =SUM(AO26)/SUM($H$26:$AO$26) -> 0
A28: 12 | B28: 257 | C28: =IF(B28<>0,(VLOOKUP($B28,сотрудники!$B$4:$D$217,2,0)),0) -> #N/A | D28: =IF(C28<>0,(VLOOKUP($B28,сотрудники!$B$4:$D$217,3,0)),0) -> #N/A | E28: =IF(D28<>0,(VLOOKUP($B28,сотрудники!$B$4:$E$217,4,0)),0) -> #N/A | F28: =SUM(H28:BA28) -> 154 | Z28: 154
A30: 13 | B30: 173 | C30: =IF(B30<>0,(VLOOKUP($B30,сотрудники!$B$4:$D$217,2,0)),0) -> #N/A | D30: =IF(C30<>0,(VLOOKUP($B30,сотрудники!$B$4:$D$217,3,0)),0) -> #N/A | E30: =IF(D30<>0,(VLOOKUP($B30,сотрудники!$B$4:$E$217,4,0)),0) -> #N/A | F30: =SUM(H30:BA30) -> 176 | I30: 176
A32: 14 | B32: 174 | C32: =IF(B32<>0,(VLOOKUP($B32,сотрудники!$B$4:$D$217,2,0)),0) -> #N/A | D32: =IF(C32<>0,(VLOOKUP($B32,сотрудники!$B$4:$D$217,3,0)),0) -> #N/A | E32: =IF(D32<>0,(VLOOKUP($B32,сотрудники!$B$4:$E$217,4,0)),0) -> #N/A | F32: =SUM(H32:BA32) -> 165 | V32: 45 | W32: 40 | X32: 40 | Y32: 40
G33: Итого % | H33: =SUM(H32)/SUM($H$32:$AO$32) -> 0 | I33: =SUM(I32)/SUM($H$32:$AO$32) -> 0 | J33: =SUM(J32)/SUM($H$32:$AO$32) -> 0 | K33: =SUM(K32)/SUM($H$32:$AO$32) -> 0 | L33: =SUM(L32)/SUM($H$32:$AO$32) -> 0 | M33: =SUM(M32)/SUM($H$32:$AO$32) -> 0 | N33: =SUM(N32)/SUM($H$32:$AO$32) -> 0 | O33: =SUM(O32)/SUM($H$32:$AO$32) -> 0 | ... AO33: =SUM(AO32)/SUM($H$32:$AO$32) -> 0
A34: 15 | B34: 98 | C34: =IF(B34<>0,(VLOOKUP($B34,сотрудники!$B$4:$D$217,2,0)),0) -> #N/A | D34: =IF(C34<>0,(VLOOKUP($B34,сотрудники!$B$4:$D$217,3,0)),0) -> #N/A | E34: =IF(D34<>0,(VLOOKUP($B34,сотрудники!$B$4:$E$217,4,0)),0) -> #N/A | F34: =SUM(H34:BA34) -> 154 | S34: 50 | T34: 50 | U34: 54
G35: Итого % | H35: =SUM(H34)/SUM($H$34:$AO$34) -> 0 | I35: =SUM(I34)/SUM($H$34:$AO$34) -> 0 | J35: =SUM(J34)/SUM($H$34:$AO$34) -> 0 | K35: =SUM(K34)/SUM($H$34:$AO$34) -> 0 | L35: =SUM(L34)/SUM($H$34:$AO$34) -> 0 | M35: =SUM(M34)/SUM($H$34:$AO$34) -> 0 | N35: =SUM(N34)/SUM($H$34:$AO$34) -> 0 | O35: =SUM(O34)/SUM($H$34:$AO$34) -> 0 | ... AO35: =SUM(AO34)/SUM($H$34:$AO$34) -> 0
A36: 16 | B36: 206 | C36: =IF(B36<>0,(VLOOKUP($B36,сотрудники!$B$4:$D$217,2,0)),0) -> #N/A | D36: =IF(C36<>0,(VLOOKUP($B36,сотрудники!$B$4:$D$217,3,0)),0) -> #N/A | E36: =IF(D36<>0,(VLOOKUP($B36,сотрудники!$B$4:$E$217,4,0)),0) -> #N/A | F36: =SUM(H36:BA36) -> 162 | Z36: 162
A38: 17 | B38: 121 | C38: =IF(B38<>0,(VLOOKUP($B38,сотрудники!$B$4:$D$217,2,0)),0) -> #N/A | D38: =IF(C38<>0,(VLOOKUP($B38,сотрудники!$B$4:$D$217,3,0)),0) -> #N/A | E38: =IF(D38<>0,(VLOOKUP($B38,сотрудники!$B$4:$E$217,4,0)),0) -> #N/A | F38: =SUM(H38:BA38) -> 165 | AI38: 165
A40: 18 | B40: 94 | C40: =IF(B40<>0,(VLOOKUP($B40,сотрудники!$B$4:$D$217,2,0)),0) -> #N/A | D40: =IF(C40<>0,(VLOOKUP($B40,сотрудники!$B$4:$D$217,3,0)),0) -> #N/A | E40: =IF(D40<>0,(VLOOKUP($B40,сотрудники!$B$4:$E$217,4,0)),0) -> #N/A | F40: =SUM(H40:BA40) -> 176 | I40: 176
A42: 19 | B42: 99 | C42: =IF(B42<>0,(VLOOKUP($B42,сотрудники!$B$4:$D$217,2,0)),0) -> #N/A | D42: =IF(C42<>0,(VLOOKUP($B42,сотрудники!$B$4:$D$217,3,0)),0) -> #N/A | E42: =IF(D42<>0,(VLOOKUP($B42,сотрудники!$B$4:$E$217,4,0)),0) -> #N/A | F42: =SUM(H42:BA42) -> 154 | S42: 54 | T42: 50 | U42: 50
G43: Итого % | H43: =SUM(H42)/SUM($H$42:$AO$42) -> 0 | I43: =SUM(I42)/SUM($H$42:$AO$42) -> 0 | J43: =SUM(J42)/SUM($H$42:$AO$42) -> 0 | K43: =SUM(K42)/SUM($H$42:$AO$42) -> 0 | L43: =SUM(L42)/SUM($H$42:$AO$42) -> 0 | M43: =SUM(M42)/SUM($H$42:$AO$42) -> 0 | N43: =SUM(N42)/SUM($H$42:$AO$42) -> 0 | O43: =SUM(O42)/SUM($H$42:$AO$42) -> 0 | ... AO43: =SUM(AO42)/SUM($H$42:$AO$42) -> 0
A44: 20 | B44: 91 | C44: =IF(B44<>0,(VLOOKUP($B44,сотрудники!$B$4:$D$217,2,0)),0) -> #N/A | D44: =IF(C44<>0,(VLOOKUP($B44,сотрудники!$B$4:$D$217,3,0)),0) -> #N/A | E44: =IF(D44<>0,(VLOOKUP($B44,сотрудники!$B$4:$E$217,4,0)),0) -> #N/A | F44: =SUM(H44:BA44) -> 165 | H44: 165
A46: 21 | B46: 86 | C46: =IF(B46<>0,(VLOOKUP($B46,сотрудники!$B$4:$D$217,2,0)),0) -> #N/A | D46: =IF(C46<>0,(VLOOKUP($B46,сотрудники!$B$4:$D$217,3,0)),0) -> #N/A | E46: =IF(D46<>0,(VLOOKUP($B46,сотрудники!$B$4:$E$217,4,0)),0) -> #N/A | F46: =SUM(H46:BA46) -> 176 | AL46: 76 | AM46: 100
G47: Итого % | H47: =SUM(H46)/SUM($H$46:$AO$46) -> 0 | I47: =SUM(I46)/SUM($H$46:$AO$46) -> 0 | J47: =SUM(J46)/SUM($H$46:$AO$46) -> 0 | K47: =SUM(K46)/SUM($H$46:$AO$46) -> 0 | L47: =SUM(L46)/SUM($H$46:$AO$46) -> 0 | M47: =SUM(M46)/SUM($H$46:$AO$46) -> 0 | N47: =SUM(N46)/SUM($H$46:$AO$46) -> 0 | O47: =SUM(O46)/SUM($H$46:$AO$46) -> 0 | ... AO47: =SUM(AO46)/SUM($H$46:$AO$46) -> 0
A48: 22 | B48: 181 | C48: =IF(B48<>0,(VLOOKUP($B48,сотрудники!$B$4:$D$217,2,0)),0) -> #N/A | D48: =IF(C48<>0,(VLOOKUP($B48,сотрудники!$B$4:$D$217,3,0)),0) -> #N/A | E48: =IF(D48<>0,(VLOOKUP($B48,сотрудники!$B$4:$E$217,4,0)),0) -> #N/A | F48: =SUM(H48:BA48) -> 167 | J48: 87 | P48: 80
G49: Итого % | H49: =SUM(H48)/SUM($H$48:$AO$48) -> 0 | I49: =SUM(I48)/SUM($H$48:$AO$48) -> 0 | J49: =SUM(J48)/SUM($H$48:$AO$48) -> 0.52095808 | K49: =SUM(K48)/SUM($H$48:$AO$48) -> 0 | L49: =SUM(L48)/SUM($H$48:$AO$48) -> 0 | M49: =SUM(M48)/SUM($H$48:$AO$48) -> 0 | N49: =SUM(N48)/SUM($H$48:$AO$48) -> 0 | O49: =SUM(O48)/SUM($H$48:$AO$48) -> 0 | ... AO49: =SUM(AO48)/SUM($H$48:$AO$48) -> 0
A50: 23 | B50: 93 | C50: =IF(B50<>0,(VLOOKUP($B50,сотрудники!$B$4:$D$217,2,0)),0) -> #N/A | D50: =IF(C50<>0,(VLOOKUP($B50,сотрудники!$B$4:$D$217,3,0)),0) -> #N/A | E50: =IF(D50<>0,(VLOOKUP($B50,сотрудники!$B$4:$E$217,4,0)),0) -> #N/A | F50: =SUM(H50:BA50) -> 167 | P50: 167
A52: 24 | B52: 124 | C52: =IF(B52<>0,(VLOOKUP($B52,сотрудники!$B$4:$D$217,2,0)),0) -> #N/A | D52: =IF(C52<>0,(VLOOKUP($B52,сотрудники!$B$4:$D$217,3,0)),0) -> #N/A | E52: =IF(D52<>0,(VLOOKUP($B52,сотрудники!$B$4:$E$217,4,0)),0) -> #N/A | F52: =SUM(H52:BA52) -> 39 | V52: 9 | W52: 10 | X52: 10 | Y52: 10
G53: Итого % | H53: =SUM(H52)/SUM($H$52:$AO$52) -> 0 | I53: =SUM(I52)/SUM($H$52:$AO$52) -> 0 | J53: =SUM(J52)/SUM($H$52:$AO$52) -> 0 | K53: =SUM(K52)/SUM($H$52:$AO$52) -> 0 | L53: =SUM(L52)/SUM($H$52:$AO$52) -> 0 | M53: =SUM(M52)/SUM($H$52:$AO$52) -> 0 | N53: =SUM(N52)/SUM($H$52:$AO$52) -> 0 | O53: =SUM(O52)/SUM($H$52:$AO$52) -> 0 | ... AO53: =SUM(AO52)/SUM($H$52:$AO$52) -> 0
A54: 25 | B54: 170 | C54: =IF(B54<>0,(VLOOKUP($B54,сотрудники!$B$4:$D$217,2,0)),0) -> #N/A | D54: =IF(C54<>0,(VLOOKUP($B54,сотрудники!$B$4:$D$217,3,0)),0) -> #N/A | E54: =IF(D54<>0,(VLOOKUP($B54,сотрудники!$B$4:$E$217,4,0)),0) -> #N/A | F54: =SUM(H54:BA54) -> 154 | J54: 154
A56: 26 | B56: 208 | C56: =IF(B56<>0,(VLOOKUP($B56,сотрудники!$B$4:$D$217,2,0)),0) -> #N/A | D56: =IF(C56<>0,(VLOOKUP($B56,сотрудники!$B$4:$D$217,3,0)),0) -> #N/A | E56: =IF(D56<>0,(VLOOKUP($B56,сотрудники!$B$4:$E$217,4,0)),0) -> #N/A | F56: =SUM(H56:BA56) -> 168 | Z56: 168
A58: 27 | B58: 267 | C58: =IF(B58<>0,(VLOOKUP($B58,сотрудники!$B$4:$D$217,2,0)),0) -> #N/A | D58: =IF(C58<>0,(VLOOKUP($B58,сотрудники!$B$4:$D$217,3,0)),0) -> #N/A | E58: =IF(D58<>0,(VLOOKUP($B58,сотрудники!$B$4:$E$217,4,0)),0) -> #N/A | F58: =SUM(H58:BA58) -> 176 | Z58: 176
...

Sheet Январь 
A1: ООО Инженерная инфраструктура | E1: месяц: | F1: ноябрь
A4: № п.п. | B4: Табельный номер (автозаполнение) | C4: ФИО сотрудника (автозаполнение) | D4: Должность (автозаполнение) | E4: Подразделение (автозаполнение) | F4: Всего отработано часов в смену | H4: часы работы на объектах
H5: Айсберг и ТА | I5: МЛАХ и ТА | J5: Сириус Арена | K5: Спортивный Парк | L5: Спец Объект | M5: КТ | N5: СБТ | O5: ЦС | P5: Академия Единоборств (ЦПС) | Q5: Академия Единоборств (УСТК1) | R5: Академия Единоборств (УСТК2) | S5: Капмус ОЦ | T5: Корпус Спорт ОЦ | U5: Корпус Школа ОЦ | V5: Международная, 10 (Лицей) | W5: ПЛ Школа | X5: ПЛ ДДУ | Y5: ПЛ Бассейн | Z5: ПНиИ | AA5: Админ. здания ОП | AB5: Планетарий | AC5: Концертный | AD5: Квартиры Худякова | AE5: Квартиры Эстонская | AF5: Олимп. Парк | AG5: РЖД | AH5: Парусная | AI5: Дельта | AJ5: Омега | AK5: Гамма | AL5: Сигма А | AM5: Сигма Б,В,Г | AN5: Хостел S | AO5: Русские сезоны
A6: 1 | B6: 90 | C6: =IF(B6<>0,(VLOOKUP($B6,сотрудники!$B$4:$D$217,2,0)),0) -> #N/A | D6: =IF(C6<>0,(VLOOKUP($B6,сотрудники!$B$4:$D$217,3,0)),0) -> #N/A | E6: =IF(D6<>0,(VLOOKUP($B6,сотрудники!$B$4:$E$217,4,0)),0) -> #N/A | F6: =SUM(G6:AO6) -> 88 | AI6: 88
A8: 2 | B8: 147 | C8: =IF(B8<>0,(VLOOKUP($B8,сотрудники!$B$4:$D$217,2,0)),0) -> #N/A | D8: =IF(C8<>0,(VLOOKUP($B8,сотрудники!$B$4:$D$217,3,0)),0) -> #N/A | E8: =IF(D8<>0,(VLOOKUP($B8,сотрудники!$B$4:$E$217,4,0)),0) -> #N/A | F8: =SUM(G8:AO8) -> 176 | AK8: 176
A10: 3 | B10: 150 | C10: =IF(B10<>0,(VLOOKUP($B10,сотрудники!$B$4:$D$217,2,0)),0) -> #N/A | D10: =IF(C10<>0,(VLOOKUP($B10,сотрудники!$B$4:$D$217,3,0)),0) -> #N/A | E10: =IF(D10<>0,(VLOOKUP($B10,сотрудники!$B$4:$E$217,4,0)),0) -> #N/A | F10: =SUM(G10:AO10) -> 136 | AK10: 136
A12: 4 | B12: 96 | C12: =IF(B12<>0,(VLOOKUP($B12,сотрудники!$B$4:$D$217,2,0)),0) -> #N/A | D12: =IF(C12<>0,(VLOOKUP($B12,сотрудники!$B$4:$D$217,3,0)),0) -> #N/A | E12: =IF(D12<>0,(VLOOKUP($B12,сотрудники!$B$4:$E$217,4,0)),0) -> #N/A | F12: =SUM(G12:AO12) -> 165 | AJ12: 165
A14: 5 | B14: 177 | C14: =IF(B14<>0,(VLOOKUP($B14,сотрудники!$B$4:$D$217,2,0)),0) -> #N/A | D14: =IF(C14<>0,(VLOOKUP($B14,сотрудники!$B$4:$D$217,3,0)),0) -> #N/A | E14: =IF(D14<>0,(VLOOKUP($B14,сотрудники!$B$4:$E$217,4,0)),0) -> #N/A | F14: =SUM(G14:AO14) -> 173 | AK14: 173
A16: 6 | B16: 77 | C16: =IF(B16<>0,(VLOOKUP($B16,сотрудники!$B$4:$D$217,2,0)),0) -> #N/A | D16: =IF(C16<>0,(VLOOKUP($B16,сотрудники!$B$4:$D$217,3,0)),0) -> #N/A | E16: =IF(D16<>0,(VLOOKUP($B16,сотрудники!$B$4:$E$217,4,0)),0) -> #N/A | F16: =SUM(G16:AO16) -> 176 | AL16: 51 | AM16: 125
G17: Итого % | H17: =SUM(H16)/SUM($H$16:$AO$16) -> 0 | I17: =SUM(I16)/SUM($H$16:$AO$16) -> 0 | J17: =SUM(J16)/SUM($H$16:$AO$16) -> 0 | K17: =SUM(K16)/SUM($H$16:$AO$16) -> 0 | L17: =SUM(L16)/SUM($H$16:$AO$16) -> 0 | M17: =SUM(M16)/SUM($H$16:$AO$16) -> 0 | N17: =SUM(N16)/SUM($H$16:$AO$16) -> 0 | O17: =SUM(O16)/SUM($H$16:$AO$16) -> 0 | ... AO17: =SUM(AO16)/SUM($H$16:$AO$16) -> 0
A18: 7 | B18: 171 | C18: =IF(B18<>0,(VLOOKUP($B18,сотрудники!$B$4:$D$217,2,0)),0) -> #N/A | D18: =IF(C18<>0,(VLOOKUP($B18,сотрудники!$B$4:$D$217,3,0)),0) -> #N/A | E18: =IF(D18<>0,(VLOOKUP($B18,сотрудники!$B$4:$E$217,4,0)),0) -> #N/A | F18: =SUM(G18:AO18) -> 165 | Z18: 165
A20: 8 | B20: 97 | C20: =IF(B20<>0,(VLOOKUP($B20,сотрудники!$B$4:$D$217,2,0)),0) -> #N/A | D20: =IF(C20<>0,(VLOOKUP($B20,сотрудники!$B$4:$D$217,3,0)),0) -> #N/A | E20: =IF(D20<>0,(VLOOKUP($B20,сотрудники!$B$4:$E$217,4,0)),0) -> #N/A | F20: =SUM(G20:AO20) -> 165 | J20: 165
A22: 9 | B22: 92 | C22: =IF(B22<>0,(VLOOKUP($B22,сотрудники!$B$4:$D$217,2,0)),0) -> #N/A | D22: =IF(C22<>0,(VLOOKUP($B22,сотрудники!$B$4:$D$217,3,0)),0) -> #N/A | E22: =IF(D22<>0,(VLOOKUP($B22,сотрудники!$B$4:$E$217,4,0)),0) -> #N/A | F22: =SUM(G22:AO22) -> 136 | I22: 136
G23: Итого % | H23: =SUM(H22)/SUM($H$22:$AO$22) -> 0 | I23: =SUM(I22)/SUM($H$22:$AO$22) -> 1 | J23: =SUM(J22)/SUM($H$22:$AO$22) -> 0 | L23: =SUM(L22)/SUM($H$22:$AO$22) -> 0 | M23: =SUM(M22)/SUM($H$22:$AO$22) -> 0 | N23: =SUM(N22)/SUM($H$22:$AO$22) -> 0 | O23: =SUM(O22)/SUM($H$22:$AO$22) -> 0 | P23: =SUM(P22)/SUM($H$22:$AO$22) -> 0 | Q23: =SUM(Q22)/SUM($H$22:$AO$22) -> 0 | R23: =SUM(R22)/SUM($H$22:$AO$22) -> 0 | S23: =SUM(S22)/SUM($H$22:$AO$22) -> 0 | ... AO23: =SUM(AO22)/SUM($H$22:$AO$22) -> 0
A24: 10 | B24: 145 | C24: =IF(B24<>0,(VLOOKUP($B24,сотрудники!$B$4:$D$217,2,0)),0) -> #N/A | D24: =IF(C24<>0,(VLOOKUP($B24,сотрудники!$B$4:$D$217,3,0)),0) -> #N/A | E24: =IF(D24<>0,(VLOOKUP($B24,сотрудники!$B$4:$E$217,4,0)),0) -> #N/A | F24: =SUM(G24:AO24) -> 136 | AL24: 68 | AM24: 68
G25: Итого % | H25: =SUM(H24)/SUM($H$24:$AO$24) -> 0 | I25: =SUM(I24)/SUM($H$24:$AO$24) -> 0 | J25: =SUM(J24)/SUM($H$24:$AO$24) -> 0 | K25: =SUM(K24)/SUM($H$24:$AO$24) -> 0 | L25: =SUM(L24)/SUM($H$24:$AO$24) -> 0 | M25: =SUM(M24)/SUM($H$24:$AO$24) -> 0 | N25: =SUM(N24)/SUM($H$24:$AO$24) -> 0 | O25: =SUM(O24)/SUM($H$24:$AO$24) -> 0 | ... AO25: =SUM(AO24)/SUM($H$24:$AO$24) -> 0
A26: 11 | B26: 100 | C26: =IF(B26<>0,(VLOOKUP($B26,сотрудники!$B$4:$D$217,2,0)),0) -> #N/A | D26: =IF(C26<>0,(VLOOKUP($B26,сотрудники!$B$4:$D$217,3,0)),0) -> #N/A | E26: =IF(D26<>0,(VLOOKUP($B26,сотрудники!$B$4:$E$217,4,0)),0) -> #N/A | F26: =SUM(G26:AO26) -> 165 | W26: 55 | X26: 55 | Y26: 55
G27: Итого % | H27: =SUM(H26)/SUM($H$26:$AO$26) -> 0 | I27: =SUM(I26)/SUM($H$26:$AO$26) -> 0 | J27: =SUM(J26)/SUM($H$26:$AO$26) -> 0 | K27: =SUM(K26)/SUM($H$26:$AO$26) -> 0 | L27: =SUM(L26)/SUM($H$26:$AO$26) -> 0 | M27: =SUM(M26)/SUM($H$26:$AO$26) -> 0 | N27: =SUM(N26)/SUM($H$26:$AO$26) -> 0 | O27: =SUM(O26)/SUM($H$26:$AO$26) -> 0 | ... U27: =SUM(U26)/SUM($H$26:$AO$26) -> 0 | W27: =SUM(W26)/SUM($H$26:$AO$26) -> 0.33333333 | X27: =SUM(X26)/SUM($H$26:$AO$26) -> 0.33333333 | Y27: =SUM(Y26)/SUM($H$26:$AO$26) -> 0.33333333 | Z27: =SUM(Z26)/SUM($H$26:$AO$26) -> 0 | AA27: =SUM(AA26)/SUM($H$26:$AO$26) -> 0 | AB27: =SUM(AB26)/SUM($H$26:$AO$26) -> 0 | AC27: =SUM(AC26)/SUM($H$26:$AO$26) -> 0 | AD27: =SUM(AD26)/SUM($H$26:$AO$26) -> 0 | ... AO27: =SUM(AO26)/SUM($H$26:$AO$26) -> 0
A28: 12 | B28: 257 | C28: =IF(B28<>0,(VLOOKUP($B28,сотрудники!$B$4:$D$217,2,0)),0) -> #N/A | D28: =IF(C28<>0,(VLOOKUP($B28,сотрудники!$B$4:$D$217,3,0)),0) -> #N/A | E28: =IF(D28<>0,(VLOOKUP($B28,сотрудники!$B$4:$E$217,4,0)),0) -> #N/A | F28: =SUM(G28:AO28) -> 190 | Z28: 190
A30: 13 | B30: 173 | C30: =IF(B30<>0,(VLOOKUP($B30,сотрудники!$B$4:$D$217,2,0)),0) -> #N/A | D30: =IF(C30<>0,(VLOOKUP($B30,сотрудники!$B$4:$D$217,3,0)),0) -> #N/A | E30: =IF(D30<>0,(VLOOKUP($B30,сотрудники!$B$4:$E$217,4,0)),0) -> #N/A | F30: =SUM(G30:AO30) -> 187 | I30: 187
A32: 14 | B32: 174 | C32: =IF(B32<>0,(VLOOKUP($B32,сотрудники!$B$4:$D$217,2,0)),0) -> #N/A | D32: =IF(C32<>0,(VLOOKUP($B32,сотрудники!$B$4:$D$217,3,0)),0) -> #N/A | E32: =IF(D32<>0,(VLOOKUP($B32,сотрудники!$B$4:$E$217,4,0)),0) -> #N/A | F32: =SUM(G32:AO32) -> 165 | S32: 42 | T32: 42 | U32: 41 | V32: 40
G33: Итого % | H33: =SUM(H32)/SUM($H$32:$AO$32) -> 0 | I33: =SUM(I32)/SUM($H$32:$AO$32) -> 0 | J33: =SUM(J32)/SUM($H$32:$AO$32) -> 0 | K33: =SUM(K32)/SUM($H$32:$AO$32) -> 0 | L33: =SUM(L32)/SUM($H$32:$AO$32) -> 0 | M33: =SUM(M32)/SUM($H$32:$AO$32) -> 0 | N33: =SUM(N32)/SUM($H$32:$AO$32) -> 0 | O33: =SUM(O32)/SUM($H$32:$AO$32) -> 0 | ... V33: =SUM(V32)/SUM($H$32:$AO$32) -> 0.24242424 | Z33: =SUM(Z32)/SUM($H$32:$AO$32) -> 0 | AA33: =SUM(AA32)/SUM($H$32:$AO$32) -> 0 | AB33: =SUM(AB32)/SUM($H$32:$AO$32) -> 0 | AC33: =SUM(AC32)/SUM($H$32:$AO$32) -> 0 | AD33: =SUM(AD32)/SUM($H$32:$AO$32) -> 0 | AE33: =SUM(AE32)/SUM($H$32:$AO$32) -> 0 | AF33: =SUM(AF32)/SUM($H$32:$AO$32) -> 0 | AG33: =SUM(AG32)/SUM($H$32:$AO$32) -> 0 | ... AO33: =SUM(AO32)/SUM($H$32:$AO$32) -> 0
A34: 15 | B34: 98 | C34: =IF(B34<>0,(VLOOKUP($B34,сотрудники!$B$4:$D$217,2,0)),0) -> #N/A | D34: =IF(C34<>0,(VLOOKUP($B34,сотрудники!$B$4:$D$217,3,0)),0) -> #N/A | E34: =IF(D34<>0,(VLOOKUP($B34,сотрудники!$B$4:$E$217,4,0)),0) -> #N/A | F34: =SUM(G34:AO34) -> 165 | S34: 42 | T34: 42 | U34: 41 | V34: 40
G35: Итого % | H35: =SUM(H34)/SUM($H$34:$AO$34) -> 0 | I35: =SUM(I34)/SUM($H$34:$AO$34) -> 0 | J35: =SUM(J34)/SUM($H$34:$AO$34) -> 0 | K35: =SUM(K34)/SUM($H$34:$AO$34) -> 0 | L35: =SUM(L34)/SUM($H$34:$AO$34) -> 0 | M35: =SUM(M34)/SUM($H$34:$AO$34) -> 0 | N35: =SUM(N34)/SUM($H$34:$AO$34) -> 0 | O35: =SUM(O34)/SUM($H$34:$AO$34) -> 0 | ... AO35: =SUM(AO34)/SUM($H$34:$AO$34) -> 0
A36: 16 | B36: 206 | C36: =IF(B36<>0,(VLOOKUP($B36,сотрудники!$B$4:$D$217,2,0)),0) -> #N/A | D36: =IF(C36<>0,(VLOOKUP($B36,сотрудники!$B$4:$D$217,3,0)),0) -> #N/A | E36: =IF(D36<>0,(VLOOKUP($B36,сотрудники!$B$4:$E$217,4,0)),0) -> #N/A | F36: =SUM(G36:AO36) -> 176 | Z36: 176
A38: 17 | B38: 121 | C38: =IF(B38<>0,(VLOOKUP($B38,сотрудники!$B$4:$D$217,2,0)),0) -> #N/A | D38: =IF(C38<>0,(VLOOKUP($B38,сотрудники!$B$4:$D$217,3,0)),0) -> #N/A | E38: =IF(D38<>0,(VLOOKUP($B38,сотрудники!$B$4:$E$217,4,0)),0) -> #N/A | F38: =SUM(G38:AO38) -> 187 | AI38: 187
A40: 18 | B40: 94 | C40: =IF(B40<>0,(VLOOKUP($B40,сотрудники!$B$4:$D$217,2,0)),0) -> #N/A | D40: =IF(C40<>0,(VLOOKUP($B40,сотрудники!$B$4:$D$217,3,0)),0) -> #N/A | E40: =IF(D40<>0,(VLOOKUP($B40,сотрудники!$B$4:$E$217,4,0)),0) -> #N/A | F40: =SUM(G40:AO40) -> 154 | I40: 154
A42: 19 | B42: 99 | C42: =IF(B42<>0,(VLOOKUP($B42,сотрудники!$B$4:$D$217,2,0)),0) -> #N/A | D42: =IF(C42<>0,(VLOOKUP($B42,сотрудники!$B$4:$D$217,3,0)),0) -> #N/A | E42: =IF(D42<>0,(VLOOKUP($B42,сотрудники!$B$4:$E$217,4,0)),0) -> #N/A | F42: =SUM(G42:AO42) -> 44 | S42: 15 | T42: 15 | U42: 14
G43: Итого % | H43: =SUM(H42)/SUM($H$42:$AO$42) -> 0 | I43: =SUM(I42)/SUM($H$42:$AO$42) -> 0 | J43: =SUM(J42)/SUM($H$42:$AO$42) -> 0 | K43: =SUM(K42)/SUM($H$42:$AO$42) -> 0 | L43: =SUM(L42)/SUM($H$42:$AO$42) -> 0 | M43: =SUM(M42)/SUM($H$42:$AO$42) -> 0 | N43: =SUM(N42)/SUM($H$42:$AO$42) -> 0 | O43: =SUM(O42)/SUM($H$42:$AO$42) -> 0 | ... AO43: =SUM(AO42)/SUM($H$42:$AO$42) -> 0
