Workbook

Sheet Май 2021
A1: Сводная таблица всех лифтов Департамента управления гостиницами
A2: Название Объекта | B2: Номер корпуса\секции | C2: Номер лифта (порядковый) | D2: Номер лифта(заводской) | E2: В Работе\отключен | F2: Заявки по замене расходных материалов(кнопки, тросики, лампы) | G2: Заявки по застреваниям и поломкам лифтов | H2: Краткое описание проблем | I2: Дата ближайшего тех.освидетельствования | J2: Дата окончания страховки | K2: Лифт для ППП | L2: Кол-во остановок
A3: Пульсар | B3: нет | C3: 1 | D3: B7NS4223 | E3: 1 | I3: 44743 | K3: 1 | L3: 13 | P3: Дельта | Q3: Кнопки и прочие мелочи: | R3: =SUM(F16:F24) -> 3
B4: нет | C4: 2 | D4: B7NS4224 | E4: 1 | G4: 1 | I4: 44743 | K4: 0 | L4: 12 | Q4: Серьезные поломки: | R4: =SUM(G16:G24) -> 26
B5: нет | C5: 3 | D5: B7NS4225 | E5: 1 | I5: 44743 | K5: 0 | L5: 11 | P5: Гамма | Q5: Кнопки и прочие мелочи: | R5: =SUM(F25:F58) -> 21
B6: нет | C6: 4 | D6: B7NS4226 | E6: 1 | I6: 44743 | K6: 0 | L6: 11 | Q6: Серьезные поломки: | R6: =SUM(G25:G58) -> 9
B7: нет | C7: 5 | D7: B7NS4227 | E7: 1 | I7: 44743 | K7: 0 | L7: 12 | P7: Сигма | Q7: Кнопки и прочие мелочи: | R7: =SUM(F59:F138) -> 22
B8: нет | C8: 6 | D8: B7NS4228 | E8: 1 | I8: 44743 | K8: 0 | L8: 3 | Q8: Серьезные поломки: | R8: =SUM(G59:G138) -> 12
B9: нет | C9: 7 | D9: B7NS4229 | E9: 1 | I9: 44743 | K9: 0 | L9: 3 | P9: Омега | Q9: Кнопки и прочие мелочи: | R9: =SUM(F139:F146) -> 1
B10: нет | C10: 8 | D10: B7NS4230 | E10: 1 | I10: 44743 | K10: 0 | L10: 3 | Q10: Серьезные поломки: | R10: =SUM(G139:G146) -> 9
B11: нет | C11: 9 | D11: B7NS4231 | E11: 1 | I11: 44743 | K11: 0 | L11: 11 | P11: Парусная | Q11: Кнопки и прочие мелочи: | R11: =SUM(F147:F150) -> 1
B12: нет | C12: 10 | D12: B7NS4232 | E12: 1 | I12: 44743 | K12: 0 | L12: 11 | Q12: Серьезные поломки: | R12: =SUM(G147:G150) -> 2
B13: нет | C13: 11 | D13: B7NS4233 | E13: 1 | I13: 44743 | K13: 1 | L13: 13 | P13: Пульсар | Q13: Кнопки и прочие мелочи: | R13: =SUM(F3:F15) -> 0
B14: нет | C14: 12 | D14: B7NS4234 | E14: 1 | I14: 44743 | K14: 0 | L14: 2 | Q14: Серьезные поломки: | R14: =SUM(G3:G15) -> 1
B15: нет | C15: 13 | D15: B7NS4235 | E15: 1 | I15: 44743 | K15: 0 | L15: 2
A16: Дельта Сириус | B16: нет | C16: 1 | D16: 20110288-1 | E16: 1 | F16: 1 | G16: 2 | I16: 44743 | J16: 44467 | K16: 0 | L16: 9 | Q16: Расходники | R16: =SUM(R3,R5,R7,R9,R11,R13) -> 48
B17: нет | C17: 2 | D17: 20110288-2 | E17: 1 | I17: 44743 | J17: 44467 | K17: 0 | L17: 9 | Q17: Серьезные поломки | R17: =SUM(R4,R6,R8,R10,R12,R14) -> 59
B18: нет | C18: 3 | D18: 20110288-3 | E18: 1 | G18: 11 | I18: 44743 | J18: 44467 | K18: 0 | L18: 9 | Q18: Итого | R18: =SUM(R16,R17) -> 107
B19: нет | C19: 4 | D19: 20110288-4 | E19: 1 | G19: 1 | I19: 44743 | J19: 44467 | K19: 1 | L19: 9
B20: нет | C20: 5 | D20: 20110288-5 | E20: 1 | G20: 1 | I20: 44743 | J20: 44467 | K20: 1 | L20: 9
B21: нет | C21: 6 | D21: 20110288-6 | E21: 1 | F21: 1 | I21: 44743 | J21: 44467 | K21: 1 | L21: 10
B22: нет | C22: 7 | D22: 20110288-7 | E22: 1 | G22: 7 | I22: 44743 | J22: 44467 | K22: 1 | L22: 10
B23: нет | C23: 8 | D23: 20110288-8 | E23: 1 | F23: 1 | I23: 44743 | J23: 44467 | K23: 0 | L23: 3
B24: нет | C24: 9 | D24: 20110288-9 | E24: 1 | G24: 4 | I24: 44743 | J24: 44467 | K24: 0 | L24: 3
A25: Гамма Сириус | B25: 1\1 | C25: 1 | D25: B7NS3809 | E25: 1 | I25: 44743 | J25: 44538 | K25: 0 | L25: 5
B26: 1\2 | C26: 2 | D26: 708509 | E26: 1 | I26: 44743 | J26: 44538 | K26: 0 | L26: 5
B27: 1\2 | C27: 3 | D27: 708511 | E27: 1 | I27: 44743 | J27: 44538 | K27: 0 | L27: 5
B28: 1\3 | C28: 4 | D28: B7NS3791 | E28: 1 | I28: 44743 | J28: 44538 | K28: 0 | L28: 5
B29: 1\4 | C29: 5 | D29: B7NS3799 | E29: 1 | F29: 2 | I29: 44743 | J29: 44538 | K29: 0 | L29: 5
B30: 1\4 | C30: 6 | D30: B7NS3806 | E30: 1 | I30: 44743 | J30: 44538 | K30: 0 | L30: 5
B31: 1\5 | C31: 7 | D31: B7NS3807 | E31: 1 | I31: 44743 | J31: 44538 | K31: 0 | L31: 5
B32: 8\1 | C32: 1 | D32: B7NS3792 | E32: 1 | G32: 1 | I32: 44743 | J32: 44538 | K32: 0 | L32: 5
B33: 8\2 | C33: 2 | D33: B7NS3804 | E33: 1 | F33: 1 | I33: 44743 | J33: 44538 | K33: 0 | L33: 5
B34: 8\3 | C34: 3 | D34: B7NS3794 | E34: 1 | I34: 44743 | J34: 44538 | K34: 0 | L34: 5
B35: 8\4 | C35: 4 | D35: B7NS3795 | E35: 1 | F35: 2 | I35: 44743 | J35: 44538 | K35: 0 | L35: 5
B36: 9\1 | C36: 1 | D36: B7NS3812 | E36: 1 | G36: 1 | I36: 44743 | J36: 44538 | K36: 0 | L36: 5
B37: 9\2 | C37: 2 | D37: B79S3811 | E37: 1 | F37: 1 | G37: 1 | I37: 44743 | J37: 44538 | K37: 0 | L37: 5
B38: 9\3 | C38: 3 | D38: B7NS3810 | E38: 1 | F38: 3 | G38: 1 | I38: 44743 | J38: 44538 | K38: 0 | L38: 5
B39: 9\4 | C39: 4 | D39: B7NS3808 | E39: 1 | I39: 44743 | J39: 44538 | K39: 0 | L39: 5
B40: 10\1 | C40: 1 | D40: B7NS3801 | E40: 1 | G40: 1 | I40: 44743 | J40: 44538 | K40: 0 | L40: 5
...

Sheet Июнь 2021
A1: Сводная таблица всех лифтов Департамента управления гостиницами
A2: Название Объекта | B2: Номер корпуса\секции | C2: Номер лифта (порядковый) | D2: Номер лифта(заводской) | E2: В Работе\отключен | F2: Количество поломок зависящих от нас | G2: Количество поломок не зависящих от нас | H2: Краткое описание проблем | I2: Дата ближайшего тех.освидетельствования | J2: Дата окончания страховки | K2: Лифт для ППП | L2: Кол-во остановок
A3: Дельта Сириус | B3: нет | C3: 1 | D3: 20110288-1 | E3: 1 | I3: 44385 | J3: 44467 | K3: 0 | L3: 9
B4: нет | C4: 2 | D4: 20110288-2 | E4: 1 | I4: 44385 | J4: 44467 | K4: 0 | L4: 9
B5: нет | C5: 3 | D5: 20110288-3 | E5: 1 | F5: 15 | G5: 1 | H5: регулировка дш | I5: 44385 | J5: 44467 | K5: 0 | L5: 9
B6: нет | C6: 4 | D6: 20110288-4 | E6: 1 | G6: 2 | H6: сброс ошибки | I6: 44385 | J6: 44467 | K6: 1 | L6: 9
B7: нет | C7: 5 | D7: 20110288-5 | E7: 1 | G7: 1 | H7: сброс ошибки | I7: 44385 | J7: 44467 | K7: 1 | L7: 9
B8: нет | C8: 6 | D8: 20110288-6 | E8: 1 | G8: 3 | H8: замена кнопки | I8: 44385 | J8: 44467 | K8: 1 | L8: 10
B9: нет | C9: 7 | D9: 20110288-7 | E9: 1 | F9: 9 | H9: регулировка дш | I9: 44385 | J9: 44467 | K9: 1 | L9: 10
B10: нет | C10: 8 | D10: 20110288-8 | E10: 1 | G10: 3 | H10: сброс ошибки | I10: 44385 | J10: 44467 | K10: 0 | L10: 3
B11: нет | C11: 9 | D11: 20110288-9 | E11: 0 | I11: 44385 | J11: 44467 | K11: 0 | L11: 3
A12: Гамма Сириус | B12: 1\1 | C12: 1 | D12: B7NS3809 | E12: 1 | I12: 44380 | J12: 44538 | K12: 0 | L12: 5
B13: 1\2 | C13: 2 | D13: 708509 | E13: 1 | G13: 1 | H13: замена кнопки | I13: 44380 | J13: 44538 | K13: 0 | L13: 5
B14: 1\2 | C14: 3 | D14: 708511 | E14: 1 | I14: 44380 | J14: 44538 | K14: 0 | L14: 5
B15: 1\3 | C15: 4 | D15: B7NS3791 | E15: 0 | G15: 1 | H15: замена кнопки | I15: 44380 | J15: 44538 | K15: 0 | L15: 5
B16: 1\4 | C16: 5 | D16: B7NS3799 | E16: 1 | I16: 44380 | J16: 44538 | K16: 0 | L16: 5
B17: 1\4 | C17: 6 | D17: B7NS3806 | E17: 1 | I17: 44380 | J17: 44538 | K17: 0 | L17: 5
B18: 1\5 | C18: 7 | D18: B7NS3807 | E18: 1 | I18: 44380 | J18: 44538 | K18: 0 | L18: 5
B19: 8\1 | C19: 1 | D19: B7NS3792 | E19: 1 | G19: 2 | H19: замена кнопки | I19: 44380 | J19: 44538 | K19: 0 | L19: 5
B20: 8\2 | C20: 2 | D20: B7NS3804 | E20: 1 | I20: 44380 | J20: 44538 | K20: 0 | L20: 5
B21: 8\3 | C21: 3 | D21: B7NS3794 | E21: 1 | I21: 44380 | J21: 44538 | K21: 0 | L21: 5
B22: 8\4 | C22: 4 | D22: B7NS3795 | E22: 1 | I22: 44380 | J22: 44538 | K22: 0 | L22: 5
B23: 9\1 | C23: 1 | D23: B7NS3812 | E23: 1 | G23: 1 | H23: замена кнопки | I23: 44380 | J23: 44538 | K23: 0 | L23: 5
B24: 9\2 | C24: 2 | D24: B79S3811 | E24: 1 | G24: 1 | H24: сброс ошибки | I24: 44380 | J24: 44538 | K24: 0 | L24: 5
B25: 9\3 | C25: 3 | D25: B7NS3810 | E25: 1 | G25: 1 | H25: замена кнопки | I25: 44380 | J25: 44538 | K25: 0 | L25: 5
B26: 9\4 | C26: 4 | D26: B7NS3808 | E26: 1 | G26: 1 | H26: сброс ошибки | I26: 44380 | J26: 44538 | K26: 0 | L26: 5
B27: 10\1 | C27: 1 | D27: B7NS3801 | E27: 1 | I27: 44380 | J27: 44538 | K27: 0 | L27: 5
B28: 10\2 | C28: 2 | D28: B7NS3802 | E28: 1 | I28: 44380 | J28: 44538 | K28: 0 | L28: 5
B29: 10\3 | C29: 3 | D29: B7NS3803 | E29: 1 | G29: 4 | H29: сброс ошибки | I29: 44380 | J29: 44538 | K29: 0 | L29: 5
B30: 10\4 | C30: 4 | D30: B7NS3821 | E30: 1 | I30: 44380 | J30: 44538 | K30: 0 | L30: 5
B31: 10\5 | C31: 5 | D31: B7NS3805 | E31: 1 | G31: 1 | H31: замена кнопки | I31: 44380 | J31: 44538 | K31: 0 | L31: 5
B32: 11\1 | C32: 1 | D32: B7NS3818 | E32: 1 | G32: 1 | H32: замена кнопки | I32: 44380 | J32: 44538 | K32: 0 | L32: 5
B33: 11\2 | C33: 2 | D33: B7NS3793 | E33: 1 | G33: 2 | H33: замена кнопки | I33: 44380 | J33: 44538 | K33: 0 | L33: 5
B34: 11\3 | C34: 3 | D34: B7NS3820 | E34: 1 | I34: 44380 | J34: 44538 | K34: 0 | L34: 5
B35: 11\4 | C35: 4 | D35: B7NS3822 | E35: 1 | I35: 44380 | J35: 44538 | K35: 0 | L35: 5
B36: 12\1 | C36: 1 | D36: B7NS3796 | E36: 1 | I36: 44380 | J36: 44538 | K36: 0 | L36: 5
B37: 12\2 | C37: 2 | D37: B7NS3797 | E37: 1 | G37: 3 | H37: сброс ошибки | I37: 44380 | J37: 44538 | K37: 0 | L37: 5
B38: 12\3 | C38: 3 | D38: B7NS3798 | E38: 1 | I38: 44380 | J38: 44538 | K38: 0 | L38: 5
B39: 12\4 | C39: 4 | D39: B7NS3818 | E39: 1 | G39: 4 | H39: замена кнопки | I39: 44380 | J39: 44538 | K39: 0 | L39: 5
B40: 14\1 | C40: 1 | D40: B7NS3787 | E40: 1 | I40: 44380 | J40: 44538 | K40: 0 | L40: 5
...

Sheet Июль 2021
A1: Сводная таблица всех лифтов Департамента управления гостиницами
A2: Название Объекта | B2: Номер корпуса\секции | C2: Номер лифта (порядковый) | D2: Номер лифта(заводской) | E2: В Работе\отключен | F2: Количество поломок зависящих от нас | G2: Количество поломок не зависящих от нас | H2: Краткое описание проблем | I2: Дата ближайшего тех.освидетельствования | J2: Дата окончания страховки | K2: Лифт для ППП | L2: Кол-во остановок
A3: Дельта Сириус | B3: нет | C3: 1 | D3: 20110288-1 | E3: 1 | I3: 44385 | J3: 44467 | K3: 0 | L3: 9
B4: нет | C4: 2 | D4: 20110288-2 | E4: 1 | G4: 1 | H4: сброс ошибок | I4: 44385 | J4: 44467 | K4: 0 | L4: 9
B5: нет | C5: 3 | D5: 20110288-3 | E5: 1 | G5: 6 | H5: сброс ошибок | I5: 44385 | J5: 44467 | K5: 0 | L5: 9
B6: нет | C6: 4 | D6: 20110288-4 | E6: 1 | G6: 1 | H6: сброс ошибок | I6: 44385 | J6: 44467 | K6: 1 | L6: 9
B7: нет | C7: 5 | D7: 20110288-5 | E7: 1 | I7: 44385 | J7: 44467 | K7: 1 | L7: 9
B8: нет | C8: 6 | D8: 20110288-6 | E8: 1 | I8: 44385 | J8: 44467 | K8: 1 | L8: 10
B9: нет | C9: 7 | D9: 20110288-7 | E9: 1 | I9: 44385 | J9: 44467 | K9: 1 | L9: 10
B10: нет | C10: 8 | D10: 20110288-8 | E10: 1 | I10: 44385 | J10: 44467 | K10: 0 | L10: 3
B11: нет | C11: 9 | D11: 20110288-9 | E11: 0 | I11: 44385 | J11: 44467 | K11: 0 | L11: 3
A12: Гамма Сириус | B12: 1\1 | C12: 1 | D12: B7NS3809 | E12: 1 | G12: 1 | H12: сброс ошибок | I12: 44380 | J12: 44538 | K12: 0 | L12: 5
B13: 1\2 | C13: 2 | D13: 708509 | E13: 1 | I13: 44380 | J13: 44538 | K13: 0 | L13: 5
B14: 1\2 | C14: 3 | D14: 708511 | E14: 1 | G14: 1 | H14: замена кнопки | I14: 44380 | J14: 44538 | K14: 0 | L14: 5
B15: 1\3 | C15: 4 | D15: B7NS3791 | E15: 0 | G15: 1 | H15: сброс ошибок | I15: 44380 | J15: 44538 | K15: 0 | L15: 5
B16: 1\4 | C16: 5 | D16: B7NS3799 | E16: 1 | I16: 44380 | J16: 44538 | K16: 0 | L16: 5
B17: 1\4 | C17: 6 | D17: B7NS3806 | E17: 1 | I17: 44380 | J17: 44538 | K17: 0 | L17: 5
B18: 1\5 | C18: 7 | D18: B7NS3807 | E18: 1 | I18: 44380 | J18: 44538 | K18: 0 | L18: 5
B19: 8\1 | C19: 1 | D19: B7NS3792 | E19: 1 | I19: 44380 | J19: 44538 | K19: 0 | L19: 5
B20: 8\2 | C20: 2 | D20: B7NS3804 | E20: 1 | G20: 1 | H20: сброс ошибок | I20: 44380 | J20: 44538 | K20: 0 | L20: 5
B21: 8\3 | C21: 3 | D21: B7NS3794 | E21: 1 | I21: 44380 | J21: 44538 | K21: 0 | L21: 5
B22: 8\4 | C22: 4 | D22: B7NS3795 | E22: 1 | G22: 1 | H22: замена кнопки | I22: 44380 | J22: 44538 | K22: 0 | L22: 5
B23: 9\1 | C23: 1 | D23: B7NS3812 | E23: 1 | I23: 44380 | J23: 44538 | K23: 0 | L23: 5
B24: 9\2 | C24: 2 | D24: B79S3811 | E24: 1 | I24: 44380 | J24: 44538 | K24: 0 | L24: 5
B25: 9\3 | C25: 3 | D25: B7NS3810 | E25: 1 | G25: 1 | H25: замена кнопки | I25: 44380 | J25: 44538 | K25: 0 | L25: 5
B26: 9\4 | C26: 4 | D26: B7NS3808 | E26: 1 | G26: 1 | H26: сброс ошибок | I26: 44380 | J26: 44538 | K26: 0 | L26: 5
B27: 10\1 | C27: 1 | D27: B7NS3801 | E27: 1 | G27: 1 | H27: замена кнопки | I27: 44380 | J27: 44538 | K27: 0 | L27: 5
B28: 10\2 | C28: 2 | D28: B7NS3802 | E28: 1 | G28: 4 | H28: сброс ошибок | I28: 44380 | J28: 44538 | K28: 0 | L28: 5
B29: 10\3 | C29: 3 | D29: B7NS3803 | E29: 1 | G29: 3 | H29: сброс ошибок | I29: 44380 | J29: 44538 | K29: 0 | L29: 5
B30: 10\4 | C30: 4 | D30: B7NS3821 | E30: 1 | G30: 1 | H30: сброс ошибок | I30: 44380 | J30: 44538 | K30: 0 | L30: 5
B31: 10\5 | C31: 5 | D31: B7NS3805 | E31: 1 | I31: 44380 | J31: 44538 | K31: 0 | L31: 5
B32: 11\1 | C32: 1 | D32: B7NS3818 | E32: 1 | I32: 44380 | J32: 44538 | K32: 0 | L32: 5
B33: 11\2 | C33: 2 | D33: B7NS3793 | E33: 1 | I33: 44380 | J33: 44538 | K33: 0 | L33: 5
B34: 11\3 | C34: 3 | D34: B7NS3820 | E34: 1 | G34: 1 | H34: сброс ошибок | I34: 44380 | J34: 44538 | K34: 0 | L34: 5
B35: 11\4 | C35: 4 | D35: B7NS3822 | E35: 1 | I35: 44380 | J35: 44538 | K35: 0 | L35: 5
B36: 12\1 | C36: 1 | D36: B7NS3796 | E36: 1 | G36: 1 | H36: замена кнопки | I36: 44380 | J36: 44538 | K36: 0 | L36: 5
B37: 12\2 | C37: 2 | D37: B7NS3797 | E37: 1 | I37: 44380 | J37: 44538 | K37: 0 | L37: 5
B38: 12\3 | C38: 3 | D38: B7NS3798 | E38: 1 | I38: 44380 | J38: 44538 | K38: 0 | L38: 5
B39: 12\4 | C39: 4 | D39: B7NS3818 | E39: 1 | G39: 1 | H39: замена тросика | I39: 44380 | J39: 44538 | K39: 0 | L39: 5
B40: 14\1 | C40: 1 | D40: B7NS3787 | E40: 1 | I40: 44380 | J40: 44538 | K40: 0 | L40: 5
...

Sheet Август 2021
A1: Сводная таблица всех лифтов Департамента управления гостиницами
A2: Название Объекта | B2: Номер корпуса\секции | C2: Номер лифта (порядковый) | D2: Номер лифта(заводской) | E2: В Работе\отключен | F2: Заявки по замене расходных материалов(кнопки, тросики, лампы) | G2: Заявки по застреваниям и поломкам лифтов | H2: Краткое описание проблем | I2: Дата ближайшего тех.освидетельствования | J2: Дата окончания страховки | K2: Лифт для ППП | L2: Кол-во остановок
A3: Пульсар | B3: нет | C3: 1 | E3: 1 | I3: 44743 | K3: 1 | L3: 13 | P3: Дельта | Q3: Кнопки и прочие мелочи: | R3: =SUM(F16:F24) -> 1
B4: нет | C4: 2 | E4: 1 | I4: 44743 | K4: 0 | L4: 12 | Q4: Серьезные поломки: | R4: =SUM(G16:G24) -> 5
B5: нет | C5: 3 | E5: 1 | I5: 44743 | K5: 0 | L5: 11 | P5: Гамма | Q5: Кнопки и прочие мелочи: | R5: =SUM(F25:F58) -> 8
B6: нет | C6: 4 | E6: 1 | I6: 44743 | K6: 0 | L6: 11 | Q6: Серьезные поломки: | R6: =SUM(G25:G58) -> 16
B7: нет | C7: 5 | E7: 0 | I7: 44743 | K7: 0 | L7: 12 | P7: Сигма | Q7: Кнопки и прочие мелочи: | R7: =SUM(F59:F138) -> 10
B8: нет | C8: 6 | E8: 1 | I8: 44743 | K8: 0 | L8: 3 | Q8: Серьезные поломки: | R8: =SUM(G59:G138) -> 7
B9: нет | C9: 7 | E9: 1 | I9: 44743 | K9: 0 | L9: 3 | P9: Омега | Q9: Кнопки и прочие мелочи: | R9: =SUM(F139:F146) -> 4
B10: нет | C10: 8 | E10: 1 | I10: 44743 | K10: 0 | L10: 3 | Q10: Серьезные поломки: | R10: =SUM(G139:G146) -> 2
B11: нет | C11: 9 | E11: 1 | I11: 44743 | K11: 0 | L11: 11 | P11: Парусная | Q11: Кнопки и прочие мелочи: | R11: =SUM(F147:F150) -> 1
B12: нет | C12: 10 | E12: 1 | I12: 44743 | K12: 0 | L12: 11 | Q12: Серьезные поломки: | R12: =SUM(G147:G150) -> 0
B13: нет | C13: 11 | E13: 1 | I13: 44743 | K13: 1 | L13: 13 | P13: Пульсар | Q13: Кнопки и прочие мелочи: | R13: =SUM(F3:F15) -> 0
B14: нет | C14: 12 | E14: 1 | I14: 44743 | K14: 0 | L14: 2 | Q14: Серьезные поломки: | R14: =SUM(G3:G15) -> 0
B15: нет | C15: 13 | E15: 1 | I15: 44743 | K15: 0 | L15: 2
A16: Дельта Сириус | B16: нет | C16: 1 | D16: 20110288-1 | E16: 1 | I16: 44743 | J16: 44467 | K16: 0 | L16: 9 | Q16: Расходники | R16: =SUM(R3,R5,R7,R9,R11,R13) -> 24
B17: нет | C17: 2 | D17: 20110288-2 | E17: 1 | F17: 1 | G17: 1 | I17: 44743 | J17: 44467 | K17: 0 | L17: 9 | Q17: Серьезные поломки | R17: =SUM(R4,R6,R8,R10,R12,R14) -> 30
B18: нет | C18: 3 | D18: 20110288-3 | E18: 1 | G18: 1 | H18: замена отводки | I18: 44743 | J18: 44467 | K18: 0 | L18: 9 | Q18: Итого | R18: =SUM(R16,R17) -> 54
B19: нет | C19: 4 | D19: 20110288-4 | E19: 1 | G19: 1 | I19: 44743 | J19: 44467 | K19: 1 | L19: 9
B20: нет | C20: 5 | D20: 20110288-5 | E20: 1 | G20: 1 | I20: 44743 | J20: 44467 | K20: 1 | L20: 9
B21: нет | C21: 6 | D21: 20110288-6 | E21: 1 | I21: 44743 | J21: 44467 | K21: 1 | L21: 10
B22: нет | C22: 7 | D22: 20110288-7 | E22: 1 | G22: 1 | I22: 44743 | J22: 44467 | K22: 1 | L22: 10
B23: нет | C23: 8 | D23: 20110288-8 | E23: 1 | I23: 44743 | J23: 44467 | K23: 0 | L23: 3
B24: нет | C24: 9 | D24: 20110288-9 | E24: 0 | I24: 44743 | J24: 44467 | K24: 0 | L24: 3
A25: Гамма Сириус | B25: 1\1 | C25: 1 | D25: B7NS3809 | E25: 1 | I25: 44743 | J25: 44538 | K25: 0 | L25: 5
B26: 1\2 | C26: 2 | D26: 708509 | E26: 1 | F26: 2 | G26: 1 | I26: 44743 | J26: 44538 | K26: 0 | L26: 5
B27: 1\2 | C27: 3 | D27: 708511 | E27: 1 | I27: 44743 | J27: 44538 | K27: 0 | L27: 5
B28: 1\3 | C28: 4 | D28: B7NS3791 | E28: 0 | I28: 44743 | J28: 44538 | K28: 0 | L28: 5
B29: 1\4 | C29: 5 | D29: B7NS3799 | E29: 1 | I29: 44743 | J29: 44538 | K29: 0 | L29: 5
B30: 1\4 | C30: 6 | D30: B7NS3806 | E30: 1 | I30: 44743 | J30: 44538 | K30: 0 | L30: 5
B31: 1\5 | C31: 7 | D31: B7NS3807 | E31: 1 | I31: 44743 | J31: 44538 | K31: 0 | L31: 5
B32: 8\1 | C32: 1 | D32: B7NS3792 | E32: 1 | F32: 1 | I32: 44743 | J32: 44538 | K32: 0 | L32: 5
B33: 8\2 | C33: 2 | D33: B7NS3804 | E33: 1 | I33: 44743 | J33: 44538 | K33: 0 | L33: 5
B34: 8\3 | C34: 3 | D34: B7NS3794 | E34: 1 | I34: 44743 | J34: 44538 | K34: 0 | L34: 5
B35: 8\4 | C35: 4 | D35: B7NS3795 | E35: 1 | I35: 44743 | J35: 44538 | K35: 0 | L35: 5
B36: 9\1 | C36: 1 | D36: B7NS3812 | E36: 1 | G36: 2 | H36: регулировка дш 1эт. | I36: 44743 | J36: 44538 | K36: 0 | L36: 5
B37: 9\2 | C37: 2 | D37: B79S3811 | E37: 1 | I37: 44743 | J37: 44538 | K37: 0 | L37: 5
B38: 9\3 | C38: 3 | D38: B7NS3810 | E38: 1 | G38: 1 | I38: 44743 | J38: 44538 | K38: 0 | L38: 5
B39: 9\4 | C39: 4 | D39: B7NS3808 | E39: 1 | G39: 1 | I39: 44743 | J39: 44538 | K39: 0 | L39: 5
B40: 10\1 | C40: 1 | D40: B7NS3801 | E40: 1 | F40: 1 | I40: 44743 | J40: 44538 | K40: 0 | L40: 5
...

Sheet Сентябрь 2021
A1: Сводная таблица всех лифтов Департамента управления гостиницами
A2: Название Объекта | B2: Номер корпуса\секции | C2: Номер лифта (порядковый) | D2: Номер лифта(заводской) | E2: В Работе\отключен | F2: Заявки по замене расходных материалов(кнопки, тросики, лампы) | G2: Заявки по застреваниям и поломкам лифтов | H2: Краткое описание проблем | I2: Дата ближайшего тех.освидетельствования | J2: Дата окончания страховки | K2: Лифт для ППП | L2: Кол-во остановок
A3: Пульсар | B3: нет | C3: 1 | E3: 1 | I3: 44743 | K3: 1 | L3: 13 | P3: Дельта | Q3: Кнопки и прочие мелочи: | R3: =SUM(F16:F24) -> 6
B4: нет | C4: 2 | E4: 1 | I4: 44743 | K4: 0 | L4: 12 | Q4: Серьезные поломки: | R4: =SUM(G16:G24) -> 8
B5: нет | C5: 3 | E5: 1 | I5: 44743 | K5: 0 | L5: 11 | P5: Гамма | Q5: Кнопки и прочие мелочи: | R5: =SUM(F25:F58) -> 4
B6: нет | C6: 4 | E6: 1 | I6: 44743 | K6: 0 | L6: 11 | Q6: Серьезные поломки: | R6: =SUM(G25:G58) -> 3
B7: нет | C7: 5 | E7: 0 | I7: 44743 | K7: 0 | L7: 12 | P7: Сигма | Q7: Кнопки и прочие мелочи: | R7: =SUM(F59:F138) -> 13
B8: нет | C8: 6 | E8: 1 | I8: 44743 | K8: 0 | L8: 3 | Q8: Серьезные поломки: | R8: =SUM(G59:G138) -> 18
B9: нет | C9: 7 | E9: 1 | I9: 44743 | K9: 0 | L9: 3 | P9: Омега | Q9: Кнопки и прочие мелочи: | R9: =SUM(F139:F146) -> 1
B10: нет | C10: 8 | E10: 1 | I10: 44743 | K10: 0 | L10: 3 | Q10: Серьезные поломки: | R10: =SUM(G139:G146) -> 4
B11: нет | C11: 9 | E11: 1 | I11: 44743 | K11: 0 | L11: 11 | P11: Парусная | Q11: Кнопки и прочие мелочи: | R11: =SUM(F147:F150) -> 0
B12: нет | C12: 10 | E12: 1 | I12: 44743 | K12: 0 | L12: 11 | Q12: Серьезные поломки: | R12: =SUM(G147:G150) -> 0
B13: нет | C13: 11 | E13: 1 | I13: 44743 | K13: 1 | L13: 13 | P13: Пульсар | Q13: Кнопки и прочие мелочи: | R13: =SUM(F3:F15) -> 0
B14: нет | C14: 12 | E14: 1 | I14: 44743 | K14: 0 | L14: 2 | Q14: Серьезные поломки: | R14: =SUM(G3:G15) -> 2
B15: нет | C15: 13 | E15: 1 | G15: 2 | H15: регулировка дш | I15: 44743 | K15: 0 | L15: 2
A16: Дельта Сириус | B16: нет | C16: 1 | D16: 20110288-1 | E16: 1 | G16: 1 | H16: Успокоитель | I16: 44743 | J16: 44467 | K16: 0 | L16: 9 | Q16: Расходники | R16: =SUM(R3,R5,R7,R9,R11,R13) -> 24
B17: нет | C17: 2 | D17: 20110288-2 | E17: 1 | F17: 1 | G17: 1 | H17: Натяжение канатов | I17: 44743 | J17: 44467 | K17: 0 | L17: 9 | Q17: Серьезные поломки | R17: =SUM(R4,R6,R8,R10,R12,R14) -> 35
B18: нет | C18: 3 | D18: 20110288-3 | E18: 1 | I18: 44743 | J18: 44467 | K18: 0 | L18: 9 | Q18: Итого | R18: =SUM(R16,R17) -> 59
B19: нет | C19: 4 | D19: 20110288-4 | E19: 1 | F19: 1 | I19: 44743 | J19: 44467 | K19: 1 | L19: 9
B20: нет | C20: 5 | D20: 20110288-5 | E20: 1 | I20: 44743 | J20: 44467 | K20: 1 | L20: 9
B21: нет | C21: 6 | D21: 20110288-6 | E21: 1 | F21: 1 | G21: 1 | I21: 44743 | J21: 44467 | K21: 1 | L21: 10
B22: нет | C22: 7 | D22: 20110288-7 | E22: 1 | F22: 1 | G22: 4 | H22: регулировка дш | I22: 44743 | J22: 44467 | K22: 1 | L22: 10
B23: нет | C23: 8 | D23: 20110288-8 | E23: 1 | F23: 1 | I23: 44743 | J23: 44467 | K23: 0 | L23: 3
B24: нет | C24: 9 | D24: 20110288-9 | E24: 0 | F24: 1 | G24: 1 | I24: 44743 | J24: 44467 | K24: 0 | L24: 3
A25: Гамма Сириус | B25: 1\1 | C25: 1 | D25: B7NS3809 | E25: 1 | I25: 44743 | J25: 44538 | K25: 0 | L25: 5
B26: 1\2 | C26: 2 | D26: 708509 | E26: 1 | I26: 44743 | J26: 44538 | K26: 0 | L26: 5
B27: 1\2 | C27: 3 | D27: 708511 | E27: 1 | I27: 44743 | J27: 44538 | K27: 0 | L27: 5
B28: 1\3 | C28: 4 | D28: B7NS3791 | E28: 0 | I28: 44743 | J28: 44538 | K28: 0 | L28: 5
B29: 1\4 | C29: 5 | D29: B7NS3799 | E29: 1 | F29: 1 | I29: 44743 | J29: 44538 | K29: 0 | L29: 5
B30: 1\4 | C30: 6 | D30: B7NS3806 | E30: 1 | I30: 44743 | J30: 44538 | K30: 0 | L30: 5
B31: 1\5 | C31: 7 | D31: B7NS3807 | E31: 1 | G31: 1 | I31: 44743 | J31: 44538 | K31: 0 | L31: 5
B32: 8\1 | C32: 1 | D32: B7NS3792 | E32: 1 | I32: 44743 | J32: 44538 | K32: 0 | L32: 5
B33: 8\2 | C33: 2 | D33: B7NS3804 | E33: 1 | G33: 1 | I33: 44743 | J33: 44538 | K33: 0 | L33: 5
B34: 8\3 | C34: 3 | D34: B7NS3794 | E34: 1 | I34: 44743 | J34: 44538 | K34: 0 | L34: 5
B35: 8\4 | C35: 4 | D35: B7NS3795 | E35: 1 | F35: 2 | I35: 44743 | J35: 44538 | K35: 0 | L35: 5
B36: 9\1 | C36: 1 | D36: B7NS3812 | E36: 1 | I36: 44743 | J36: 44538 | K36: 0 | L36: 5
B37: 9\2 | C37: 2 | D37: B79S3811 | E37: 1 | I37: 44743 | J37: 44538 | K37: 0 | L37: 5
B38: 9\3 | C38: 3 | D38: B7NS3810 | E38: 1 | I38: 44743 | J38: 44538 | K38: 0 | L38: 5
B39: 9\4 | C39: 4 | D39: B7NS3808 | E39: 1 | I39: 44743 | J39: 44538 | K39: 0 | L39: 5
B40: 10\1 | C40: 1 | D40: B7NS3801 | E40: 1 | I40: 44743 | J40: 44538 | K40: 0 | L40: 5
...

Sheet Октябрь 2021
A1: Сводная таблица всех лифтов Департамента управления гостиницами
A2: Название Объекта | B2: Номер корпуса\секции | C2: Номер лифта (порядковый) | D2: Номер лифта(заводской) | E2: В Работе\отключен | F2: Заявки по замене расходных материалов(кнопки, тросики, лампы) | G2: Заявки по застреваниям и поломкам лифтов | H2: Краткое описание проблем | I2: Дата ближайшего тех.освидетельствования | J2: Дата окончания страховки | K2: Лифт для ППП | L2: Кол-во остановок
A3: Пульсар | B3: нет | C3: 1 | E3: 1 | I3: 44743 | K3: 1 | L3: 13 | P3: Дельта | Q3: Кнопки и прочие мелочи: | R3: =SUM(F16:F24) -> 4
B4: нет | C4: 2 | E4: 1 | I4: 44743 | K4: 0 | L4: 12 | Q4: Серьезные поломки: | R4: =SUM(G16:G24) -> 19
B5: нет | C5: 3 | E5: 1 | I5: 44743 | K5: 0 | L5: 11 | P5: Гамма | Q5: Кнопки и прочие мелочи: | R5: =SUM(F25:F58) -> 11
B6: нет | C6: 4 | E6: 1 | I6: 44743 | K6: 0 | L6: 11 | Q6: Серьезные поломки: | R6: =SUM(G25:G58) -> 14
B7: нет | C7: 5 | E7: 0 | I7: 44743 | K7: 0 | L7: 12 | P7: Сигма | Q7: Кнопки и прочие мелочи: | R7: =SUM(F59:F138) -> 5
B8: нет | C8: 6 | E8: 1 | I8: 44743 | K8: 0 | L8: 3 | Q8: Серьезные поломки: | R8: =SUM(G59:G138) -> 10
B9: нет | C9: 7 | E9: 1 | I9: 44743 | K9: 0 | L9: 3 | P9: Омега | Q9: Кнопки и прочие мелочи: | R9: =SUM(F139:F146) -> 0
B10: нет | C10: 8 | E10: 1 | I10: 44743 | K10: 0 | L10: 3 | Q10: Серьезные поломки: | R10: =SUM(G139:G146) -> 3
B11: нет | C11: 9 | E11: 1 | I11: 44743 | K11: 0 | L11: 11 | P11: Парусная | Q11: Кнопки и прочие мелочи: | R11: =SUM(F147:F150) -> 0
B12: нет | C12: 10 | E12: 1 | I12: 44743 | K12: 0 | L12: 11 | Q12: Серьезные поломки: | R12: =SUM(G147:G150) -> 0
B13: нет | C13: 11 | E13: 1 | I13: 44743 | K13: 1 | L13: 13 | P13: Пульсар | Q13: Кнопки и прочие мелочи: | R13: =SUM(F3:F15) -> 0
B14: нет | C14: 12 | E14: 1 | I14: 44743 | K14: 0 | L14: 2 | Q14: Серьезные поломки: | R14: =SUM(G3:G15) -> 0
B15: нет | C15: 13 | E15: 1 | I15: 44743 | K15: 0 | L15: 2
A16: Дельта Сириус | B16: нет | C16: 1 | D16: 20110288-1 | E16: 1 | F16: 1 | G16: 2 | I16: 44743 | J16: 44467 | K16: 0 | L16: 9 | Q16: Расходники | R16: =SUM(R3,R5,R7,R9,R11,R13) -> 20
B17: нет | C17: 2 | D17: 20110288-2 | E17: 1 | G17: 3 | I17: 44743 | J17: 44467 | K17: 0 | L17: 9 | Q17: Серьезные поломки | R17: =SUM(R4,R6,R8,R10,R12,R14) -> 46
B18: нет | C18: 3 | D18: 20110288-3 | E18: 1 | F18: 1 | G18: 1 | I18: 44743 | J18: 44467 | K18: 0 | L18: 9 | Q18: Итого | R18: =SUM(R16,R17) -> 66
B19: нет | C19: 4 | D19: 20110288-4 | E19: 1 | G19: 2 | I19: 44743 | J19: 44467 | K19: 1 | L19: 9
B20: нет | C20: 5 | D20: 20110288-5 | E20: 1 | G20: 1 | I20: 44743 | J20: 44467 | K20: 1 | L20: 9
B21: нет | C21: 6 | D21: 20110288-6 | E21: 1 | F21: 1 | G21: 3 | I21: 44743 | J21: 44467 | K21: 1 | L21: 10
B22: нет | C22: 7 | D22: 20110288-7 | E22: 1 | G22: 5 | I22: 44743 | J22: 44467 | K22: 1 | L22: 10
B23: нет | C23: 8 | D23: 20110288-8 | E23: 1 | G23: 2 | I23: 44743 | J23: 44467 | K23: 0 | L23: 3
B24: нет | C24: 9 | D24: 20110288-9 | E24: 1 | F24: 1 | I24: 44743 | J24: 44467 | K24: 0 | L24: 3
A25: Гамма Сириус | B25: 1\1 | C25: 1 | D25: B7NS3809 | E25: 1 | G25: 1 | I25: 44743 | J25: 44538 | K25: 0 | L25: 5
B26: 1\2 | C26: 2 | D26: 708509 | E26: 1 | G26: 1 | I26: 44743 | J26: 44538 | K26: 0 | L26: 5
B27: 1\2 | C27: 3 | D27: 708511 | E27: 1 | F27: 3 | I27: 44743 | J27: 44538 | K27: 0 | L27: 5
B28: 1\3 | C28: 4 | D28: B7NS3791 | E28: 0 | I28: 44743 | J28: 44538 | K28: 0 | L28: 5
B29: 1\4 | C29: 5 | D29: B7NS3799 | E29: 1 | G29: 1 | I29: 44743 | J29: 44538 | K29: 0 | L29: 5
B30: 1\4 | C30: 6 | D30: B7NS3806 | E30: 1 | I30: 44743 | J30: 44538 | K30: 0 | L30: 5
B31: 1\5 | C31: 7 | D31: B7NS3807 | E31: 1 | F31: 1 | I31: 44743 | J31: 44538 | K31: 0 | L31: 5
B32: 8\1 | C32: 1 | D32: B7NS3792 | E32: 1 | G32: 1 | I32: 44743 | J32: 44538 | K32: 0 | L32: 5
B33: 8\2 | C33: 2 | D33: B7NS3804 | E33: 1 | G33: 1 | I33: 44743 | J33: 44538 | K33: 0 | L33: 5
B34: 8\3 | C34: 3 | D34: B7NS3794 | E34: 1 | I34: 44743 | J34: 44538 | K34: 0 | L34: 5
B35: 8\4 | C35: 4 | D35: B7NS3795 | E35: 1 | F35: 2 | I35: 44743 | J35: 44538 | K35: 0 | L35: 5
B36: 9\1 | C36: 1 | D36: B7NS3812 | E36: 1 | I36: 44743 | J36: 44538 | K36: 0 | L36: 5
B37: 9\2 | C37: 2 | D37: B79S3811 | E37: 1 | I37: 44743 | J37: 44538 | K37: 0 | L37: 5
B38: 9\3 | C38: 3 | D38: B7NS3810 | E38: 1 | I38: 44743 | J38: 44538 | K38: 0 | L38: 5
B39: 9\4 | C39: 4 | D39: B7NS3808 | E39: 1 | G39: 1 | I39: 44743 | J39: 44538 | K39: 0 | L39: 5
B40: 10\1 | C40: 1 | D40: B7NS3801 | E40: 1 | G40: 1 | I40: 44743 | J40: 44538 | K40: 0 | L40: 5
...

Sheet Ноябрь 2021
A1: Сводная таблица всех лифтов Департамента управления гостиницами
A2: Название Объекта | B2: Номер корпуса\секции | C2: Номер лифта (порядковый) | D2: Номер лифта(заводской) | E2: В Работе\отключен | F2: Заявки по замене расходных материалов(кнопки, тросики, лампы) | G2: Заявки по застреваниям и поломкам лифтов | H2: Краткое описание проблем | I2: Дата ближайшего тех.освидетельствования | J2: Дата окончания страховки | K2: Лифт для ППП | L2: Кол-во остановок
A3: Пульсар | B3: нет | C3: 1 | E3: 1 | I3: 44743 | K3: 1 | L3: 13 | P3: Дельта | Q3: Кнопки и прочие мелочи: | R3: =SUM(F16:F24) -> 9
B4: нет | C4: 2 | E4: 1 | I4: 44743 | K4: 0 | L4: 12 | Q4: Серьезные поломки: | R4: =SUM(G16:G24) -> 13
B5: нет | C5: 3 | E5: 1 | I5: 44743 | K5: 0 | L5: 11 | P5: Гамма | Q5: Кнопки и прочие мелочи: | R5: =SUM(F25:F58) -> 18
B6: нет | C6: 4 | E6: 1 | I6: 44743 | K6: 0 | L6: 11 | Q6: Серьезные поломки: | R6: =SUM(G25:G58) -> 7
B7: нет | C7: 5 | E7: 0 | I7: 44743 | K7: 0 | L7: 12 | P7: Сигма | Q7: Кнопки и прочие мелочи: | R7: =SUM(F59:F138) -> 6
B8: нет | C8: 6 | E8: 1 | I8: 44743 | K8: 0 | L8: 3 | Q8: Серьезные поломки: | R8: =SUM(G59:G138) -> 5
B9: нет | C9: 7 | E9: 1 | I9: 44743 | K9: 0 | L9: 3 | P9: Омега | Q9: Кнопки и прочие мелочи: | R9: =SUM(F139:F146) -> 1
B10: нет | C10: 8 | E10: 1 | I10: 44743 | K10: 0 | L10: 3 | Q10: Серьезные поломки: | R10: =SUM(G139:G146) -> 1
B11: нет | C11: 9 | E11: 1 | I11: 44743 | K11: 0 | L11: 11 | P11: Парусная | Q11: Кнопки и прочие мелочи: | R11: =SUM(F147:F150) -> 1
B12: нет | C12: 10 | E12: 1 | I12: 44743 | K12: 0 | L12: 11 | Q12: Серьезные поломки: | R12: =SUM(G147:G150) -> 0
B13: нет | C13: 11 | E13: 1 | I13: 44743 | K13: 1 | L13: 13 | P13: Пульсар | Q13: Кнопки и прочие мелочи: | R13: =SUM(F3:F15) -> 0
B14: нет | C14: 12 | E14: 1 | I14: 44743 | K14: 0 | L14: 2 | Q14: Серьезные поломки: | R14: =SUM(G3:G15) -> 1
B15: нет | C15: 13 | E15: 1 | G15: 1 | I15: 44743 | K15: 0 | L15: 2
A16: Дельта Сириус | B16: нет | C16: 1 | D16: 20110288-1 | E16: 1 | F16: 1 | G16: 1 | I16: 44743 | J16: 44467 | K16: 0 | L16: 9 | Q16: Расходники | R16: =SUM(R3,R5,R7,R9,R11,R13) -> 35
B17: нет | C17: 2 | D17: 20110288-2 | E17: 1 | F17: 2 | G17: 4 | I17: 44743 | J17: 44467 | K17: 0 | L17: 9 | Q17: Серьезные поломки | R17: =SUM(R4,R6,R8,R10,R12,R14) -> 27
B18: нет | C18: 3 | D18: 20110288-3 | E18: 1 | F18: 1 | G18: 2 | I18: 44743 | J18: 44467 | K18: 0 | L18: 9 | Q18: Итого | R18: =SUM(R16,R17) -> 62
B19: нет | C19: 4 | D19: 20110288-4 | E19: 1 | I19: 44743 | J19: 44467 | K19: 1 | L19: 9
B20: нет | C20: 5 | D20: 20110288-5 | E20: 1 | I20: 44743 | J20: 44467 | K20: 1 | L20: 9
B21: нет | C21: 6 | D21: 20110288-6 | E21: 1 | F21: 1 | G21: 3 | I21: 44743 | J21: 44467 | K21: 1 | L21: 10
B22: нет | C22: 7 | D22: 20110288-7 | E22: 1 | F22: 3 | G22: 3 | I22: 44743 | J22: 44467 | K22: 1 | L22: 10
B23: нет | C23: 8 | D23: 20110288-8 | E23: 1 | F23: 1 | I23: 44743 | J23: 44467 | K23: 0 | L23: 3
B24: нет | C24: 9 | D24: 20110288-9 | E24: 1 | I24: 44743 | J24: 44467 | K24: 0 | L24: 3
A25: Гамма Сириус | B25: 1\1 | C25: 1 | D25: B7NS3809 | E25: 1 | F25: 1 | G25: 1 | I25: 44743 | J25: 44538 | K25: 0 | L25: 5
B26: 1\2 | C26: 2 | D26: 708509 | E26: 1 | I26: 44743 | J26: 44538 | K26: 0 | L26: 5
B27: 1\2 | C27: 3 | D27: 708511 | E27: 1 | F27: 3 | I27: 44743 | J27: 44538 | K27: 0 | L27: 5
B28: 1\3 | C28: 4 | D28: B7NS3791 | E28: 0 | I28: 44743 | J28: 44538 | K28: 0 | L28: 5
B29: 1\4 | C29: 5 | D29: B7NS3799 | E29: 1 | F29: 1 | I29: 44743 | J29: 44538 | K29: 0 | L29: 5
B30: 1\4 | C30: 6 | D30: B7NS3806 | E30: 1 | I30: 44743 | J30: 44538 | K30: 0 | L30: 5
B31: 1\5 | C31: 7 | D31: B7NS3807 | E31: 1 | I31: 44743 | J31: 44538 | K31: 0 | L31: 5
B32: 8\1 | C32: 1 | D32: B7NS3792 | E32: 1 | I32: 44743 | J32: 44538 | K32: 0 | L32: 5
B33: 8\2 | C33: 2 | D33: B7NS3804 | E33: 1 | G33: 1 | I33: 44743 | J33: 44538 | K33: 0 | L33: 5
B34: 8\3 | C34: 3 | D34: B7NS3794 | E34: 1 | G34: 1 | I34: 44743 | J34: 44538 | K34: 0 | L34: 5
B35: 8\4 | C35: 4 | D35: B7NS3795 | E35: 1 | I35: 44743 | J35: 44538 | K35: 0 | L35: 5
B36: 9\1 | C36: 1 | D36: B7NS3812 | E36: 1 | G36: 1 | I36: 44743 | J36: 44538 | K36: 0 | L36: 5
B37: 9\2 | C37: 2 | D37: B79S3811 | E37: 1 | I37: 44743 | J37: 44538 | K37: 0 | L37: 5
B38: 9\3 | C38: 3 | D38: B7NS3810 | E38: 1 | F38: 2 | I38: 44743 | J38: 44538 | K38: 0 | L38: 5
B39: 9\4 | C39: 4 | D39: B7NS3808 | E39: 1 | I39: 44743 | J39: 44538 | K39: 0 | L39: 5
B40: 10\1 | C40: 1 | D40: B7NS3801 | E40: 1 | I40: 44743 | J40: 44538 | K40: 0 | L40: 5
...

Sheet Декабрь 2021
A1: Сводная таблица всех лифтов Департамента управления гостиницами
A2: Название Объекта | B2: Номер корпуса\секции | C2: Номер лифта (порядковый) | D2: Номер лифта(заводской) | E2: В Работе\отключен | F2: Заявки по замене расходных материалов(кнопки, тросики, лампы) | G2: Заявки по застреваниям и поломкам лифтов | H2: Краткое описание проблем | I2: Дата ближайшего тех.освидетельствования | J2: Дата окончания страховки | K2: Лифт для ППП | L2: Кол-во остановок
A3: Пульсар | B3: нет | C3: 1 | D3: B7NS4223 | E3: 1 | I3: 44743 | K3: 1 | L3: 13 | P3: Дельта | Q3: Кнопки и прочие мелочи: | R3: =SUM(F16:F24) -> 3
B4: нет | C4: 2 | D4: B7NS4224 | E4: 1 | I4: 44743 | K4: 0 | L4: 12 | Q4: Серьезные поломки: | R4: =SUM(G16:G24) -> 9
B5: нет | C5: 3 | D5: B7NS4225 | E5: 1 | I5: 44743 | K5: 0 | L5: 11 | P5: Гамма | Q5: Кнопки и прочие мелочи: | R5: =SUM(F25:F58) -> 4
B6: нет | C6: 4 | D6: B7NS4226 | E6: 1 | I6: 44743 | K6: 0 | L6: 11 | Q6: Серьезные поломки: | R6: =SUM(G25:G58) -> 4
B7: нет | C7: 5 | D7: B7NS4227 | E7: 1 | I7: 44743 | K7: 0 | L7: 12 | P7: Сигма | Q7: Кнопки и прочие мелочи: | R7: =SUM(F59:F138) -> 4
B8: нет | C8: 6 | D8: B7NS4228 | E8: 1 | I8: 44743 | K8: 0 | L8: 3 | Q8: Серьезные поломки: | R8: =SUM(G59:G138) -> 6
B9: нет | C9: 7 | D9: B7NS4229 | E9: 1 | I9: 44743 | K9: 0 | L9: 3 | P9: Омега | Q9: Кнопки и прочие мелочи: | R9: =SUM(F139:F146) -> 0
B10: нет | C10: 8 | D10: B7NS4230 | E10: 1 | I10: 44743 | K10: 0 | L10: 3 | Q10: Серьезные поломки: | R10: =SUM(G139:G146) -> 1
B11: нет | C11: 9 | D11: B7NS4231 | E11: 1 | I11: 44743 | K11: 0 | L11: 11 | P11: Парусная | Q11: Кнопки и прочие мелочи: | R11: =SUM(F147:F150) -> 0
B12: нет | C12: 10 | D12: B7NS4232 | E12: 1 | I12: 44743 | K12: 0 | L12: 11 | Q12: Серьезные поломки: | R12: =SUM(G147:G150) -> 0
B13: нет | C13: 11 | D13: B7NS4233 | E13: 1 | I13: 44743 | K13: 1 | L13: 13 | P13: Пульсар | Q13: Кнопки и прочие мелочи: | R13: =SUM(F3:F15) -> 0
B14: нет | C14: 12 | D14: B7NS4234 | E14: 1 | I14: 44743 | K14: 0 | L14: 2 | Q14: Серьезные поломки: | R14: =SUM(G3:G15) -> 0
B15: нет | C15: 13 | D15: B7NS4235 | E15: 1 | I15: 44743 | K15: 0 | L15: 2
A16: Дельта Сириус | B16: нет | C16: 1 | D16: 20110288-1 | E16: 1 | F16: 1 | G16: 1 | I16: 44743 | J16: 44467 | K16: 0 | L16: 9 | Q16: Расходники | R16: =SUM(R3,R5,R7,R9,R11,R13) -> 11
B17: нет | C17: 2 | D17: 20110288-2 | E17: 1 | F17: 1 | G17: 2 | I17: 44743 | J17: 44467 | K17: 0 | L17: 9 | Q17: Серьезные поломки | R17: =SUM(R4,R6,R8,R10,R12,R14) -> 20
B18: нет | C18: 3 | D18: 20110288-3 | E18: 1 | G18: 1 | I18: 44743 | J18: 44467 | K18: 0 | L18: 9 | Q18: Итого | R18: =SUM(R16,R17) -> 31
B19: нет | C19: 4 | D19: 20110288-4 | E19: 1 | I19: 44743 | J19: 44467 | K19: 1 | L19: 9
B20: нет | C20: 5 | D20: 20110288-5 | E20: 1 | I20: 44743 | J20: 44467 | K20: 1 | L20: 9
B21: нет | C21: 6 | D21: 20110288-6 | E21: 1 | G21: 1 | I21: 44743 | J21: 44467 | K21: 1 | L21: 10
B22: нет | C22: 7 | D22: 20110288-7 | E22: 1 | F22: 1 | G22: 3 | I22: 44743 | J22: 44467 | K22: 1 | L22: 10
B23: нет | C23: 8 | D23: 20110288-8 | E23: 1 | I23: 44743 | J23: 44467 | K23: 0 | L23: 3
B24: нет | C24: 9 | D24: 20110288-9 | E24: 1 | G24: 1 | I24: 44743 | J24: 44467 | K24: 0 | L24: 3
A25: Гамма Сириус | B25: 1\1 | C25: 1 | D25: B7NS3809 | E25: 1 | I25: 44743 | J25: 44538 | K25: 0 | L25: 5
B26: 1\2 | C26: 2 | D26: 708509 | E26: 1 | I26: 44743 | J26: 44538 | K26: 0 | L26: 5
B27: 1\2 | C27: 3 | D27: 708511 | E27: 1 | I27: 44743 | J27: 44538 | K27: 0 | L27: 5
B28: 1\3 | C28: 4 | D28: B7NS3791 | E28: 0 | I28: 44743 | J28: 44538 | K28: 0 | L28: 5
B29: 1\4 | C29: 5 | D29: B7NS3799 | E29: 1 | I29: 44743 | J29: 44538 | K29: 0 | L29: 5
B30: 1\4 | C30: 6 | D30: B7NS3806 | E30: 1 | I30: 44743 | J30: 44538 | K30: 0 | L30: 5
B31: 1\5 | C31: 7 | D31: B7NS3807 | E31: 1 | I31: 44743 | J31: 44538 | K31: 0 | L31: 5
B32: 8\1 | C32: 1 | D32: B7NS3792 | E32: 1 | I32: 44743 | J32: 44538 | K32: 0 | L32: 5
B33: 8\2 | C33: 2 | D33: B7NS3804 | E33: 1 | G33: 1 | I33: 44743 | J33: 44538 | K33: 0 | L33: 5
B34: 8\3 | C34: 3 | D34: B7NS3794 | E34: 1 | I34: 44743 | J34: 44538 | K34: 0 | L34: 5
B35: 8\4 | C35: 4 | D35: B7NS3795 | E35: 1 | I35: 44743 | J35: 44538 | K35: 0 | L35: 5
B36: 9\1 | C36: 1 | D36: B7NS3812 | E36: 1 | G36: 1 | I36: 44743 | J36: 44538 | K36: 0 | L36: 5
B37: 9\2 | C37: 2 | D37: B79S3811 | E37: 1 | I37: 44743 | J37: 44538 | K37: 0 | L37: 5
B38: 9\3 | C38: 3 | D38: B7NS3810 | E38: 1 | F38: 1 | I38: 44743 | J38: 44538 | K38: 0 | L38: 5
B39: 9\4 | C39: 4 | D39: B7NS3808 | E39: 1 | I39: 44743 | J39: 44538 | K39: 0 | L39: 5
B40: 10\1 | C40: 1 | D40: B7NS3801 | E40: 1 | I40: 44743 | J40: 44538 | K40: 0 | L40: 5
...

Sheet Январь 2022
A1: Сводная таблица всех лифтов Департамента управления гостиницами
A2: Название Объекта | B2: Номер корпуса\секции | C2: Номер лифта (порядковый) | D2: Номер лифта(заводской) | E2: В Работе\отключен | F2: Заявки по замене расходных материалов(кнопки, тросики, лампы) | G2: Заявки по застреваниям и поломкам лифтов | H2: Краткое описание проблем | I2: Дата ближайшего тех.освидетельствования | J2: Дата окончания страховки | K2: Лифт для ППП | L2: Кол-во остановок
A3: Пульсар | B3: нет | C3: 1 | D3: B7NS4223 | E3: 1 | I3: 44743 | K3: 1 | L3: 13 | P3: Дельта | Q3: Кнопки и прочие мелочи: | R3: =SUM(F16:F24) -> 2
B4: нет | C4: 2 | D4: B7NS4224 | E4: 1 | I4: 44743 | K4: 0 | L4: 12 | Q4: Серьезные поломки: | R4: =SUM(G16:G24) -> 14
B5: нет | C5: 3 | D5: B7NS4225 | E5: 1 | I5: 44743 | K5: 0 | L5: 11 | P5: Гамма | Q5: Кнопки и прочие мелочи: | R5: =SUM(F25:F58) -> 7
B6: нет | C6: 4 | D6: B7NS4226 | E6: 1 | I6: 44743 | K6: 0 | L6: 11 | Q6: Серьезные поломки: | R6: =SUM(G25:G58) -> 15
B7: нет | C7: 5 | D7: B7NS4227 | E7: 1 | I7: 44743 | K7: 0 | L7: 12 | P7: Сигма | Q7: Кнопки и прочие мелочи: | R7: =SUM(F59:F138) -> 7
B8: нет | C8: 6 | D8: B7NS4228 | E8: 1 | I8: 44743 | K8: 0 | L8: 3 | Q8: Серьезные поломки: | R8: =SUM(G59:G138) -> 15
B9: нет | C9: 7 | D9: B7NS4229 | E9: 1 | I9: 44743 | K9: 0 | L9: 3 | P9: Омега | Q9: Кнопки и прочие мелочи: | R9: =SUM(F139:F146) -> 2
B10: нет | C10: 8 | D10: B7NS4230 | E10: 1 | I10: 44743 | K10: 0 | L10: 3 | Q10: Серьезные поломки: | R10: =SUM(G139:G146) -> 3
B11: нет | C11: 9 | D11: B7NS4231 | E11: 1 | I11: 44743 | K11: 0 | L11: 11 | P11: Парусная | Q11: Кнопки и прочие мелочи: | R11: =SUM(F147:F150) -> 0
B12: нет | C12: 10 | D12: B7NS4232 | E12: 1 | I12: 44743 | K12: 0 | L12: 11 | Q12: Серьезные поломки: | R12: =SUM(G147:G150) -> 2
B13: нет | C13: 11 | D13: B7NS4233 | E13: 1 | I13: 44743 | K13: 1 | L13: 13 | P13: Пульсар | Q13: Кнопки и прочие мелочи: | R13: =SUM(F3:F15) -> 0
B14: нет | C14: 12 | D14: B7NS4234 | E14: 1 | I14: 44743 | K14: 0 | L14: 2 | Q14: Серьезные поломки: | R14: =SUM(G3:G15) -> 0
B15: нет | C15: 13 | D15: B7NS4235 | E15: 1 | I15: 44743 | K15: 0 | L15: 2
A16: Дельта Сириус | B16: нет | C16: 1 | D16: 20110288-1 | E16: 1 | I16: 44743 | J16: 44467 | K16: 0 | L16: 9 | Q16: Расходники | R16: =SUM(R3,R5,R7,R9,R11,R13) -> 18
B17: нет | C17: 2 | D17: 20110288-2 | E17: 1 | G17: 6 | I17: 44743 | J17: 44467 | K17: 0 | L17: 9 | Q17: Серьезные поломки | R17: =SUM(R4,R6,R8,R10,R12,R14) -> 49
B18: нет | C18: 3 | D18: 20110288-3 | E18: 1 | G18: 2 | I18: 44743 | J18: 44467 | K18: 0 | L18: 9 | Q18: Итого | R18: =SUM(R16,R17) -> 67
B19: нет | C19: 4 | D19: 20110288-4 | E19: 1 | G19: 1 | I19: 44743 | J19: 44467 | K19: 1 | L19: 9
B20: нет | C20: 5 | D20: 20110288-5 | E20: 1 | I20: 44743 | J20: 44467 | K20: 1 | L20: 9
B21: нет | C21: 6 | D21: 20110288-6 | E21: 1 | G21: 2 | I21: 44743 | J21: 44467 | K21: 1 | L21: 10
B22: нет | C22: 7 | D22: 20110288-7 | E22: 1 | F22: 1 | G22: 2 | I22: 44743 | J22: 44467 | K22: 1 | L22: 10
B23: нет | C23: 8 | D23: 20110288-8 | E23: 1 | G23: 1 | I23: 44743 | J23: 44467 | K23: 0 | L23: 3
B24: нет | C24: 9 | D24: 20110288-9 | E24: 1 | F24: 1 | I24: 44743 | J24: 44467 | K24: 0 | L24: 3
A25: Гамма Сириус | B25: 1\1 | C25: 1 | D25: B7NS3809 | E25: 1 | F25: 1 | G25: 2 | I25: 44743 | J25: 44538 | K25: 0 | L25: 5
B26: 1\2 | C26: 2 | D26: 708509 | E26: 1 | G26: 3 | I26: 44743 | J26: 44538 | K26: 0 | L26: 5
B27: 1\2 | C27: 3 | D27: 708511 | E27: 1 | F27: 1 | I27: 44743 | J27: 44538 | K27: 0 | L27: 5
B28: 1\3 | C28: 4 | D28: B7NS3791 | E28: 0 | G28: 1 | I28: 44743 | J28: 44538 | K28: 0 | L28: 5
B29: 1\4 | C29: 5 | D29: B7NS3799 | E29: 1 | F29: 2 | I29: 44743 | J29: 44538 | K29: 0 | L29: 5
B30: 1\4 | C30: 6 | D30: B7NS3806 | E30: 1 | I30: 44743 | J30: 44538 | K30: 0 | L30: 5
B31: 1\5 | C31: 7 | D31: B7NS3807 | E31: 1 | I31: 44743 | J31: 44538 | K31: 0 | L31: 5
B32: 8\1 | C32: 1 | D32: B7NS3792 | E32: 1 | I32: 44743 | J32: 44538 | K32: 0 | L32: 5
B33: 8\2 | C33: 2 | D33: B7NS3804 | E33: 1 | F33: 1 | G33: 1 | I33: 44743 | J33: 44538 | K33: 0 | L33: 5
B34: 8\3 | C34: 3 | D34: B7NS3794 | E34: 1 | G34: 1 | I34: 44743 | J34: 44538 | K34: 0 | L34: 5
B35: 8\4 | C35: 4 | D35: B7NS3795 | E35: 1 | I35: 44743 | J35: 44538 | K35: 0 | L35: 5
B36: 9\1 | C36: 1 | D36: B7NS3812 | E36: 1 | I36: 44743 | J36: 44538 | K36: 0 | L36: 5
B37: 9\2 | C37: 2 | D37: B79S3811 | E37: 1 | F37: 1 | I37: 44743 | J37: 44538 | K37: 0 | L37: 5
B38: 9\3 | C38: 3 | D38: B7NS3810 | E38: 1 | I38: 44743 | J38: 44538 | K38: 0 | L38: 5
B39: 9\4 | C39: 4 | D39: B7NS3808 | E39: 1 | I39: 44743 | J39: 44538 | K39: 0 | L39: 5
B40: 10\1 | C40: 1 | D40: B7NS3801 | E40: 1 | I40: 44743 | J40: 44538 | K40: 0 | L40: 5
...

Sheet Февраль 2022
A1: Сводная таблица всех лифтов Департамента управления гостиницами
A2: Название Объекта | B2: Номер корпуса\секции | C2: Номер лифта (порядковый) | D2: Номер лифта(заводской) | E2: В Работе\отключен | F2: Заявки по замене расходных материалов(кнопки, тросики, лампы) | G2: Заявки по застреваниям и поломкам лифтов | H2: Краткое описание проблем | I2: Дата ближайшего тех.освидетельствования | J2: Дата окончания страховки | K2: Лифт для ППП | L2: Кол-во остановок
A3: Пульсар | B3: нет | C3: 1 | D3: B7NS4223 | E3: 1 | I3: 44743 | K3: 1 | L3: 13 | P3: Дельта | Q3: Кнопки и прочие мелочи: | R3: =SUM(F16:F24) -> 4
B4: нет | C4: 2 | D4: B7NS4224 | E4: 1 | I4: 44743 | K4: 0 | L4: 12 | Q4: Серьезные поломки: | R4: =SUM(G16:G24) -> 11
B5: нет | C5: 3 | D5: B7NS4225 | E5: 1 | I5: 44743 | K5: 0 | L5: 11 | P5: Гамма | Q5: Кнопки и прочие мелочи: | R5: =SUM(F25:F58) -> 13
B6: нет | C6: 4 | D6: B7NS4226 | E6: 1 | I6: 44743 | K6: 0 | L6: 11 | Q6: Серьезные поломки: | R6: =SUM(G25:G58) -> 11
B7: нет | C7: 5 | D7: B7NS4227 | E7: 1 | I7: 44743 | K7: 0 | L7: 12 | P7: Сигма | Q7: Кнопки и прочие мелочи: | R7: =SUM(F59:F138) -> 6
B8: нет | C8: 6 | D8: B7NS4228 | E8: 1 | I8: 44743 | K8: 0 | L8: 3 | Q8: Серьезные поломки: | R8: =SUM(G59:G138) -> 13
B9: нет | C9: 7 | D9: B7NS4229 | E9: 1 | I9: 44743 | K9: 0 | L9: 3 | P9: Омега | Q9: Кнопки и прочие мелочи: | R9: =SUM(F139:F146) -> 1
B10: нет | C10: 8 | D10: B7NS4230 | E10: 1 | I10: 44743 | K10: 0 | L10: 3 | Q10: Серьезные поломки: | R10: =SUM(G139:G146) -> 1
B11: нет | C11: 9 | D11: B7NS4231 | E11: 1 | I11: 44743 | K11: 0 | L11: 11 | P11: Парусная | Q11: Кнопки и прочие мелочи: | R11: =SUM(F147:F150) -> 0
B12: нет | C12: 10 | D12: B7NS4232 | E12: 1 | I12: 44743 | K12: 0 | L12: 11 | Q12: Серьезные поломки: | R12: =SUM(G147:G150) -> 0
B13: нет | C13: 11 | D13: B7NS4233 | E13: 1 | I13: 44743 | K13: 1 | L13: 13 | P13: Пульсар | Q13: Кнопки и прочие мелочи: | R13: =SUM(F3:F15) -> 0
B14: нет | C14: 12 | D14: B7NS4234 | E14: 1 | I14: 44743 | K14: 0 | L14: 2 | Q14: Серьезные поломки: | R14: =SUM(G3:G15) -> 0
B15: нет | C15: 13 | D15: B7NS4235 | E15: 1 | I15: 44743 | K15: 0 | L15: 2
A16: Дельта Сириус | B16: нет | C16: 1 | D16: 20110288-1 | E16: 1 | I16: 44743 | J16: 44467 | K16: 0 | L16: 9 | Q16: Расходники | R16: =SUM(R3,R5,R7,R9,R11,R13) -> 24
B17: нет | C17: 2 | D17: 20110288-2 | E17: 1 | G17: 2 | I17: 44743 | J17: 44467 | K17: 0 | L17: 9 | Q17: Серьезные поломки | R17: =SUM(R4,R6,R8,R10,R12,R14) -> 36
B18: нет | C18: 3 | D18: 20110288-3 | E18: 1 | F18: 1 | G18: 1 | I18: 44743 | J18: 44467 | K18: 0 | L18: 9 | Q18: Итого | R18: =SUM(R16,R17) -> 60
B19: нет | C19: 4 | D19: 20110288-4 | E19: 1 | I19: 44743 | J19: 44467 | K19: 1 | L19: 9
B20: нет | C20: 5 | D20: 20110288-5 | E20: 1 | I20: 44743 | J20: 44467 | K20: 1 | L20: 9
B21: нет | C21: 6 | D21: 20110288-6 | E21: 1 | I21: 44743 | J21: 44467 | K21: 1 | L21: 10
B22: нет | C22: 7 | D22: 20110288-7 | E22: 1 | F22: 2 | G22: 4 | I22: 44743 | J22: 44467 | K22: 1 | L22: 10
B23: нет | C23: 8 | D23: 20110288-8 | E23: 1 | F23: 1 | G23: 1 | H23: автомат в вру | I23: 44743 | J23: 44467 | K23: 0 | L23: 3
B24: нет | C24: 9 | D24: 20110288-9 | E24: 1 | G24: 3 | I24: 44743 | J24: 44467 | K24: 0 | L24: 3
A25: Гамма Сириус | B25: 1\1 | C25: 1 | D25: B7NS3809 | E25: 1 | F25: 2 | G25: 1 | I25: 44743 | J25: 44538 | K25: 0 | L25: 5
B26: 1\2 | C26: 2 | D26: 708509 | E26: 1 | G26: 2 | I26: 44743 | J26: 44538 | K26: 0 | L26: 5
B27: 1\2 | C27: 3 | D27: 708511 | E27: 1 | I27: 44743 | J27: 44538 | K27: 0 | L27: 5
B28: 1\3 | C28: 4 | D28: B7NS3791 | E28: 0 | I28: 44743 | J28: 44538 | K28: 0 | L28: 5
B29: 1\4 | C29: 5 | D29: B7NS3799 | E29: 1 | G29: 2 | I29: 44743 | J29: 44538 | K29: 0 | L29: 5
B30: 1\4 | C30: 6 | D30: B7NS3806 | E30: 1 | I30: 44743 | J30: 44538 | K30: 0 | L30: 5
B31: 1\5 | C31: 7 | D31: B7NS3807 | E31: 1 | I31: 44743 | J31: 44538 | K31: 0 | L31: 5
B32: 8\1 | C32: 1 | D32: B7NS3792 | E32: 1 | I32: 44743 | J32: 44538 | K32: 0 | L32: 5
B33: 8\2 | C33: 2 | D33: B7NS3804 | E33: 1 | I33: 44743 | J33: 44538 | K33: 0 | L33: 5
B34: 8\3 | C34: 3 | D34: B7NS3794 | E34: 1 | F34: 1 | I34: 44743 | J34: 44538 | K34: 0 | L34: 5
B35: 8\4 | C35: 4 | D35: B7NS3795 | E35: 1 | F35: 2 | I35: 44743 | J35: 44538 | K35: 0 | L35: 5
B36: 9\1 | C36: 1 | D36: B7NS3812 | E36: 1 | I36: 44743 | J36: 44538 | K36: 0 | L36: 5
B37: 9\2 | C37: 2 | D37: B79S3811 | E37: 1 | I37: 44743 | J37: 44538 | K37: 0 | L37: 5
B38: 9\3 | C38: 3 | D38: B7NS3810 | E38: 1 | I38: 44743 | J38: 44538 | K38: 0 | L38: 5
B39: 9\4 | C39: 4 | D39: B7NS3808 | E39: 1 | I39: 44743 | J39: 44538 | K39: 0 | L39: 5
B40: 10\1 | C40: 1 | D40: B7NS3801 | E40: 1 | F40: 1 | I40: 44743 | J40: 44538 | K40: 0 | L40: 5
...

Sheet Март 2022
A1: Сводная таблица всех лифтов Департамента управления гостиницами
A2: Название Объекта | B2: Номер корпуса\секции | C2: Номер лифта (порядковый) | D2: Номер лифта(заводской) | E2: В Работе\отключен | F2: Заявки по замене расходных материалов(кнопки, тросики, лампы) | G2: Заявки по застреваниям и поломкам лифтов | H2: Краткое описание проблем | I2: Дата ближайшего тех.освидетельствования | J2: Дата окончания страховки | K2: Лифт для ППП | L2: Кол-во остановок
A3: Пульсар | B3: нет | C3: 1 | D3: B7NS4223 | E3: 1 | F3: 1 | I3: 44743 | K3: 1 | L3: 13 | P3: Дельта | Q3: Кнопки и прочие мелочи: | R3: =SUM(F16:F24) -> 2
B4: нет | C4: 2 | D4: B7NS4224 | E4: 1 | I4: 44743 | K4: 0 | L4: 12 | Q4: Серьезные поломки: | R4: =SUM(G16:G24) -> 5
B5: нет | C5: 3 | D5: B7NS4225 | E5: 1 | I5: 44743 | K5: 0 | L5: 11 | P5: Гамма | Q5: Кнопки и прочие мелочи: | R5: =SUM(F25:F58) -> 12
B6: нет | C6: 4 | D6: B7NS4226 | E6: 1 | I6: 44743 | K6: 0 | L6: 11 | Q6: Серьезные поломки: | R6: =SUM(G25:G58) -> 9
B7: нет | C7: 5 | D7: B7NS4227 | E7: 1 | I7: 44743 | K7: 0 | L7: 12 | P7: Сигма | Q7: Кнопки и прочие мелочи: | R7: =SUM(F59:F138) -> 10
B8: нет | C8: 6 | D8: B7NS4228 | E8: 1 | I8: 44743 | K8: 0 | L8: 3 | Q8: Серьезные поломки: | R8: =SUM(G59:G138) -> 13
B9: нет | C9: 7 | D9: B7NS4229 | E9: 1 | I9: 44743 | K9: 0 | L9: 3 | P9: Омега | Q9: Кнопки и прочие мелочи: | R9: =SUM(F139:F146) -> 1
B10: нет | C10: 8 | D10: B7NS4230 | E10: 1 | I10: 44743 | K10: 0 | L10: 3 | Q10: Серьезные поломки: | R10: =SUM(G139:G146) -> 5
B11: нет | C11: 9 | D11: B7NS4231 | E11: 1 | G11: 1 | I11: 44743 | K11: 0 | L11: 11 | P11: Парусная | Q11: Кнопки и прочие мелочи: | R11: =SUM(F147:F150) -> 0
B12: нет | C12: 10 | D12: B7NS4232 | E12: 1 | I12: 44743 | K12: 0 | L12: 11 | Q12: Серьезные поломки: | R12: =SUM(G147:G150) -> 0
B13: нет | C13: 11 | D13: B7NS4233 | E13: 1 | I13: 44743 | K13: 1 | L13: 13 | P13: Пульсар | Q13: Кнопки и прочие мелочи: | R13: =SUM(F3:F15) -> 1
B14: нет | C14: 12 | D14: B7NS4234 | E14: 1 | I14: 44743 | K14: 0 | L14: 2 | Q14: Серьезные поломки: | R14: =SUM(G3:G15) -> 1
B15: нет | C15: 13 | D15: B7NS4235 | E15: 1 | I15: 44743 | K15: 0 | L15: 2
A16: Дельта Сириус | B16: нет | C16: 1 | D16: 20110288-1 | E16: 1 | G16: 1 | I16: 44743 | J16: 44467 | K16: 0 | L16: 9 | Q16: Расходники | R16: =SUM(R3,R5,R7,R9,R11,R13) -> 26
B17: нет | C17: 2 | D17: 20110288-2 | E17: 1 | I17: 44743 | J17: 44467 | K17: 0 | L17: 9 | Q17: Серьезные поломки | R17: =SUM(R4,R6,R8,R10,R12,R14) -> 33
B18: нет | C18: 3 | D18: 20110288-3 | E18: 1 | G18: 1 | I18: 44743 | J18: 44467 | K18: 0 | L18: 9 | Q18: Итого | R18: =SUM(R16,R17) -> 59
B19: нет | C19: 4 | D19: 20110288-4 | E19: 1 | I19: 44743 | J19: 44467 | K19: 1 | L19: 9
B20: нет | C20: 5 | D20: 20110288-5 | E20: 1 | I20: 44743 | J20: 44467 | K20: 1 | L20: 9
B21: нет | C21: 6 | D21: 20110288-6 | E21: 1 | F21: 1 | G21: 2 | I21: 44743 | J21: 44467 | K21: 1 | L21: 10
B22: нет | C22: 7 | D22: 20110288-7 | E22: 1 | F22: 1 | I22: 44743 | J22: 44467 | K22: 1 | L22: 10
B23: нет | C23: 8 | D23: 20110288-8 | E23: 1 | G23: 1 | I23: 44743 | J23: 44467 | K23: 0 | L23: 3
B24: нет | C24: 9 | D24: 20110288-9 | E24: 1 | I24: 44743 | J24: 44467 | K24: 0 | L24: 3
A25: Гамма Сириус | B25: 1\1 | C25: 1 | D25: B7NS3809 | E25: 1 | I25: 44743 | J25: 44538 | K25: 0 | L25: 5
B26: 1\2 | C26: 2 | D26: 708509 | E26: 1 | G26: 1 | I26: 44743 | J26: 44538 | K26: 0 | L26: 5
B27: 1\2 | C27: 3 | D27: 708511 | E27: 1 | I27: 44743 | J27: 44538 | K27: 0 | L27: 5
B28: 1\3 | C28: 4 | D28: B7NS3791 | E28: 0 | I28: 44743 | J28: 44538 | K28: 0 | L28: 5
B29: 1\4 | C29: 5 | D29: B7NS3799 | E29: 1 | I29: 44743 | J29: 44538 | K29: 0 | L29: 5
B30: 1\4 | C30: 6 | D30: B7NS3806 | E30: 1 | I30: 44743 | J30: 44538 | K30: 0 | L30: 5
B31: 1\5 | C31: 7 | D31: B7NS3807 | E31: 1 | F31: 1 | I31: 44743 | J31: 44538 | K31: 0 | L31: 5
B32: 8\1 | C32: 1 | D32: B7NS3792 | E32: 1 | I32: 44743 | J32: 44538 | K32: 0 | L32: 5
B33: 8\2 | C33: 2 | D33: B7NS3804 | E33: 1 | F33: 1 | I33: 44743 | J33: 44538 | K33: 0 | L33: 5
B34: 8\3 | C34: 3 | D34: B7NS3794 | E34: 1 | F34: 1 | I34: 44743 | J34: 44538 | K34: 0 | L34: 5
B35: 8\4 | C35: 4 | D35: B7NS3795 | E35: 1 | I35: 44743 | J35: 44538 | K35: 0 | L35: 5
B36: 9\1 | C36: 1 | D36: B7NS3812 | E36: 1 | I36: 44743 | J36: 44538 | K36: 0 | L36: 5
B37: 9\2 | C37: 2 | D37: B79S3811 | E37: 1 | F37: 1 | I37: 44743 | J37: 44538 | K37: 0 | L37: 5
B38: 9\3 | C38: 3 | D38: B7NS3810 | E38: 1 | I38: 44743 | J38: 44538 | K38: 0 | L38: 5
B39: 9\4 | C39: 4 | D39: B7NS3808 | E39: 1 | F39: 1 | G39: 1 | I39: 44743 | J39: 44538 | K39: 0 | L39: 5
B40: 10\1 | C40: 1 | D40: B7NS3801 | E40: 1 | G40: 1 | I40: 44743 | J40: 44538 | K40: 0 | L40: 5
...

Sheet Апрель 2022
A1: Сводная таблица всех лифтов Департамента управления гостиницами
A2: Название Объекта | B2: Номер корпуса\секции | C2: Номер лифта (порядковый) | D2: Номер лифта(заводской) | E2: В Работе\отключен | F2: Заявки по замене расходных материалов(кнопки, тросики, лампы) | G2: Заявки по застреваниям и поломкам лифтов | H2: Краткое описание проблем | I2: Дата ближайшего тех.освидетельствования | J2: Дата окончания страховки | K2: Лифт для ППП | L2: Кол-во остановок
A3: Пульсар | B3: нет | C3: 1 | D3: B7NS4223 | E3: 1 | I3: 44743 | K3: 1 | L3: 13 | P3: Дельта | Q3: Кнопки и прочие мелочи: | R3: =SUM(F16:F24) -> 1
B4: нет | C4: 2 | D4: B7NS4224 | E4: 1 | I4: 44743 | K4: 0 | L4: 12 | Q4: Серьезные поломки: | R4: =SUM(G16:G24) -> 8
B5: нет | C5: 3 | D5: B7NS4225 | E5: 1 | I5: 44743 | K5: 0 | L5: 11 | P5: Гамма | Q5: Кнопки и прочие мелочи: | R5: =SUM(F25:F58) -> 12
B6: нет | C6: 4 | D6: B7NS4226 | E6: 1 | I6: 44743 | K6: 0 | L6: 11 | Q6: Серьезные поломки: | R6: =SUM(G25:G58) -> 9
B7: нет | C7: 5 | D7: B7NS4227 | E7: 1 | I7: 44743 | K7: 0 | L7: 12 | P7: Сигма | Q7: Кнопки и прочие мелочи: | R7: =SUM(F59:F138) -> 4
B8: нет | C8: 6 | D8: B7NS4228 | E8: 1 | I8: 44743 | K8: 0 | L8: 3 | Q8: Серьезные поломки: | R8: =SUM(G59:G138) -> 13
B9: нет | C9: 7 | D9: B7NS4229 | E9: 1 | I9: 44743 | K9: 0 | L9: 3 | P9: Омега | Q9: Кнопки и прочие мелочи: | R9: =SUM(F139:F146) -> 0
B10: нет | C10: 8 | D10: B7NS4230 | E10: 1 | I10: 44743 | K10: 0 | L10: 3 | Q10: Серьезные поломки: | R10: =SUM(G139:G146) -> 3
B11: нет | C11: 9 | D11: B7NS4231 | E11: 1 | I11: 44743 | K11: 0 | L11: 11 | P11: Парусная | Q11: Кнопки и прочие мелочи: | R11: =SUM(F147:F150) -> 0
B12: нет | C12: 10 | D12: B7NS4232 | E12: 1 | I12: 44743 | K12: 0 | L12: 11 | Q12: Серьезные поломки: | R12: =SUM(G147:G150) -> 0
B13: нет | C13: 11 | D13: B7NS4233 | E13: 1 | I13: 44743 | K13: 1 | L13: 13 | P13: Пульсар | Q13: Кнопки и прочие мелочи: | R13: =SUM(F3:F15) -> 0
B14: нет | C14: 12 | D14: B7NS4234 | E14: 1 | I14: 44743 | K14: 0 | L14: 2 | Q14: Серьезные поломки: | R14: =SUM(G3:G15) -> 0
B15: нет | C15: 13 | D15: B7NS4235 | E15: 1 | I15: 44743 | K15: 0 | L15: 2
A16: Дельта Сириус | B16: нет | C16: 1 | D16: 20110288-1 | E16: 1 | G16: 1 | I16: 44743 | J16: 44467 | K16: 0 | L16: 9 | Q16: Расходники | R16: =SUM(R3,R5,R7,R9,R11,R13) -> 17
B17: нет | C17: 2 | D17: 20110288-2 | E17: 1 | F17: 1 | G17: 1 | H17: лампа | I17: 44743 | J17: 44467 | K17: 0 | L17: 9 | Q17: Серьезные поломки | R17: =SUM(R4,R6,R8,R10,R12,R14) -> 33
B18: нет | C18: 3 | D18: 20110288-3 | E18: 1 | G18: 1 | I18: 44743 | J18: 44467 | K18: 0 | L18: 9 | Q18: Итого | R18: =SUM(R16,R17) -> 50
B19: нет | C19: 4 | D19: 20110288-4 | E19: 1 | I19: 44743 | J19: 44467 | K19: 1 | L19: 9
B20: нет | C20: 5 | D20: 20110288-5 | E20: 1 | I20: 44743 | J20: 44467 | K20: 1 | L20: 9
B21: нет | C21: 6 | D21: 20110288-6 | E21: 1 | I21: 44743 | J21: 44467 | K21: 1 | L21: 10
B22: нет | C22: 7 | D22: 20110288-7 | E22: 1 | G22: 3 | I22: 44743 | J22: 44467 | K22: 1 | L22: 10
B23: нет | C23: 8 | D23: 20110288-8 | E23: 1 | G23: 1 | I23: 44743 | J23: 44467 | K23: 0 | L23: 3
B24: нет | C24: 9 | D24: 20110288-9 | E24: 1 | G24: 1 | I24: 44743 | J24: 44467 | K24: 0 | L24: 3
A25: Гамма Сириус | B25: 1\1 | C25: 1 | D25: B7NS3809 | E25: 1 | F25: 1 | I25: 44743 | J25: 44538 | K25: 0 | L25: 5
B26: 1\2 | C26: 2 | D26: 708509 | E26: 1 | I26: 44743 | J26: 44538 | K26: 0 | L26: 5
B27: 1\2 | C27: 3 | D27: 708511 | E27: 1 | I27: 44743 | J27: 44538 | K27: 0 | L27: 5
B28: 1\3 | C28: 4 | D28: B7NS3791 | E28: 1 | I28: 44743 | J28: 44538 | K28: 0 | L28: 5
B29: 1\4 | C29: 5 | D29: B7NS3799 | E29: 1 | F29: 1 | I29: 44743 | J29: 44538 | K29: 0 | L29: 5
B30: 1\4 | C30: 6 | D30: B7NS3806 | E30: 1 | I30: 44743 | J30: 44538 | K30: 0 | L30: 5
B31: 1\5 | C31: 7 | D31: B7NS3807 | E31: 1 | I31: 44743 | J31: 44538 | K31: 0 | L31: 5
B32: 8\1 | C32: 1 | D32: B7NS3792 | E32: 1 | F32: 1 | H32: поручень | I32: 44743 | J32: 44538 | K32: 0 | L32: 5
B33: 8\2 | C33: 2 | D33: B7NS3804 | E33: 1 | G33: 1 | I33: 44743 | J33: 44538 | K33: 0 | L33: 5
B34: 8\3 | C34: 3 | D34: B7NS3794 | E34: 1 | I34: 44743 | J34: 44538 | K34: 0 | L34: 5
B35: 8\4 | C35: 4 | D35: B7NS3795 | E35: 1 | G35: 1 | I35: 44743 | J35: 44538 | K35: 0 | L35: 5
B36: 9\1 | C36: 1 | D36: B7NS3812 | E36: 1 | I36: 44743 | J36: 44538 | K36: 0 | L36: 5
B37: 9\2 | C37: 2 | D37: B79S3811 | E37: 1 | G37: 1 | I37: 44743 | J37: 44538 | K37: 0 | L37: 5
B38: 9\3 | C38: 3 | D38: B7NS3810 | E38: 1 | F38: 1 | I38: 44743 | J38: 44538 | K38: 0 | L38: 5
B39: 9\4 | C39: 4 | D39: B7NS3808 | E39: 1 | I39: 44743 | J39: 44538 | K39: 0 | L39: 5
B40: 10\1 | C40: 1 | D40: B7NS3801 | E40: 1 | I40: 44743 | J40: 44538 | K40: 0 | L40: 5
...

Sheet Май 2022
A1: Сводная таблица всех лифтов Департамента управления гостиницами
A2: Название Объекта | B2: Номер корпуса\секции | C2: Номер лифта (порядковый) | D2: Номер лифта(заводской) | E2: В Работе\отключен | F2: Заявки по замене расходных материалов(кнопки, тросики, лампы) | G2: Заявки по застреваниям и поломкам лифтов | H2: Краткое описание проблем | I2: Дата ближайшего тех.освидетельствования | J2: Дата окончания страховки | K2: Лифт для ППП | L2: Кол-во остановок | M2: г\п
A3: Апарт-отель | B3: нет | C3: 1 | D3: B7NS4223 | E3: 1 | I3: 44743 | K3: 1 | L3: 13 | M3: 1350 | P3: Дельта | Q3: Кнопки и прочие мелочи: | R3: =SUM(F16:F24) -> 8
B4: нет | C4: 2 | D4: B7NS4224 | E4: 1 | I4: 44743 | K4: 0 | L4: 12 | M4: 800 | Q4: Серьезные поломки: | R4: =SUM(G16:G24) -> 11
B5: нет | C5: 3 | D5: B7NS4225 | E5: 1 | I5: 44743 | K5: 0 | L5: 11 | M5: 800 | P5: Гамма | Q5: Кнопки и прочие мелочи: | R5: =SUM(F25:F58) -> 10
B6: нет | C6: 4 | D6: B7NS4226 | E6: 1 | I6: 44743 | K6: 0 | L6: 11 | M6: 800 | Q6: Серьезные поломки: | R6: =SUM(G25:G58) -> 12
B7: нет | C7: 5 | D7: B7NS4227 | E7: 1 | I7: 44743 | K7: 0 | L7: 12 | M7: 1000 | P7: Сигма | Q7: Кнопки и прочие мелочи: | R7: =SUM(F59:F138) -> 4
B8: нет | C8: 6 | D8: B7NS4228 | E8: 1 | I8: 44743 | K8: 0 | L8: 3 | M8: 800 | Q8: Серьезные поломки: | R8: =SUM(G59:G138) -> 8
B9: нет | C9: 7 | D9: B7NS4229 | E9: 1 | I9: 44743 | K9: 0 | L9: 2 | M9: 250 | P9: Омега | Q9: Кнопки и прочие мелочи: | R9: =SUM(F139:F146) -> 2
B10: нет | C10: 8 | D10: B7NS4230 | E10: 1 | I10: 44743 | K10: 0 | L10: 3 | M10: 1000 | Q10: Серьезные поломки: | R10: =SUM(G139:G146) -> 8
B11: нет | C11: 9 | D11: B7NS4231 | E11: 1 | I11: 44743 | K11: 0 | L11: 3 | M11: 1000 | P11: Парусная | Q11: Кнопки и прочие мелочи: | R11: =SUM(F147:F150) -> 0
B12: нет | C12: 10 | D12: B7NS4232 | E12: 1 | I12: 44743 | K12: 0 | L12: 2 | M12: 250 | Q12: Серьезные поломки: | R12: =SUM(G147:G150) -> 0
B13: нет | C13: 11 | D13: B7NS4233 | E13: 1 | I13: 44743 | K13: 1 | L13: 12 | M13: 800 | P13: Пульсар | Q13: Кнопки и прочие мелочи: | R13: =SUM(F3:F15) -> 0
B14: нет | C14: 12 | D14: B7NS4234 | E14: 1 | I14: 44743 | K14: 0 | L14: 12 | M14: 800 | Q14: Серьезные поломки: | R14: =SUM(G3:G15) -> 0
B15: нет | C15: 13 | D15: B7NS4235 | E15: 1 | I15: 44743 | K15: 0 | L15: 13 | M15: 1350
A16: Дельта Сириус | B16: нет | C16: 1 | D16: 20110288-1 | E16: 1 | I16: 44743 | J16: 44467 | K16: 0 | L16: 9 | M16: 1600 | Q16: Расходники | R16: =SUM(R3,R5,R7,R9,R11,R13) -> 24
B17: нет | C17: 2 | D17: 20110288-2 | E17: 1 | F17: 1 | G17: 2 | I17: 44743 | J17: 44467 | K17: 0 | L17: 9 | M17: 1600 | Q17: Серьезные поломки | R17: =SUM(R4,R6,R8,R10,R12,R14) -> 39
B18: нет | C18: 3 | D18: 20110288-3 | E18: 1 | F18: 2 | G18: 1 | I18: 44743 | J18: 44467 | K18: 0 | L18: 9 | M18: 1600 | Q18: Итого | R18: =SUM(R16,R17) -> 63
B19: нет | C19: 4 | D19: 20110288-4 | E19: 1 | I19: 44743 | J19: 44467 | K19: 1 | L19: 9 | M19: 1600
B20: нет | C20: 5 | D20: 20110288-5 | E20: 1 | F20: 1 | I20: 44743 | J20: 44467 | K20: 1 | L20: 9 | M20: 1600
B21: нет | C21: 6 | D21: 20110288-6 | E21: 1 | G21: 5 | I21: 44743 | J21: 44467 | K21: 1 | L21: 10 | M21: 1275
B22: нет | C22: 7 | D22: 20110288-7 | E22: 1 | F22: 1 | G22: 2 | I22: 44743 | J22: 44467 | K22: 1 | L22: 10 | M22: 1275
B23: нет | C23: 8 | D23: 20110288-8 | E23: 1 | F23: 1 | I23: 44743 | J23: 44467 | K23: 0 | L23: 3 | M23: 1000
B24: нет | C24: 9 | D24: 20110288-9 | E24: 1 | F24: 2 | G24: 1 | I24: 44743 | J24: 44467 | K24: 0 | L24: 3 | M24: 1000
A25: Гамма Сириус | B25: 1\1 | C25: 1 | D25: B7NS3809 | E25: 1 | I25: 44743 | J25: 44538 | K25: 0 | L25: 5
B26: 1\2 | C26: 2 | D26: 708509 | E26: 1 | I26: 44743 | J26: 44538 | K26: 0 | L26: 5
B27: 1\2 | C27: 3 | D27: 708511 | E27: 1 | I27: 44743 | J27: 44538 | K27: 0 | L27: 5
B28: 1\3 | C28: 4 | D28: B7NS3791 | E28: 1 | I28: 44743 | J28: 44538 | K28: 0 | L28: 5
B29: 1\4 | C29: 5 | D29: B7NS3799 | E29: 1 | G29: 1 | I29: 44743 | J29: 44538 | K29: 0 | L29: 5
B30: 1\4 | C30: 6 | D30: B7NS3806 | E30: 1 | I30: 44743 | J30: 44538 | K30: 0 | L30: 5
B31: 1\5 | C31: 7 | D31: B7NS3807 | E31: 1 | F31: 1 | I31: 44743 | J31: 44538 | K31: 0 | L31: 5
B32: 8\1 | C32: 1 | D32: B7NS3792 | E32: 1 | I32: 44743 | J32: 44538 | K32: 0 | L32: 5
B33: 8\2 | C33: 2 | D33: B7NS3804 | E33: 1 | I33: 44743 | J33: 44538 | K33: 0 | L33: 5
B34: 8\3 | C34: 3 | D34: B7NS3794 | E34: 1 | I34: 44743 | J34: 44538 | K34: 0 | L34: 5
B35: 8\4 | C35: 4 | D35: B7NS3795 | E35: 1 | G35: 1 | I35: 44743 | J35: 44538 | K35: 0 | L35: 5
B36: 9\1 | C36: 1 | D36: B7NS3812 | E36: 1 | G36: 1 | I36: 44743 | J36: 44538 | K36: 0 | L36: 5
B37: 9\2 | C37: 2 | D37: B79S3811 | E37: 1 | I37: 44743 | J37: 44538 | K37: 0 | L37: 5
B38: 9\3 | C38: 3 | D38: B7NS3810 | E38: 1 | I38: 44743 | J38: 44538 | K38: 0 | L38: 5
B39: 9\4 | C39: 4 | D39: B7NS3808 | E39: 1 | I39: 44743 | J39: 44538 | K39: 0 | L39: 5
B40: 10\1 | C40: 1 | D40: B7NS3801 | E40: 1 | I40: 44743 | J40: 44538 | K40: 0 | L40: 5
...

Sheet Июнь 2022
