Workbook
Name _12.01.2024: #REF!
Name _12.01.2024: #REF!
Name II00_0000006: #REF!
Name II00_0000006: #REF!
Name II00_0000007: #REF!
Name II00_0000007: #REF!
Name II00_0000027: #REF!
Name II00_0000027: #REF!
Name II00_0000028: #REF!
Name II00_0000028: #REF!
Name II00_0000029: #REF!
Name II00_0000029: #REF!
Name II00_0000030: #REF!
Name II00_0000030: #REF!
Name II00_0000033: #REF!
Name II00_0000033: #REF!
Name II00_0000035: #REF!
Name II00_0000035: #REF!
Name II00_0000036: #REF!
Name II00_0000036: #REF!
Name II00_0000041: #REF!
Name II00_0000041: #REF!
Name II00_0000043: #REF!
Name II00_0000043: #REF!
Name II00_0000045: #REF!
Name II00_0000045: #REF!
Name II00_0000046: #REF!
Name II00_0000046: #REF!
Name II00_0000047: #REF!
Name II00_0000047: #REF!
Name II00_0000048: #REF!
Name II00_0000048: #REF!
Name II00_0000049: #REF!
Name II00_0000049: #REF!
Name II00_0000050: #REF!
Name II00_0000050: #REF!
Name II00_0000052: #REF!
Name II00_0000052: #REF!
Name II00_0000053: #REF!
Name II00_0000053: #REF!
Name II00_0000056: #REF!
Name II00_0000056: #REF!
Name II00_0000057: #REF!
Name II00_0000057: #REF!
Name II00_0000059: #REF!
Name II00_0000059: #REF!
Name II00_0000063: #REF!
Name II00_0000063: #REF!
Name II00_0000064: #REF!
Name II00_0000064: #REF!
Name II00_0000067: #REF!
Name II00_0000067: #REF!
Name II00_0000068: #REF!
Name II00_0000068: #REF!
Name II00_0000074: #REF!
Name II00_0000074: #REF!
Name II00_0000076: #REF!
Name II00_0000076: #REF!
Name II00_0000078: #REF!
Name II00_0000078: #REF!

Sheet Прилож. к АКТУ
A1: ОБЩЕСТВО С ОГРАНИЧЕННОЙ ОТВЕТСТВЕННОСТЬЮ «ИНЖЕНЕРНАЯ ИНФРАСТРУКТУРА» (ООО «ИНЖЕНЕРНАЯ ИНФРАСТРУКТУРА»)
H3: УТВЕРЖДАЮ:
H4: Технический директор
H5: ________________ С.И.Рябинин
B7: Приложение к акту на списание материалов №
B8: =NOW()+0 -> 45967.782
A11: Материально ответственное лицо | C11: =IF(H11<>0,(VLOOKUP(H11,Сотрудники!D:E,2,0)),0) -> Руководитель группы | H11: Хабаров Д.Б.
C12: должность | G12: ФИО
A13: Комиссия в составе:
A14: Председатель комиссии | C14: =IF(H14<>0,(VLOOKUP(H14,Сотрудники!D:E,2,0)),0) -> Ведущий инженер по эксплуатации | H14: Семидалов Ю.С.
C15: должность | G15: ФИО
A16: Члены комиссии | C16: =IF(H16<>0,(VLOOKUP(H16,Сотрудники!D:E,2,0)),0) -> Ведущий инженер | H16: Агеев В.А.
C17: должность | G17: ФИО
C18: =IF(H18<>0,(VLOOKUP(H18,Сотрудники!D:E,2,0)),0) -> Ведущий инженер | H18: Линев А.В.
C19: должность | G19: ФИО
C20: =IF(H20<>0,(VLOOKUP(H20,Сотрудники!D:E,2,0)),0) -> Главный специалист СБ | H20: Антимонов В.С.
C21: должность | G21: ФИО
A23: Объект: | B23: Сириус Арена
A24: Проект: | B24: =IF(B23<>0,(VLOOKUP(B23,'Объекты '!A:B,2,0)),0) -> Эксплуатация и ТО_7804Ф
A25: За период: | B25: Октябрь 2025
A26: Подразделение: | B26: =IF(H11<>0,(VLOOKUP(H11,Сотрудники!D:F,3,0)),0) -> Группа по эксплуатации лифтового оборудования и грузоподъемных механизмов
A28: № п/п | B28: Наименование (ТМЦ) | C28: ИНВ | D28: Ед. изм. | E28: Кол-во | F28: Статья затрат | G28: № Заявки | H28: Основание для списания
A29: 1 | B29: Плата GECB-EN GCA26800LC6 | D29: шт | E29: 1 | F29: 2204003 Материалы для ТО и ТР лифтов и эскалаторов | G29: Заявка на обеспечение II00-0000952 от 13.08.2025 | H29: Акт установки №202510СА
B31: Председатель комиссии | H31: =H14 -> Семидалов Ю.С.
G32: подпись ФИО
B33: Члены комиссии | H33: =H16 -> Агеев В.А.
G34: подпись ФИО
H35: =H18 -> Линев А.В.
G36: подпись ФИО
H37: =H20 -> Антимонов В.С.
G38: подпись ФИО
B39: Материально ответственное лицо | H39: =H11 -> Хабаров Д.Б.
G40: подпись ФИО

Sheet Объекты 
A1: Объеты | B1: Проекты | C1: Период | D1: Подразделение
A2: Автодром | B2: Эксплуатация и ТО_12/23-181/1/ НИЦ | C2: Январь 2025 | D2: Администрация
A3: Апарт-отель_«Альфа Сириус» | B3: Эксплуатация и ТО_2349УК | C3: Февраль 2025 | D3: Группа главного энергетика
A4: Бассейн_Воскресенская, 18 | B4: Эксплуатация и ТО_7804Ф | C4: Март 2025 | D4: Группа по автоматизированным системам управления технологическими процессами
A5: ГК «Гамма Сириус» | B5: Эксплуатация и ТО_7807ДДУУК | C5: Апрель 2025 | D5: Группа по подготовке льда и спортивных сооружений
A6: Гостиница _Триумфальный, 3 | B6: Эксплуатация и ТО_7807ДДУУК | C6: Май 2025 | D6: Группа по ремонту технологического оборудования
A7: Гостиница «Альфа Сириус» | B7: Эксплуатация и ТО_2349УК | C7: Июнь 2025 | D7: Группа по эксплуатации лифтового оборудования и грузоподъемных механизмов
A8: Гостиница «Дельта Сириус» | B8: Эксплуатация и ТО_7807ДДУУК | C8: Июль 2025 | D8: Группа по эксплуатации систем отопления, водоснабжения, водоотведения и канализации
A9: Гостиница «Омега Сириус» | B9: Эксплуатация и ТО_7807ДДУУК | C9: Август 2025 | D9: Группа по эксплуатации систем холодоснабжения, вентиляции и кондиционирования
A10: Гостиница «Сигма Сириус» (Квартал А) | B10: Эксплуатация и ТО_7807ДДУУК | C10: Сентябрь 2025 | D10: Группа по эксплуатации специальных объектов
A11: ДДУ_Воскресенская, 16 | B11: Эксплуатация и ТО_7804Ф | C11: Октябрь 2025 | D11: Группа электротехнической лаборатории
A12: Кампус ОЦ «Сириус» | B12: Эксплуатация и ТО_7804Ф | C12: Ноябрь 2025 | D12: Дежурная служба
A13: Квартирный фонд_Худякова | B13: Эксплуатация и ТО_7807ДДУУК
A14: Квартирный фонд_Эстонская | B14: Эксплуатация и ТО_7807ДДУУК
A15: Комплекс апартаментов, Парусная д.10,12 | B15: Эксплуатация и ТО_7804Ф | C15: Декабрь 2025 | D15: Диспетчерский отдел
A16: Комплекс Трамплинов | B16: Эксплуатация и ТО_7804Ф | D16: Отдел материально-технического обеспечения
A17: Концертный комплекс | B17: Эксплуатация и ТО_7804Ф | D17: Отдел охраны труда
A18: Корпус «Искусство» | B18: Эксплуатация и ТО_7804Ф | D18: Отдел по общестроительным работам
A19: Корпус «Спорт» | B19: Эксплуатация и ТО_7804Ф | D19: Отдел по подготовке льда и трансформации арен
A20: Корпус «Школа» | B20: Эксплуатация и ТО_7804Ф | D20: Отдел по пожарной безопасности, гражданской обороне и чрезвычайным ситуациям
A21: ЛД Шайба | B21: Эксплуатация и ТО_7804Ф | D21: Отдел производственного контроля и эксплуатации ГТС
A22: Ледовый дворец спорта для фигурного катания и шорт-трека | B22: Эксплуатация и ТО_7804Ф | D22: Производственно-технический отдел
A23: Лицей_Воскресенская, 18 | B23: Эксплуатация и ТО_7804Ф | D23: Ремонтная служба
A24: Лицей_Международная, 10 | B24: Эксплуатация и ТО_7804Ф | D24: Служба безопасности
A25: Медицинский центр "Сириус" | B25: Эксплуатация и ТО_5850/01 МЦС | D25: Служба безопасности, Отдел режима и контроля
A26: Международная, 2, 2/1, 4,6,8 | B26: Эксплуатация и ТО_7804Ф | D26: Служба эксплуатации горного кластера
A27: Объект незавершенного строительства г. Москва | B27: Эксплуатация и ТО_7804Ф | D27: Транспортно-механический отдел
A28: Санно-бобслейная трасса | B28: Эксплуатация и ТО_7804Ф | D28: Отдел обслуживания технических средств охраны
A29: Сигма Сириус (Квартал Б,В,Г) | B29: Эксплуатация и ТО_7807ДДУУК
A30: Сириус Арена | B30: Эксплуатация и ТО_7804Ф
A31: Спортивный парк | B31: Эксплуатация и ТО_7804Ф
A32: Спорткомплекс_Инжирная | B32: Эксплуатация и ТО_Спорткомплекс_Инжирная_306/24"
A33: Спорткомплекс_Кур.пр. | B33: Эксплуатация и ТО_Спорткомплекс_Кур.пр._314/24"
A34: Территория Олимпийского парка | B34: Эксплуатация и ТО_7804Ф
A35: Технико-внедренческая зона (РЖД склады) | B35: Эксплуатация и ТО_2349УК
A36: Университет «Сириус» (ПНиИ «Сириус») | B36: Эксплуатация и ТО_7804Ф
A37: Хостел «S Hostel» | B37: Эксплуатация и ТО_2349УК

Sheet Сотрудники
A1: № п.п. | B1: Табельный номер | C1: ФИО сотрудника | D1: ФИО | E1: Должность (выбрать из списка) | F1: Подразделение (выбрать из списка)
B2: 00410 | C2: Агаревский Алексей Николаевич | D2: =LEFT(C2,FIND(" ",C2,1)+1)&"."&MID(C2,FIND(" ",C2,FIND(" ",C2,1)+1)+1,1)&"." -> Агаревский А.Н. | E2: Заместитель руководителя отдела по складскому хозяйству | F2: Отдел материально-технического обеспечения
B3: 00166 | C3: Агеев Владимир Андреевич | D3: =LEFT(C3,FIND(" ",C3,1)+1)&"."&MID(C3,FIND(" ",C3,FIND(" ",C3,1)+1)+1,1)&"." -> Агеев В.А. | E3: Ведущий инженер | F3: Группа по эксплуатации лифтового оборудования и грузоподъемных механизмов
B4: 00112 | C4: Агеев Юрий Сергеевич | D4: =LEFT(C4,FIND(" ",C4,1)+1)&"."&MID(C4,FIND(" ",C4,FIND(" ",C4,1)+1)+1,1)&"." -> Агеев Ю.С. | E4: Ведущий инженер | F4: Группа по эксплуатации систем холодоснабжения, вентиляции и кондиционирования
C5: Антимонов Виталий Сергеевич | D5: =LEFT(C5,FIND(" ",C5,1)+1)&"."&MID(C5,FIND(" ",C5,FIND(" ",C5,1)+1)+1,1)&"." -> Антимонов В.С. | E5: Главный специалист СБ | F5: Служба безопасности, Отдел режима и контроля
B6: 00400 | C6: Апанасик Дмитрий Анатольевич | D6: =LEFT(C6,FIND(" ",C6,1)+1)&"."&MID(C6,FIND(" ",C6,FIND(" ",C6,1)+1)+1,1)&"." -> Апанасик Д.А. | E6: Руководитель эксплуатации объектов | F6: Администрация
B7: 26377 | C7: Атанов Виктор Витальевич | D7: =LEFT(C7,FIND(" ",C7,1)+1)&"."&MID(C7,FIND(" ",C7,FIND(" ",C7,1)+1)+1,1)&"." -> Атанов В.В. | E7: Заместитель технического директора по системам инженерно-технического обеспечения | F7: Администрация
B8: 00076 | C8: Ашихмин Александр Алексеевич | D8: =LEFT(C8,FIND(" ",C8,1)+1)&"."&MID(C8,FIND(" ",C8,FIND(" ",C8,1)+1)+1,1)&"." -> Ашихмин А.А. | E8: Ведущий инженер холодоснабжения, вентиляции и кондиционирования | F8: Группа по эксплуатации систем холодоснабжения, вентиляции и кондиционирования
C9: Бабич Леонид Николаевич | D9: =LEFT(C9,FIND(" ",C9,1)+1)&"."&MID(C9,FIND(" ",C9,FIND(" ",C9,1)+1)+1,1)&"." -> Бабич Л.Н. | E9: Главный специалист СБ | F9: Служба безопасности, Отдел режима и контроля
C10: Бастун Олег Сергеевич | D10: =LEFT(C10,FIND(" ",C10,1)+1)&"."&MID(C10,FIND(" ",C10,FIND(" ",C10,1)+1)+1,1)&"." -> Бастун О.С. | E10: Ведущий инженер КИПиА | F10: Группа по автоматизированным системам управления технологическими процессами
B11: 00147 | C11: Бишов Иван Иванович | D11: =LEFT(C11,FIND(" ",C11,1)+1)&"."&MID(C11,FIND(" ",C11,FIND(" ",C11,1)+1)+1,1)&"." -> Бишов И.И. | E11: Ведущий инженер-энергетик | F11: Группа главного энергетика
B12: 00415 | C12: Богосян Саркис Вагаршакович | D12: =LEFT(C12,FIND(" ",C12,1)+1)&"."&MID(C12,FIND(" ",C12,FIND(" ",C12,1)+1)+1,1)&"." -> Богосян С.В. | E12: Ведущий специалист по эксплуатации объекта | F12: Дежурная служба
B13: 00150 | C13: Боровик Геннадий Васильевич | D13: =LEFT(C13,FIND(" ",C13,1)+1)&"."&MID(C13,FIND(" ",C13,FIND(" ",C13,1)+1)+1,1)&"." -> Боровик Г.В. | E13: Ведущий инженер | F13: Дежурная служба
C14: Брайко Владимир Сергеевич | D14: =LEFT(C14,FIND(" ",C14,1)+1)&"."&MID(C14,FIND(" ",C14,FIND(" ",C14,1)+1)+1,1)&"." -> Брайко В.С. | E14: Ведущий инженер по обслуживанию систем противопожарной защиты | F14: Отдел по пожарной безопасности, гражданской обороне и чрезвычайным ситуациям
B15: 00125 | C15: Брюхов Николай Андреевич | D15: =LEFT(C15,FIND(" ",C15,1)+1)&"."&MID(C15,FIND(" ",C15,FIND(" ",C15,1)+1)+1,1)&"." -> Брюхов Н.А. | E15: Руководитель отдела | F15: Отдел по общестроительным работам
B16: 26469 | C16: Бугров Виктор Владимирович | D16: =LEFT(C16,FIND(" ",C16,1)+1)&"."&MID(C16,FIND(" ",C16,FIND(" ",C16,1)+1)+1,1)&"." -> Бугров В.В. | E16: Руководитель отдела | F16: Диспетчерский отдел
B17: 26124 | C17: Буняк Алексей Андреевич | D17: =LEFT(C17,FIND(" ",C17,1)+1)&"."&MID(C17,FIND(" ",C17,FIND(" ",C17,1)+1)+1,1)&"." -> Буняк А.А. | E17: Ведущий инженер КИПиА | F17: Группа по автоматизированным системам управления технологическими процессами
B18: 26003 | C18: Бурдин Вячеслав Владимирович | D18: =LEFT(C18,FIND(" ",C18,1)+1)&"."&MID(C18,FIND(" ",C18,FIND(" ",C18,1)+1)+1,1)&"." -> Бурдин В.В. | E18: Ведущий инженер | F18: Отдел по общестроительным работам
C19: Бурова Анастасия Сергеевна | D19: =LEFT(C19,FIND(" ",C19,1)+1)&"."&MID(C19,FIND(" ",C19,FIND(" ",C19,1)+1)+1,1)&"." -> Бурова А.С. | E19: Главный специалист по охране труда | F19: Отдел охраны труда
B20: 00096 | C20: Буянов Владимир Николаевич | D20: =LEFT(C20,FIND(" ",C20,1)+1)&"."&MID(C20,FIND(" ",C20,FIND(" ",C20,1)+1)+1,1)&"." -> Буянов В.Н. | E20: Дежурный инженер | F20: Дежурная служба
B21: 26447 | C21: Верескунов Александр Николаевич | D21: =LEFT(C21,FIND(" ",C21,1)+1)&"."&MID(C21,FIND(" ",C21,FIND(" ",C21,1)+1)+1,1)&"." -> Верескунов А.Н. | E21: Ведущий инженер отопления, водоснабжения, водоотведения и канализации | F21: Группа по эксплуатации систем отопления, водоснабжения, водоотведения и канализации
B22: 00035 | C22: Виницкий Александр Александрович | D22: =LEFT(C22,FIND(" ",C22,1)+1)&"."&MID(C22,FIND(" ",C22,FIND(" ",C22,1)+1)+1,1)&"." -> Виницкий А.А. | E22: Ведущий инженер холодоснабжения, вентиляции и кондиционирования | F22: Группа по эксплуатации специальных объектов
B23: 00431 | C23: Волочок Александр Петрович | D23: =LEFT(C23,FIND(" ",C23,1)+1)&"."&MID(C23,FIND(" ",C23,FIND(" ",C23,1)+1)+1,1)&"." -> Волочок А.П. | E23: Ведущий специалист по эксплуатации объекта | F23: Дежурная служба
B24: 00015 | C24: Воробьев Григорий Геннадьевич | D24: =LEFT(C24,FIND(" ",C24,1)+1)&"."&MID(C24,FIND(" ",C24,FIND(" ",C24,1)+1)+1,1)&"." -> Воробьев Г.Г. | E24: Ведущий инженер-энергетик | F24: Служба эксплуатации горного кластера
C25: Воротов Андрей Александрович | D25: =LEFT(C25,FIND(" ",C25,1)+1)&"."&MID(C25,FIND(" ",C25,FIND(" ",C25,1)+1)+1,1)&"." -> Воротов А.А. | E25: Ведущий специалист по промышленной безопасности | F25: Отдел производственного контроля и эксплуатации ГТС
B26: 26048 | C26: Гаврилов Александр Львович | D26: =LEFT(C26,FIND(" ",C26,1)+1)&"."&MID(C26,FIND(" ",C26,FIND(" ",C26,1)+1)+1,1)&"." -> Гаврилов А.Л. | E26: Руководитель отдела | F26: Отдел по пожарной безопасности, гражданской обороне и чрезвычайным ситуациям
B27: 00016 | C27: Гаврилюк Леонид Александрович | D27: =LEFT(C27,FIND(" ",C27,1)+1)&"."&MID(C27,FIND(" ",C27,FIND(" ",C27,1)+1)+1,1)&"." -> Гаврилюк Л.А. | E27: Ведущий инженер | F27: Служба эксплуатации горного кластера
B28: 26465 | C28: Гашев Андрей Александрович | D28: =LEFT(C28,FIND(" ",C28,1)+1)&"."&MID(C28,FIND(" ",C28,FIND(" ",C28,1)+1)+1,1)&"." -> Гашев А.А. | E28: Ведущий инженер по обслуживанию систем противопожарной защиты | F28: Отдел по пожарной безопасности, гражданской обороне и чрезвычайным ситуациям
C29: Гетманов Валентин Юрьевич | D29: =LEFT(C29,FIND(" ",C29,1)+1)&"."&MID(C29,FIND(" ",C29,FIND(" ",C29,1)+1)+1,1)&"." -> Гетманов В.Ю. | E29: Руководитель службы | F29: Служба эксплуатации горного кластера
B30: 00077 | C30: Гильманов Равиль Дамирович | D30: =LEFT(C30,FIND(" ",C30,1)+1)&"."&MID(C30,FIND(" ",C30,FIND(" ",C30,1)+1)+1,1)&"." -> Гильманов Р.Д. | E30: Дежурный инженер | F30: Дежурная служба
C31: Гниломедов Олег Евгеньевич | D31: =LEFT(C31,FIND(" ",C31,1)+1)&"."&MID(C31,FIND(" ",C31,FIND(" ",C31,1)+1)+1,1)&"." -> Гниломедов О.Е. | E31: Заместитель руководителя службы – начальник отдела | F31: Служба безопасности, Отдел режима и контроля
B32: 00171 | C32: Головкин Петр Георгиевич | D32: =LEFT(C32,FIND(" ",C32,1)+1)&"."&MID(C32,FIND(" ",C32,FIND(" ",C32,1)+1)+1,1)&"." -> Головкин П.Г. | E32: Дежурный инженер | F32: Дежурная служба
B33: 26052 | C33: Голошапов Владимир Николаевич | D33: =LEFT(C33,FIND(" ",C33,1)+1)&"."&MID(C33,FIND(" ",C33,FIND(" ",C33,1)+1)+1,1)&"." -> Голошапов В.Н. | E33: Специалист по пожарной безопасности | F33: Отдел по пожарной безопасности, гражданской обороне и чрезвычайным ситуациям
B34: 00172 | C34: Горшков Андрей Александрович | D34: =LEFT(C34,FIND(" ",C34,1)+1)&"."&MID(C34,FIND(" ",C34,FIND(" ",C34,1)+1)+1,1)&"." -> Горшков А.А. | E34: Ведущий инженер-энергетик | F34: Группа главного энергетика
B35: 26329 | C35: Грак Виктор Мефодьевич | D35: =LEFT(C35,FIND(" ",C35,1)+1)&"."&MID(C35,FIND(" ",C35,FIND(" ",C35,1)+1)+1,1)&"." -> Грак В.М. | E35: Ведущий инженер | F35: Группа по эксплуатации систем отопления, водоснабжения, водоотведения и канализации
B36: 00211 | C36: Губин Дмитрий Владимирович | D36: =LEFT(C36,FIND(" ",C36,1)+1)&"."&MID(C36,FIND(" ",C36,FIND(" ",C36,1)+1)+1,1)&"." -> Губин Д.В. | E36: Заместитель технического директора по системам электроснабжения | F36: Администрация
B37: 26360 | C37: Данилко Алексей Вячеславович | D37: =LEFT(C37,FIND(" ",C37,1)+1)&"."&MID(C37,FIND(" ",C37,FIND(" ",C37,1)+1)+1,1)&"." -> Данилко А.В. | E37: Руководитель группы | F37: Группа по эксплуатации систем холодоснабжения, вентиляции и кондиционирования
B38: 00102 | C38: Данилов Сергей Алексеевич | D38: =LEFT(C38,FIND(" ",C38,1)+1)&"."&MID(C38,FIND(" ",C38,FIND(" ",C38,1)+1)+1,1)&"." -> Данилов С.А. | E38: Руководитель группы | F38: Группа по эксплуатации специальных объектов
B39: 00092 | C39: Дейнека Данил Юрьевич | D39: =LEFT(C39,FIND(" ",C39,1)+1)&"."&MID(C39,FIND(" ",C39,FIND(" ",C39,1)+1)+1,1)&"." -> Дейнека Д.Ю. | E39: Ведущий инженер | F39: Дежурная служба
B40: 26510 | C40: Демченко Алексей Михайлович | D40: =LEFT(C40,FIND(" ",C40,1)+1)&"."&MID(C40,FIND(" ",C40,FIND(" ",C40,1)+1)+1,1)&"." -> Демченко А.М. | E40: Ведущий специалист по подготовке льда | F40: Группа по подготовке льда и спортивных сооружений
...

Sheet Должности
A1: Должности
A2: Ведущий инженер
A3: Ведущий инженер - гидротехник
A4: Ведущий инженер АСУТП
A5: Ведущий инженер КИПиА
A6: Ведущий инженер отопления, водоснабжения, водоотведения и канализации
A7: Ведущий инженер по водоподготовке
A8: Ведущий инженер по обслуж. систем противопож. защиты
A9: Ведущий инженер по эксплуатации
A10: Ведущий инженер по эксплуатации бассейнов
A11: Ведущий инженер холодоснаб., вентиляции и кондиционир.
A12: Ведущий инженер-энергетик
... A43: Начальник отдела
