Workbook
Name _12.01.2024: #REF!
Name _12.01.2024: #REF!
Name _12.01.2024: #REF!
Name II00_0000006: #REF!
Name II00_0000006: #REF!
Name II00_0000006: #REF!
Name II00_0000007: #REF!
Name II00_0000007: #REF!
Name II00_0000007: #REF!
Name II00_0000027: #REF!
Name II00_0000027: #REF!
Name II00_0000027: #REF!
Name II00_0000028: #REF!
Name II00_0000028: #REF!
Name II00_0000028: #REF!
Name II00_0000029: #REF!
Name II00_0000029: #REF!
Name II00_0000029: #REF!
Name II00_0000030: #REF!
Name II00_0000030: #REF!
Name II00_0000030: #REF!
Name II00_0000033: #REF!
Name II00_0000033: #REF!
Name II00_0000033: #REF!
Name II00_0000035: #REF!
Name II00_0000035: #REF!
Name II00_0000035: #REF!
Name II00_0000036: #REF!
Name II00_0000036: #REF!
Name II00_0000036: #REF!
Name II00_0000041: #REF!
Name II00_0000041: #REF!
Name II00_0000041: #REF!
Name II00_0000043: #REF!
Name II00_0000043: #REF!
Name II00_0000043: #REF!
Name II00_0000045: #REF!
Name II00_0000045: #REF!
Name II00_0000045: #REF!
Name II00_0000046: #REF!
Name II00_0000046: #REF!
Name II00_0000046: #REF!
Name II00_0000047: #REF!
Name II00_0000047: #REF!
Name II00_0000047: #REF!
Name II00_0000048: #REF!
Name II00_0000048: #REF!
Name II00_0000048: #REF!
Name II00_0000049: #REF!
Name II00_0000049: #REF!
Name II00_0000049: #REF!
Name II00_0000050: #REF!
Name II00_0000050: #REF!
Name II00_0000050: #REF!
Name II00_0000052: #REF!
Name II00_0000052: #REF!
Name II00_0000052: #REF!
Name II00_0000053: #REF!
Name II00_0000053: #REF!
Name II00_0000053: #REF!

Sheet Прилож. к АКТУ
A1: ОБЩЕСТВО С ОГРАНИЧЕННОЙ ОТВЕТСТВЕННОСТЬЮ «ИНЖЕНЕРНАЯ ИНФРАСТРУКТУРА» (ООО «ИНЖЕНЕРНАЯ ИНФРАСТРУКТУРА»)
G3: УТВЕРЖДАЮ:
G4: Технический директор
G5: ________________ С.И.Рябинин
B7: Приложение к акту на списание материалов №1к
B8: 18 декабря 2025 г.
A11: Материально ответственное лицо Фонд «Талант и Успех» | C11: =IF(G11<>0,(VLOOKUP(G11,Сотрудники!D:E,2,0)),0) -> Ведущий специалист | G11: Чукбар Е.В.
C12: должность | G12: ФИО
A13: Комиссия в составе:
A14: Председатель комиссии | C14: =IF(G14<>0,(VLOOKUP(G14,Сотрудники!D:E,2,0)),0) -> Заместитель технического директора по строительству | G14: Зарубин И.А.
C15: должность | G15: ФИО
A16: Члены комиссии | C16: =IF(G16<>0,(VLOOKUP(G16,Сотрудники!D:E,2,0)),0) -> Ведущий инженер | G16: Агеев В.А.
C17: должность | G17: ФИО
C18: =IF(G18<>0,(VLOOKUP(G18,Сотрудники!D:E,2,0)),0) -> Руководитель группы | G18: Хабаров Д.Б.
C19: должность | G19: ФИО
C20: =IF(G20<>0,(VLOOKUP(G20,Сотрудники!D:E,2,0)),0) -> Главный специалист СБ | G20: Ячменев И.Р.
C21: должность | G21: ФИО
A23: Объект: | B23: Кампус ОЦ «Сириус»
A24: Проект: | B24: =IF(B23<>0,(VLOOKUP(B23,'Объекты '!A:B,2,0)),0) -> Эксплуатация и ТО_7804Ф
A25: За период: | B25: Декабрь 2025
A26: Подразделение: | B26: Группа по эксплуатации лифтового оборудования и грузоподъемных механизмов
A29: № п/п | B29: Наименование (ТМЦ) | C29: ИНВ | D29: Ед. изм. | E29: Кол-во | F29: Статья затрат | G29: Основание для списания
A30: 1 | B30: Лампа аварийного освещения светодиодная 12В, 1W, XIZIOTIS XAA417AK2 | D30: шт | E30: 1 | F30: 2204013 Материалы для ТО и ТР прочего оборудования | G30: Техническое обслуживание лифтового оборудования
A31: 2 | B31: Маслосборная коробка ZAA508R1 | D31: шт | E31: 16 | F31: 2204013 Материалы для ТО и ТР прочего оборудования | G31: Техническое обслуживание лифтового оборудования
A32: 3 | B32: Плата этажного индикатора PWB-PL TLHPI-1A (rev2.0) Thyssen | D32: шт | E32: 1 | F32: 2204013 Материалы для ТО и ТР прочего оборудования | G32: Акт установки №1к от 18.12.2025
A33: 4 | B33: Пружина доводчика ДШ L=720мм D=19мм, Selcom | D33: шт | E33: 1 | F33: 2204013 Материалы для ТО и ТР прочего оборудования | G33: Техническое обслуживание лифтового оборудования
A34: 5 | B34: Ролик подвески ДК/ДШ, d=56 мм, 3201.05.0032C, Hydra, | D34: шт | E34: 4 | F34: 2204013 Материалы для ТО и ТР прочего оборудования | G34: Техническое обслуживание лифтового оборудования
A35: 6 | B35: Тросик пружины дверей шахты L=1070mm, 3201.05.4001, Wittur | D35: шт | E35: 40 | F35: 2204013 Материалы для ТО и ТР прочего оборудования | G35: Техническое обслуживание лифтового оборудования
A36: 7 | B36: Стрейч-пленка для ручной упаковки черная вторичное сырье вес 2кг 20мкм x 217м x 500мм | D36: шт | E36: 5 | F36: 2204013 Материалы для ТО и ТР прочего оборудования | G36: Расходный материал для выполения работ ТО и ТР
B38: Председатель комиссии | G38: =G14 -> Зарубин И.А.
F39: подпись | G39: ФИО
B40: Члены комиссии | G40: =G16 -> Агеев В.А.
F41: подпись | G41: ФИО
G42: =G18 -> Хабаров Д.Б.
F43: подпись | G43: ФИО
G44: =G20 -> Ячменев И.Р.
F45: подпись | G45: ФИО
B46: Материально ответственное лицо Фонд «Талант и Успех» | G46: =G11 -> Чукбар Е.В.
F47: подпись | G47: ФИО

Sheet Объекты 
A1: Объеты | B1: Проекты | C1: Период | D1: Подразделение
A2: Автодром | B2: Эксплуатация и ТО_12/23-181/1/ НИЦ | C2: Январь 2025 | D2: Администрация
A3: Апарт-отель_«Альфа Сириус» | B3: Эксплуатация и ТО_2349УК | C3: Февраль 2025 | D3: Группа главного энергетика
A4: Бассейн_Воскресенская, 18 | B4: Эксплуатация и ТО_7804Ф | C4: Март 2025 | D4: Группа по автоматизированным системам управления технологическими процессами
A5: ГК «Гамма Сириус» | B5: Эксплуатация и ТО_7807ДДУУК | C5: Апрель 2025 | D5: Группа по подготовке льда и спортивных сооружений
A6: Гостиница _Триумфальный, 3 | B6: Эксплуатация и ТО_7807ДДУУК | C6: Май 2025 | D6: Группа по ремонту технологического оборудования
A7: Гостиница «Альфа Сириус» | B7: Эксплуатация и ТО_2349УК | C7: Июнь 2025 | D7: Группа по эксплуатации лифтового оборудования и грузоподъемных механизмов
A8: Гостиница «Дельта Сириус» | B8: Эксплуатация и ТО_7807ДДУУК | C8: Июль 2025 | D8: Группа по эксплуатации систем отопления, водоснабжения, водоотведения и канализации
A9: Гостиница «Омега Сириус» | B9: Эксплуатация и ТО_7807ДДУУК | C9: Август 2025 | D9: Группа по эксплуатации систем холодоснабжения, вентиляции и кондиционирования
A10: Гостиница «Сигма Сириус» (Квартал А) | B10: Эксплуатация и ТО_7807ДДУУК | C10: Сентябрь 2025 | D10: Группа по эксплуатации специальных объектов
A11: ДДУ_Воскресенская, 16 | B11: Эксплуатация и ТО_7804Ф | C11: Октябрь 2025 | D11: Группа электротехнической лаборатории
A12: Кампус ОЦ «Сириус» | B12: Эксплуатация и ТО_7804Ф | C12: Ноябрь 2025 | D12: Дежурная служба
A13: Комплекс апартаментов, Парусная д.10,12 | B13: Эксплуатация и ТО_7804Ф | C13: Декабрь 2025 | D13: Диспетчерский отдел
A14: Комплекс Трамплинов | B14: Эксплуатация и ТО_7804Ф | D14: Отдел материально-технического обеспечения
A15: Концертный комплекс | B15: Эксплуатация и ТО_7804Ф | D15: Отдел охраны труда
A16: Корпус «Искусство» | B16: Эксплуатация и ТО_7804Ф | D16: Отдел по общестроительным работам
A17: Корпус «Спорт» | B17: Эксплуатация и ТО_7804Ф | D17: Отдел по подготовке льда и трансформации арен
A18: Корпус «Школа» | B18: Эксплуатация и ТО_7804Ф | D18: Отдел по пожарной безопасности, гражданской обороне и чрезвычайным ситуациям
A19: ЛД Шайба | B19: Эксплуатация и ТО_7804Ф | D19: Отдел производственного контроля и эксплуатации ГТС
A20: Ледовый дворец спорта для фигурного катания и шорт-трека | B20: Эксплуатация и ТО_7804Ф | D20: Производственно-технический отдел
A21: Лицей_Воскресенская, 18 | B21: Эксплуатация и ТО_7804Ф | D21: Ремонтная служба
A22: Лицей_Международная, 10 | B22: Эксплуатация и ТО_7804Ф | D22: Служба безопасности
A23: Медицинский центр "Сириус" | B23: Эксплуатация и ТО_5850/01 МЦС | D23: Служба безопасности, Отдел режима и контроля
A24: Международная, 2, 2/1, 4,6,8 | B24: Эксплуатация и ТО_7804Ф | D24: Служба эксплуатации горного кластера
A25: Объект незавершенного строительства г. Москва | B25: Эксплуатация и ТО_7804Ф | D25: Транспортно-механический отдел
A26: Санно-бобслейная трасса | B26: Эксплуатация и ТО_7804Ф | D26: Отдел обслуживания технических средств охраны
A27: Сигма Сириус (Квартал Б,В,Г) | B27: Эксплуатация и ТО_7807ДДУУК
A28: Сириус Арена | B28: Эксплуатация и ТО_7804Ф
A29: Спортивный парк | B29: Эксплуатация и ТО_7804Ф
A30: Спорткомплекс_Инжирная | B30: Эксплуатация и ТО_Спорткомплекс_Инжирная_306/24"
A31: Спорткомплекс_Кур.пр. | B31: Эксплуатация и ТО_Спорткомплекс_Кур.пр._314/24"
A32: Территория Олимпийского парка | B32: Эксплуатация и ТО_7804Ф
A33: Технико-внедренческая зона (РЖД склады) | B33: Эксплуатация и ТО_2349УК
A34: Университет «Сириус» (ПНиИ «Сириус») | B34: Эксплуатация и ТО_7804Ф
A35: Хостел «S Hostel» | B35: Эксплуатация и ТО_2349УК

Sheet Сотрудники
A1: № п.п. | B1: Табельный номер | C1: ФИО сотрудника | D1: ФИО | E1: Должность (выбрать из списка) | F1: Подразделение (выбрать из списка)
B2: 00410 | C2: Агаревский Алексей Николаевич | D2: =LEFT(C2,FIND(" ",C2,1)+1)&"."&MID(C2,FIND(" ",C2,FIND(" ",C2,1)+1)+1,1)&"." -> Агаревский А.Н. | E2: Заместитель руководителя отдела по складскому хозяйству | F2: Отдел материально-технического обеспечения
B3: 00166 | C3: Агеев Владимир Андреевич | D3: =LEFT(C3,FIND(" ",C3,1)+1)&"."&MID(C3,FIND(" ",C3,FIND(" ",C3,1)+1)+1,1)&"." -> Агеев В.А. | E3: Ведущий инженер | F3: Группа по эксплуатации лифтового оборудования и грузоподъемных механизмов
B4: 00112 | C4: Агеев Юрий Сергеевич | D4: =LEFT(C4,FIND(" ",C4,1)+1)&"."&MID(C4,FIND(" ",C4,FIND(" ",C4,1)+1)+1,1)&"." -> Агеев Ю.С. | E4: Ведущий инженер | F4: Группа по эксплуатации систем холодоснабжения, вентиляции и кондиционирования
C5: Антимонов Виталий Сергеевич | D5: =LEFT(C5,FIND(" ",C5,1)+1)&"."&MID(C5,FIND(" ",C5,FIND(" ",C5,1)+1)+1,1)&"." -> Антимонов В.С. | E5: Главный специалист СБ | F5: Служба безопасности, Отдел режима и контроля
B6: 00400 | C6: Апанасик Дмитрий Анатольевич | D6: =LEFT(C6,FIND(" ",C6,1)+1)&"."&MID(C6,FIND(" ",C6,FIND(" ",C6,1)+1)+1,1)&"." -> Апанасик Д.А. | E6: Руководитель эксплуатации объектов | F6: Администрация
B7: 26377 | C7: Атанов Виктор Витальевич | D7: =LEFT(C7,FIND(" ",C7,1)+1)&"."&MID(C7,FIND(" ",C7,FIND(" ",C7,1)+1)+1,1)&"." -> Атанов В.В. | E7: Заместитель технического директора по системам инженерно-технического обеспечения | F7: Администрация
B8: 00076 | C8: Ашихмин Александр Алексеевич | D8: =LEFT(C8,FIND(" ",C8,1)+1)&"."&MID(C8,FIND(" ",C8,FIND(" ",C8,1)+1)+1,1)&"." -> Ашихмин А.А. | E8: Ведущий инженер холодоснабжения, вентиляции и кондиционирования | F8: Группа по эксплуатации систем холодоснабжения, вентиляции и кондиционирования
C9: Бабич Леонид Николаевич | D9: =LEFT(C9,FIND(" ",C9,1)+1)&"."&MID(C9,FIND(" ",C9,FIND(" ",C9,1)+1)+1,1)&"." -> Бабич Л.Н. | E9: Главный специалист СБ | F9: Служба безопасности, Отдел режима и контроля
C10: Бастун Олег Сергеевич | D10: =LEFT(C10,FIND(" ",C10,1)+1)&"."&MID(C10,FIND(" ",C10,FIND(" ",C10,1)+1)+1,1)&"." -> Бастун О.С. | E10: Ведущий инженер КИПиА | F10: Группа по автоматизированным системам управления технологическими процессами
B11: 00147 | C11: Бишов Иван Иванович | D11: =LEFT(C11,FIND(" ",C11,1)+1)&"."&MID(C11,FIND(" ",C11,FIND(" ",C11,1)+1)+1,1)&"." -> Бишов И.И. | E11: Ведущий инженер-энергетик | F11: Группа главного энергетика
B12: 00415 | C12: Богосян Саркис Вагаршакович | D12: =LEFT(C12,FIND(" ",C12,1)+1)&"."&MID(C12,FIND(" ",C12,FIND(" ",C12,1)+1)+1,1)&"." -> Богосян С.В. | E12: Ведущий специалист по эксплуатации объекта | F12: Дежурная служба
B13: 00150 | C13: Боровик Геннадий Васильевич | D13: =LEFT(C13,FIND(" ",C13,1)+1)&"."&MID(C13,FIND(" ",C13,FIND(" ",C13,1)+1)+1,1)&"." -> Боровик Г.В. | E13: Ведущий инженер | F13: Дежурная служба
C14: Брайко Владимир Сергеевич | D14: =LEFT(C14,FIND(" ",C14,1)+1)&"."&MID(C14,FIND(" ",C14,FIND(" ",C14,1)+1)+1,1)&"." -> Брайко В.С. | E14: Ведущий инженер по обслуживанию систем противопожарной защиты | F14: Отдел по пожарной безопасности, гражданской обороне и чрезвычайным ситуациям
B15: 00125 | C15: Брюхов Николай Андреевич | D15: =LEFT(C15,FIND(" ",C15,1)+1)&"."&MID(C15,FIND(" ",C15,FIND(" ",C15,1)+1)+1,1)&"." -> Брюхов Н.А. | E15: Руководитель отдела | F15: Отдел по общестроительным работам
B16: 26469 | C16: Бугров Виктор Владимирович | D16: =LEFT(C16,FIND(" ",C16,1)+1)&"."&MID(C16,FIND(" ",C16,FIND(" ",C16,1)+1)+1,1)&"." -> Бугров В.В. | E16: Руководитель отдела | F16: Диспетчерский отдел
B17: 26124 | C17: Буняк Алексей Андреевич | D17: =LEFT(C17,FIND(" ",C17,1)+1)&"."&MID(C17,FIND(" ",C17,FIND(" ",C17,1)+1)+1,1)&"." -> Буняк А.А. | E17: Ведущий инженер КИПиА | F17: Группа по автоматизированным системам управления технологическими процессами
B18: 26003 | C18: Бурдин Вячеслав Владимирович | D18: =LEFT(C18,FIND(" ",C18,1)+1)&"."&MID(C18,FIND(" ",C18,FIND(" ",C18,1)+1)+1,1)&"." -> Бурдин В.В. | E18: Ведущий инженер | F18: Отдел по общестроительным работам
C19: Бурова Анастасия Сергеевна | D19: =LEFT(C19,FIND(" ",C19,1)+1)&"."&MID(C19,FIND(" ",C19,FIND(" ",C19,1)+1)+1,1)&"." -> Бурова А.С. | E19: Главный специалист по охране труда | F19: Отдел охраны труда
B20: 00096 | C20: Буянов Владимир Николаевич | D20: =LEFT(C20,FIND(" ",C20,1)+1)&"."&MID(C20,FIND(" ",C20,FIND(" ",C20,1)+1)+1,1)&"." -> Буянов В.Н. | E20: Дежурный инженер | F20: Дежурная служба
B21: 26447 | C21: Верескунов Александр Николаевич | D21: =LEFT(C21,FIND(" ",C21,1)+1)&"."&MID(C21,FIND(" ",C21,FIND(" ",C21,1)+1)+1,1)&"." -> Верескунов А.Н. | E21: Ведущий инженер отопления, водоснабжения, водоотведения и канализации | F21: Группа по эксплуатации систем отопления, водоснабжения, водоотведения и канализации
B22: 00035 | C22: Виницкий Александр Александрович | D22: =LEFT(C22,FIND(" ",C22,1)+1)&"."&MID(C22,FIND(" ",C22,FIND(" ",C22,1)+1)+1,1)&"." -> Виницкий А.А. | E22: Ведущий инженер холодоснабжения, вентиляции и кондиционирования | F22: Группа по эксплуатации специальных объектов
B23: 00431 | C23: Волочок Александр Петрович | D23: =LEFT(C23,FIND(" ",C23,1)+1)&"."&MID(C23,FIND(" ",C23,FIND(" ",C23,1)+1)+1,1)&"." -> Волочок А.П. | E23: Ведущий специалист по эксплуатации объекта | F23: Дежурная служба
B24: 00015 | C24: Воробьев Григорий Геннадьевич | D24: =LEFT(C24,FIND(" ",C24,1)+1)&"."&MID(C24,FIND(" ",C24,FIND(" ",C24,1)+1)+1,1)&"." -> Воробьев Г.Г. | E24: Ведущий инженер-энергетик | F24: Служба эксплуатации горного кластера
C25: Воротов Андрей Александрович | D25: =LEFT(C25,FIND(" ",C25,1)+1)&"."&MID(C25,FIND(" ",C25,FIND(" ",C25,1)+1)+1,1)&"." -> Воротов А.А. | E25: Ведущий специалист по промышленной безопасности | F25: Отдел производственного контроля и эксплуатации ГТС
B26: 26048 | C26: Гаврилов Александр Львович | D26: =LEFT(C26,FIND(" ",C26,1)+1)&"."&MID(C26,FIND(" ",C26,FIND(" ",C26,1)+1)+1,1)&"." -> Гаврилов А.Л. | E26: Руководитель отдела | F26: Отдел по пожарной безопасности, гражданской обороне и чрезвычайным ситуациям
B27: 00016 | C27: Гаврилюк Леонид Александрович | D27: =LEFT(C27,FIND(" ",C27,1)+1)&"."&MID(C27,FIND(" ",C27,FIND(" ",C27,1)+1)+1,1)&"." -> Гаврилюк Л.А. | E27: Ведущий инженер | F27: Служба эксплуатации горного кластера
B28: 26465 | C28: Гашев Андрей Александрович | D28: =LEFT(C28,FIND(" ",C28,1)+1)&"."&MID(C28,FIND(" ",C28,FIND(" ",C28,1)+1)+1,1)&"." -> Гашев А.А. | E28: Ведущий инженер по обслуживанию систем противопожарной защиты | F28: Отдел по пожарной безопасности, гражданской обороне и чрезвычайным ситуациям
C29: Гетманов Валентин Юрьевич | D29: =LEFT(C29,FIND(" ",C29,1)+1)&"."&MID(C29,FIND(" ",C29,FIND(" ",C29,1)+1)+1,1)&"." -> Гетманов В.Ю. | E29: Руководитель службы | F29: Служба эксплуатации горного кластера
B30: 00077 | C30: Гильманов Равиль Дамирович | D30: =LEFT(C30,FIND(" ",C30,1)+1)&"."&MID(C30,FIND(" ",C30,FIND(" ",C30,1)+1)+1,1)&"." -> Гильманов Р.Д. | E30: Дежурный инженер | F30: Дежурная служба
C31: Гниломедов Олег Евгеньевич | D31: =LEFT(C31,FIND(" ",C31,1)+1)&"."&MID(C31,FIND(" ",C31,FIND(" ",C31,1)+1)+1,1)&"." -> Гниломедов О.Е. | E31: Заместитель руководителя службы – начальник отдела | F31: Служба безопасности, Отдел режима и контроля
B32: 00171 | C32: Головкин Петр Георгиевич | D32: =LEFT(C32,FIND(" ",C32,1)+1)&"."&MID(C32,FIND(" ",C32,FIND(" ",C32,1)+1)+1,1)&"." -> Головкин П.Г. | E32: Дежурный инженер | F32: Дежурная служба
B33: 26052 | C33: Голошапов Владимир Николаевич | D33: =LEFT(C33,FIND(" ",C33,1)+1)&"."&MID(C33,FIND(" ",C33,FIND(" ",C33,1)+1)+1,1)&"." -> Голошапов В.Н. | E33: Специалист по пожарной безопасности | F33: Отдел по пожарной безопасности, гражданской обороне и чрезвычайным ситуациям
B34: 00172 | C34: Горшков Андрей Александрович | D34: =LEFT(C34,FIND(" ",C34,1)+1)&"."&MID(C34,FIND(" ",C34,FIND(" ",C34,1)+1)+1,1)&"." -> Горшков А.А. | E34: Ведущий инженер-энергетик | F34: Группа главного энергетика
B35: 26329 | C35: Грак Виктор Мефодьевич | D35: =LEFT(C35,FIND(" ",C35,1)+1)&"."&MID(C35,FIND(" ",C35,FIND(" ",C35,1)+1)+1,1)&"." -> Грак В.М. | E35: Ведущий инженер | F35: Группа по эксплуатации систем отопления, водоснабжения, водоотведения и канализации
B36: 00211 | C36: Губин Дмитрий Владимирович | D36: =LEFT(C36,FIND(" ",C36,1)+1)&"."&MID(C36,FIND(" ",C36,FIND(" ",C36,1)+1)+1,1)&"." -> Губин Д.В. | E36: Заместитель технического директора по системам электроснабжения | F36: Администрация
B37: 26360 | C37: Данилко Алексей Вячеславович | D37: =LEFT(C37,FIND(" ",C37,1)+1)&"."&MID(C37,FIND(" ",C37,FIND(" ",C37,1)+1)+1,1)&"." -> Данилко А.В. | E37: Руководитель группы | F37: Группа по эксплуатации систем холодоснабжения, вентиляции и кондиционирования
B38: 00102 | C38: Данилов Сергей Алексеевич | D38: =LEFT(C38,FIND(" ",C38,1)+1)&"."&MID(C38,FIND(" ",C38,FIND(" ",C38,1)+1)+1,1)&"." -> Данилов С.А. | E38: Руководитель группы | F38: Группа по эксплуатации специальных объектов
B39: 00092 | C39: Дейнека Данил Юрьевич | D39: =LEFT(C39,FIND(" ",C39,1)+1)&"."&MID(C39,FIND(" ",C39,FIND(" ",C39,1)+1)+1,1)&"." -> Дейнека Д.Ю. | E39: Ведущий инженер | F39: Дежурная служба
B40: 26510 | C40: Демченко Алексей Михайлович | D40: =LEFT(C40,FIND(" ",C40,1)+1)&"."&MID(C40,FIND(" ",C40,FIND(" ",C40,1)+1)+1,1)&"." -> Демченко А.М. | E40: Ведущий специалист по подготовке льда | F40: Группа по подготовке льда и спортивных сооружений
...

Sheet Должности
A1: Должности
A2: Ведущий инженер
A3: Ведущий инженер - гидротехник
A4: Ведущий инженер АСУТП
A5: Ведущий инженер КИПиА
A6: Ведущий инженер отопления, водоснабжения, водоотведения и канализации
A7: Ведущий инженер по водоподготовке
A8: Ведущий инженер по обслуж. систем противопож. защиты
A9: Ведущий инженер по эксплуатации
A10: Ведущий инженер по эксплуатации бассейнов
A11: Ведущий инженер холодоснаб., вентиляции и кондиционир.
A12: Ведущий инженер-энергетик
... A43: Начальник отдела
